[2024-07-18T15:49:34.194+0000] {taskinstance.py:1957} INFO - Dependencies all met for dep_context=non-requeueable deps ti=<TaskInstance: google_analytics_data_etl.task_prepare_query_to_postgres manual__2024-07-18T15:04:45.851017+00:00 [queued]>
[2024-07-18T15:49:34.211+0000] {taskinstance.py:1957} INFO - Dependencies all met for dep_context=requeueable deps ti=<TaskInstance: google_analytics_data_etl.task_prepare_query_to_postgres manual__2024-07-18T15:04:45.851017+00:00 [queued]>
[2024-07-18T15:49:34.215+0000] {taskinstance.py:2171} INFO - Starting attempt 3 of 4
[2024-07-18T15:49:34.236+0000] {taskinstance.py:2192} INFO - Executing <Task(PythonOperator): task_prepare_query_to_postgres> on 2024-07-18 15:04:45.851017+00:00
[2024-07-18T15:49:34.245+0000] {standard_task_runner.py:60} INFO - Started process 1607 to run task
[2024-07-18T15:49:34.248+0000] {standard_task_runner.py:87} INFO - Running: ['***', 'tasks', 'run', 'google_analytics_data_etl', 'task_prepare_query_to_postgres', 'manual__2024-07-18T15:04:45.851017+00:00', '--job-id', '179', '--raw', '--subdir', 'DAGS_FOLDER/google_analytics_data_etl/google_analytics_data_etl.py', '--cfg-path', '/tmp/tmpgilw9inz']
[2024-07-18T15:49:34.251+0000] {standard_task_runner.py:88} INFO - Job 179: Subtask task_prepare_query_to_postgres
[2024-07-18T15:49:34.373+0000] {task_command.py:423} INFO - Running <TaskInstance: google_analytics_data_etl.task_prepare_query_to_postgres manual__2024-07-18T15:04:45.851017+00:00 [running]> on host 3d44d7374020
[2024-07-18T15:49:34.552+0000] {taskinstance.py:2481} INFO - Exporting env vars: AIRFLOW_CTX_DAG_OWNER='***' AIRFLOW_CTX_DAG_ID='google_analytics_data_etl' AIRFLOW_CTX_TASK_ID='task_prepare_query_to_postgres' AIRFLOW_CTX_EXECUTION_DATE='2024-07-18T15:04:45.851017+00:00' AIRFLOW_CTX_TRY_NUMBER='3' AIRFLOW_CTX_DAG_RUN_ID='manual__2024-07-18T15:04:45.851017+00:00'
[2024-07-18T15:49:34.568+0000] {taskinstance.py:2699} ERROR - Task failed with exception
Traceback (most recent call last):
  File "/home/airflow/.local/lib/python3.8/site-packages/airflow/models/taskinstance.py", line 433, in _execute_task
    result = execute_callable(context=context, **execute_callable_kwargs)
  File "/home/airflow/.local/lib/python3.8/site-packages/airflow/operators/python.py", line 199, in execute
    return_value = self.execute_callable()
  File "/home/airflow/.local/lib/python3.8/site-packages/airflow/operators/python.py", line 216, in execute_callable
    return self.python_callable(*self.op_args, **self.op_kwargs)
  File "/opt/airflow/dags/google_analytics_data_etl/logics/load.py", line 7, in prepare_query_load_postgres_event
    value = f"({i}, '{data['event_name'][i]}', '{data['event_bundle_sequence_id'][i]}', {int(data['user_pseudo_id'][i])})"
KeyError: 0
[2024-07-18T15:49:34.598+0000] {taskinstance.py:1138} INFO - Marking task as UP_FOR_RETRY. dag_id=google_analytics_data_etl, task_id=task_prepare_query_to_postgres, execution_date=20240718T150445, start_date=20240718T154934, end_date=20240718T154934
[2024-07-18T15:49:34.616+0000] {standard_task_runner.py:107} ERROR - Failed to execute job 179 for task task_prepare_query_to_postgres (0; 1607)
[2024-07-18T15:49:34.669+0000] {local_task_job_runner.py:234} INFO - Task exited with return code 1
[2024-07-18T15:49:34.757+0000] {taskinstance.py:3281} INFO - 0 downstream tasks scheduled from follow-on schedule check
