[2024-07-17T14:09:15.940+0000] {taskinstance.py:1957} INFO - Dependencies all met for dep_context=non-requeueable deps ti=<TaskInstance: google_analytics_data_etl.task_extraction_data manual__2024-07-17T14:05:48.098724+00:00 [queued]>
[2024-07-17T14:09:15.960+0000] {taskinstance.py:1957} INFO - Dependencies all met for dep_context=requeueable deps ti=<TaskInstance: google_analytics_data_etl.task_extraction_data manual__2024-07-17T14:05:48.098724+00:00 [queued]>
[2024-07-17T14:09:15.967+0000] {taskinstance.py:2171} INFO - Starting attempt 3 of 4
[2024-07-17T14:09:16.028+0000] {taskinstance.py:2192} INFO - Executing <Task(PythonOperator): task_extraction_data> on 2024-07-17 14:05:48.098724+00:00
[2024-07-17T14:09:16.062+0000] {standard_task_runner.py:60} INFO - Started process 1133 to run task
[2024-07-17T14:09:16.065+0000] {standard_task_runner.py:87} INFO - Running: ['***', 'tasks', 'run', 'google_analytics_data_etl', 'task_extraction_data', 'manual__2024-07-17T14:05:48.098724+00:00', '--job-id', '25', '--raw', '--subdir', 'DAGS_FOLDER/google_analytics_data_etl/google_analytics_data_etl.py', '--cfg-path', '/tmp/tmp7q_5aw8r']
[2024-07-17T14:09:16.071+0000] {standard_task_runner.py:88} INFO - Job 25: Subtask task_extraction_data
[2024-07-17T14:09:16.140+0000] {task_command.py:423} INFO - Running <TaskInstance: google_analytics_data_etl.task_extraction_data manual__2024-07-17T14:05:48.098724+00:00 [running]> on host f5f2893b4d65
[2024-07-17T14:09:16.293+0000] {taskinstance.py:2481} INFO - Exporting env vars: AIRFLOW_CTX_DAG_OWNER='***' AIRFLOW_CTX_DAG_ID='google_analytics_data_etl' AIRFLOW_CTX_TASK_ID='task_extraction_data' AIRFLOW_CTX_EXECUTION_DATE='2024-07-17T14:05:48.098724+00:00' AIRFLOW_CTX_TRY_NUMBER='3' AIRFLOW_CTX_DAG_RUN_ID='manual__2024-07-17T14:05:48.098724+00:00'
[2024-07-17T14:09:16.336+0000] {taskinstance.py:2699} ERROR - Task failed with exception
Traceback (most recent call last):
  File "/home/airflow/.local/lib/python3.8/site-packages/airflow/models/taskinstance.py", line 433, in _execute_task
    result = execute_callable(context=context, **execute_callable_kwargs)
  File "/home/airflow/.local/lib/python3.8/site-packages/airflow/operators/python.py", line 199, in execute
    return_value = self.execute_callable()
  File "/home/airflow/.local/lib/python3.8/site-packages/airflow/operators/python.py", line 216, in execute_callable
    return self.python_callable(*self.op_args, **self.op_kwargs)
  File "/opt/airflow/dags/google_analytics_data_etl/logics/extract.py", line 6, in extract_data
    with open('datas\Raw_Data.json', 'r') as file:
FileNotFoundError: [Errno 2] No such file or directory: 'datas\\Raw_Data.json'
[2024-07-17T14:09:16.371+0000] {taskinstance.py:1138} INFO - Marking task as UP_FOR_RETRY. dag_id=google_analytics_data_etl, task_id=task_extraction_data, execution_date=20240717T140548, start_date=20240717T140915, end_date=20240717T140916
[2024-07-17T14:09:16.447+0000] {standard_task_runner.py:107} ERROR - Failed to execute job 25 for task task_extraction_data ([Errno 2] No such file or directory: 'datas\\Raw_Data.json'; 1133)
[2024-07-17T14:09:16.500+0000] {local_task_job_runner.py:234} INFO - Task exited with return code 1
[2024-07-17T14:09:16.623+0000] {taskinstance.py:3281} INFO - 0 downstream tasks scheduled from follow-on schedule check
