[2024-07-18T15:54:50.018+0000] {taskinstance.py:1957} INFO - Dependencies all met for dep_context=non-requeueable deps ti=<TaskInstance: google_analytics_data_etl.task_load_data_postgres manual__2024-07-18T15:04:45.851017+00:00 [queued]>
[2024-07-18T15:54:50.031+0000] {taskinstance.py:1957} INFO - Dependencies all met for dep_context=requeueable deps ti=<TaskInstance: google_analytics_data_etl.task_load_data_postgres manual__2024-07-18T15:04:45.851017+00:00 [queued]>
[2024-07-18T15:54:50.032+0000] {taskinstance.py:2171} INFO - Starting attempt 3 of 4
[2024-07-18T15:54:50.075+0000] {taskinstance.py:2192} INFO - Executing <Task(PostgresOperator): task_load_data_postgres> on 2024-07-18 15:04:45.851017+00:00
[2024-07-18T15:54:50.091+0000] {standard_task_runner.py:60} INFO - Started process 1706 to run task
[2024-07-18T15:54:50.098+0000] {standard_task_runner.py:87} INFO - Running: ['***', 'tasks', 'run', 'google_analytics_data_etl', 'task_load_data_postgres', 'manual__2024-07-18T15:04:45.851017+00:00', '--job-id', '187', '--raw', '--subdir', 'DAGS_FOLDER/google_analytics_data_etl/google_analytics_data_etl.py', '--cfg-path', '/tmp/tmp6blzlfth']
[2024-07-18T15:54:50.113+0000] {standard_task_runner.py:88} INFO - Job 187: Subtask task_load_data_postgres
[2024-07-18T15:54:50.176+0000] {task_command.py:423} INFO - Running <TaskInstance: google_analytics_data_etl.task_load_data_postgres manual__2024-07-18T15:04:45.851017+00:00 [running]> on host 3d44d7374020
[2024-07-18T15:54:50.257+0000] {abstractoperator.py:708} ERROR - Exception rendering Jinja template for task 'task_load_data_postgres', field 'sql'. Template: "{{ ti.xcom_pull(task_id=task_prepare_query_to_postgres, key='query_event_to_postgres')}}"
Traceback (most recent call last):
  File "/home/airflow/.local/lib/python3.8/site-packages/airflow/models/abstractoperator.py", line 700, in _do_render_template_fields
    rendered_content = self.render_template(
  File "/home/airflow/.local/lib/python3.8/site-packages/airflow/template/templater.py", line 174, in render_template
    return self._render(template, context)
  File "/home/airflow/.local/lib/python3.8/site-packages/airflow/models/abstractoperator.py", line 654, in _render
    return super()._render(template, context, dag=dag)
  File "/home/airflow/.local/lib/python3.8/site-packages/airflow/template/templater.py", line 131, in _render
    return render_template_to_string(template, context)
  File "/home/airflow/.local/lib/python3.8/site-packages/airflow/utils/helpers.py", line 289, in render_template_to_string
    return render_template(template, cast(MutableMapping[str, Any], context), native=False)
  File "/home/airflow/.local/lib/python3.8/site-packages/airflow/utils/helpers.py", line 284, in render_template
    return "".join(nodes)
  File "<template>", line 13, in root
  File "/home/airflow/.local/lib/python3.8/site-packages/jinja2/sandbox.py", line 393, in call
    return __context.call(__obj, *args, **kwargs)
  File "/home/airflow/.local/lib/python3.8/site-packages/jinja2/runtime.py", line 298, in call
    return __obj(*args, **kwargs)
  File "/home/airflow/.local/lib/python3.8/site-packages/airflow/utils/session.py", line 79, in wrapper
    return func(*args, session=session, **kwargs)
TypeError: xcom_pull() got an unexpected keyword argument 'task_id'
[2024-07-18T15:54:50.260+0000] {taskinstance.py:2699} ERROR - Task failed with exception
Traceback (most recent call last):
  File "/home/airflow/.local/lib/python3.8/site-packages/airflow/models/taskinstance.py", line 2335, in _run_raw_task
    self._execute_task_with_callbacks(context, test_mode, session=session)
  File "/home/airflow/.local/lib/python3.8/site-packages/airflow/models/taskinstance.py", line 2466, in _execute_task_with_callbacks
    task_orig = self.render_templates(context=context)
  File "/home/airflow/.local/lib/python3.8/site-packages/airflow/models/taskinstance.py", line 2878, in render_templates
    original_task.render_template_fields(context)
  File "/home/airflow/.local/lib/python3.8/site-packages/airflow/models/baseoperator.py", line 1248, in render_template_fields
    self._do_render_template_fields(self, self.template_fields, context, jinja_env, set())
  File "/home/airflow/.local/lib/python3.8/site-packages/airflow/utils/session.py", line 79, in wrapper
    return func(*args, session=session, **kwargs)
  File "/home/airflow/.local/lib/python3.8/site-packages/airflow/models/abstractoperator.py", line 700, in _do_render_template_fields
    rendered_content = self.render_template(
  File "/home/airflow/.local/lib/python3.8/site-packages/airflow/template/templater.py", line 174, in render_template
    return self._render(template, context)
  File "/home/airflow/.local/lib/python3.8/site-packages/airflow/models/abstractoperator.py", line 654, in _render
    return super()._render(template, context, dag=dag)
  File "/home/airflow/.local/lib/python3.8/site-packages/airflow/template/templater.py", line 131, in _render
    return render_template_to_string(template, context)
  File "/home/airflow/.local/lib/python3.8/site-packages/airflow/utils/helpers.py", line 289, in render_template_to_string
    return render_template(template, cast(MutableMapping[str, Any], context), native=False)
  File "/home/airflow/.local/lib/python3.8/site-packages/airflow/utils/helpers.py", line 284, in render_template
    return "".join(nodes)
  File "<template>", line 13, in root
  File "/home/airflow/.local/lib/python3.8/site-packages/jinja2/sandbox.py", line 393, in call
    return __context.call(__obj, *args, **kwargs)
  File "/home/airflow/.local/lib/python3.8/site-packages/jinja2/runtime.py", line 298, in call
    return __obj(*args, **kwargs)
  File "/home/airflow/.local/lib/python3.8/site-packages/airflow/utils/session.py", line 79, in wrapper
    return func(*args, session=session, **kwargs)
TypeError: xcom_pull() got an unexpected keyword argument 'task_id'
[2024-07-18T15:54:50.269+0000] {taskinstance.py:1138} INFO - Marking task as UP_FOR_RETRY. dag_id=google_analytics_data_etl, task_id=task_load_data_postgres, execution_date=20240718T150445, start_date=20240718T155450, end_date=20240718T155450
[2024-07-18T15:54:50.285+0000] {standard_task_runner.py:107} ERROR - Failed to execute job 187 for task task_load_data_postgres (xcom_pull() got an unexpected keyword argument 'task_id'; 1706)
[2024-07-18T15:54:50.330+0000] {local_task_job_runner.py:234} INFO - Task exited with return code 1
[2024-07-18T15:54:50.385+0000] {taskinstance.py:3281} INFO - 0 downstream tasks scheduled from follow-on schedule check
