[2024-07-17T14:06:41.257+0000] {taskinstance.py:1957} INFO - Dependencies all met for dep_context=non-requeueable deps ti=<TaskInstance: google_analytics_data_etl.task_extraction_data manual__2024-07-17T14:06:38.214249+00:00 [queued]>
[2024-07-17T14:06:41.269+0000] {taskinstance.py:1957} INFO - Dependencies all met for dep_context=requeueable deps ti=<TaskInstance: google_analytics_data_etl.task_extraction_data manual__2024-07-17T14:06:38.214249+00:00 [queued]>
[2024-07-17T14:06:41.270+0000] {taskinstance.py:2171} INFO - Starting attempt 1 of 2
[2024-07-17T14:06:41.292+0000] {taskinstance.py:2192} INFO - Executing <Task(PythonOperator): task_extraction_data> on 2024-07-17 14:06:38.214249+00:00
[2024-07-17T14:06:41.301+0000] {standard_task_runner.py:60} INFO - Started process 1081 to run task
[2024-07-17T14:06:41.306+0000] {standard_task_runner.py:87} INFO - Running: ['***', 'tasks', 'run', 'google_analytics_data_etl', 'task_extraction_data', 'manual__2024-07-17T14:06:38.214249+00:00', '--job-id', '22', '--raw', '--subdir', 'DAGS_FOLDER/google_analytics_data_etl/google_analytics_data_etl.py', '--cfg-path', '/tmp/tmp20zxqfdc']
[2024-07-17T14:06:41.310+0000] {standard_task_runner.py:88} INFO - Job 22: Subtask task_extraction_data
[2024-07-17T14:06:41.378+0000] {task_command.py:423} INFO - Running <TaskInstance: google_analytics_data_etl.task_extraction_data manual__2024-07-17T14:06:38.214249+00:00 [running]> on host f5f2893b4d65
[2024-07-17T14:06:41.470+0000] {taskinstance.py:2481} INFO - Exporting env vars: AIRFLOW_CTX_DAG_OWNER='***' AIRFLOW_CTX_DAG_ID='google_analytics_data_etl' AIRFLOW_CTX_TASK_ID='task_extraction_data' AIRFLOW_CTX_EXECUTION_DATE='2024-07-17T14:06:38.214249+00:00' AIRFLOW_CTX_TRY_NUMBER='1' AIRFLOW_CTX_DAG_RUN_ID='manual__2024-07-17T14:06:38.214249+00:00'
[2024-07-17T14:06:41.494+0000] {logging_mixin.py:188} INFO - INI ADA PERCOBAAN DATA
[2024-07-17T14:06:41.505+0000] {taskinstance.py:2699} ERROR - Task failed with exception
Traceback (most recent call last):
  File "/home/airflow/.local/lib/python3.8/site-packages/airflow/models/taskinstance.py", line 433, in _execute_task
    result = execute_callable(context=context, **execute_callable_kwargs)
  File "/home/airflow/.local/lib/python3.8/site-packages/airflow/operators/python.py", line 199, in execute
    return_value = self.execute_callable()
  File "/home/airflow/.local/lib/python3.8/site-packages/airflow/operators/python.py", line 216, in execute_callable
    return self.python_callable(*self.op_args, **self.op_kwargs)
  File "/opt/airflow/dags/google_analytics_data_etl/logics/extract.py", line 7, in extract_data
    with open('../../datas/Raw_Data.json', 'r') as file:
FileNotFoundError: [Errno 2] No such file or directory: '../../datas/Raw_Data.json'
[2024-07-17T14:06:41.600+0000] {taskinstance.py:1138} INFO - Marking task as UP_FOR_RETRY. dag_id=google_analytics_data_etl, task_id=task_extraction_data, execution_date=20240717T140638, start_date=20240717T140641, end_date=20240717T140641
[2024-07-17T14:06:41.667+0000] {standard_task_runner.py:107} ERROR - Failed to execute job 22 for task task_extraction_data ([Errno 2] No such file or directory: '../../datas/Raw_Data.json'; 1081)
[2024-07-17T14:06:41.687+0000] {local_task_job_runner.py:234} INFO - Task exited with return code 1
[2024-07-17T14:06:41.728+0000] {taskinstance.py:3281} INFO - 0 downstream tasks scheduled from follow-on schedule check
