[2024-07-17T14:11:44.999+0000] {taskinstance.py:1957} INFO - Dependencies all met for dep_context=non-requeueable deps ti=<TaskInstance: google_analytics_data_etl.task_load_data_postgres manual__2024-07-17T14:04:06.997834+00:00 [queued]>
[2024-07-17T14:11:45.007+0000] {taskinstance.py:1957} INFO - Dependencies all met for dep_context=requeueable deps ti=<TaskInstance: google_analytics_data_etl.task_load_data_postgres manual__2024-07-17T14:04:06.997834+00:00 [queued]>
[2024-07-17T14:11:45.008+0000] {taskinstance.py:2171} INFO - Starting attempt 1 of 2
[2024-07-17T14:11:45.020+0000] {taskinstance.py:2192} INFO - Executing <Task(PostgresOperator): task_load_data_postgres> on 2024-07-17 14:04:06.997834+00:00
[2024-07-17T14:11:45.038+0000] {standard_task_runner.py:60} INFO - Started process 1222 to run task
[2024-07-17T14:11:45.038+0000] {standard_task_runner.py:87} INFO - Running: ['***', 'tasks', 'run', 'google_analytics_data_etl', 'task_load_data_postgres', 'manual__2024-07-17T14:04:06.997834+00:00', '--job-id', '44', '--raw', '--subdir', 'DAGS_FOLDER/google_analytics_data_etl/google_analytics_data_etl.py', '--cfg-path', '/tmp/tmpuhja2tyw']
[2024-07-17T14:11:45.039+0000] {standard_task_runner.py:88} INFO - Job 44: Subtask task_load_data_postgres
[2024-07-17T14:11:45.104+0000] {task_command.py:423} INFO - Running <TaskInstance: google_analytics_data_etl.task_load_data_postgres manual__2024-07-17T14:04:06.997834+00:00 [running]> on host f5f2893b4d65
[2024-07-17T14:11:45.210+0000] {taskinstance.py:2481} INFO - Exporting env vars: AIRFLOW_CTX_DAG_OWNER='***' AIRFLOW_CTX_DAG_ID='google_analytics_data_etl' AIRFLOW_CTX_TASK_ID='task_load_data_postgres' AIRFLOW_CTX_EXECUTION_DATE='2024-07-17T14:04:06.997834+00:00' AIRFLOW_CTX_TRY_NUMBER='1' AIRFLOW_CTX_DAG_RUN_ID='manual__2024-07-17T14:04:06.997834+00:00'
[2024-07-17T14:11:45.213+0000] {sql.py:276} INFO - Executing: INSERT INTO your_table (col1, col2) VALUES (%s, %s)
[2024-07-17T14:11:45.231+0000] {taskinstance.py:2699} ERROR - Task failed with exception
Traceback (most recent call last):
  File "/home/airflow/.local/lib/python3.8/site-packages/airflow/models/taskinstance.py", line 433, in _execute_task
    result = execute_callable(context=context, **execute_callable_kwargs)
  File "/home/airflow/.local/lib/python3.8/site-packages/airflow/providers/common/sql/operators/sql.py", line 277, in execute
    hook = self.get_db_hook()
  File "/home/airflow/.local/lib/python3.8/site-packages/airflow/providers/common/sql/operators/sql.py", line 188, in get_db_hook
    return self._hook
  File "/usr/local/lib/python3.8/functools.py", line 967, in __get__
    val = self.func(instance)
  File "/home/airflow/.local/lib/python3.8/site-packages/airflow/providers/common/sql/operators/sql.py", line 150, in _hook
    conn = BaseHook.get_connection(conn_id)
  File "/home/airflow/.local/lib/python3.8/site-packages/airflow/hooks/base.py", line 82, in get_connection
    conn = Connection.get_connection_from_secrets(conn_id)
  File "/home/airflow/.local/lib/python3.8/site-packages/airflow/models/connection.py", line 479, in get_connection_from_secrets
    raise AirflowNotFoundException(f"The conn_id `{conn_id}` isn't defined")
airflow.exceptions.AirflowNotFoundException: The conn_id `your_postgres_conn_id` isn't defined
[2024-07-17T14:11:45.235+0000] {taskinstance.py:1138} INFO - Marking task as UP_FOR_RETRY. dag_id=google_analytics_data_etl, task_id=task_load_data_postgres, execution_date=20240717T140406, start_date=20240717T141145, end_date=20240717T141145
[2024-07-17T14:11:45.256+0000] {standard_task_runner.py:107} ERROR - Failed to execute job 44 for task task_load_data_postgres (The conn_id `your_postgres_conn_id` isn't defined; 1222)
[2024-07-17T14:11:45.293+0000] {local_task_job_runner.py:234} INFO - Task exited with return code 1
[2024-07-17T14:11:45.316+0000] {taskinstance.py:3281} INFO - 0 downstream tasks scheduled from follow-on schedule check
