[2024-07-16T14:15:44.891+0000] {processor.py:161} INFO - Started process (PID=4892) to work on /opt/airflow/dags/google_analytics_data_etl.py
[2024-07-16T14:15:44.896+0000] {processor.py:830} INFO - Processing file /opt/airflow/dags/google_analytics_data_etl.py for tasks to queue
[2024-07-16T14:15:44.905+0000] {logging_mixin.py:188} INFO - [2024-07-16T14:15:44.904+0000] {dagbag.py:538} INFO - Filling up the DagBag from /opt/airflow/dags/google_analytics_data_etl.py
[2024-07-16T14:15:45.018+0000] {logging_mixin.py:188} INFO - [2024-07-16T14:15:45.015+0000] {dagbag.py:348} ERROR - Failed to import: /opt/airflow/dags/google_analytics_data_etl.py
Traceback (most recent call last):
  File "/home/airflow/.local/lib/python3.8/site-packages/airflow/models/dagbag.py", line 344, in parse
    loader.exec_module(new_module)
  File "<frozen importlib._bootstrap_external>", line 839, in exec_module
  File "<frozen importlib._bootstrap_external>", line 976, in get_code
  File "<frozen importlib._bootstrap_external>", line 906, in source_to_code
  File "<frozen importlib._bootstrap>", line 219, in _call_with_frames_removed
  File "/opt/airflow/dags/google_analytics_data_etl.py", line 2
    from airflow.operators
                          ^
SyntaxError: invalid syntax
[2024-07-16T14:15:45.021+0000] {processor.py:842} WARNING - No viable dags retrieved from /opt/airflow/dags/google_analytics_data_etl.py
[2024-07-16T14:15:45.116+0000] {processor.py:183} INFO - Processing /opt/airflow/dags/google_analytics_data_etl.py took 0.242 seconds
[2024-07-16T14:16:15.373+0000] {processor.py:161} INFO - Started process (PID=4947) to work on /opt/airflow/dags/google_analytics_data_etl.py
[2024-07-16T14:16:15.376+0000] {processor.py:830} INFO - Processing file /opt/airflow/dags/google_analytics_data_etl.py for tasks to queue
[2024-07-16T14:16:15.381+0000] {logging_mixin.py:188} INFO - [2024-07-16T14:16:15.381+0000] {dagbag.py:538} INFO - Filling up the DagBag from /opt/airflow/dags/google_analytics_data_etl.py
[2024-07-16T14:16:15.414+0000] {logging_mixin.py:188} INFO - [2024-07-16T14:16:15.411+0000] {dagbag.py:348} ERROR - Failed to import: /opt/airflow/dags/google_analytics_data_etl.py
Traceback (most recent call last):
  File "/home/airflow/.local/lib/python3.8/site-packages/airflow/models/dagbag.py", line 344, in parse
    loader.exec_module(new_module)
  File "<frozen importlib._bootstrap_external>", line 839, in exec_module
  File "<frozen importlib._bootstrap_external>", line 976, in get_code
  File "<frozen importlib._bootstrap_external>", line 906, in source_to_code
  File "<frozen importlib._bootstrap>", line 219, in _call_with_frames_removed
  File "/opt/airflow/dags/google_analytics_data_etl.py", line 2
    from airflow.operators
                          ^
SyntaxError: invalid syntax
[2024-07-16T14:16:15.416+0000] {processor.py:842} WARNING - No viable dags retrieved from /opt/airflow/dags/google_analytics_data_etl.py
[2024-07-16T14:16:15.470+0000] {processor.py:183} INFO - Processing /opt/airflow/dags/google_analytics_data_etl.py took 0.110 seconds
[2024-07-16T14:16:43.287+0000] {processor.py:161} INFO - Started process (PID=4998) to work on /opt/airflow/dags/google_analytics_data_etl.py
[2024-07-16T14:16:43.291+0000] {processor.py:830} INFO - Processing file /opt/airflow/dags/google_analytics_data_etl.py for tasks to queue
[2024-07-16T14:16:43.296+0000] {logging_mixin.py:188} INFO - [2024-07-16T14:16:43.296+0000] {dagbag.py:538} INFO - Filling up the DagBag from /opt/airflow/dags/google_analytics_data_etl.py
[2024-07-16T14:16:43.380+0000] {logging_mixin.py:188} INFO - [2024-07-16T14:16:43.369+0000] {dagbag.py:348} ERROR - Failed to import: /opt/airflow/dags/google_analytics_data_etl.py
Traceback (most recent call last):
  File "/home/airflow/.local/lib/python3.8/site-packages/airflow/models/dagbag.py", line 344, in parse
    loader.exec_module(new_module)
  File "<frozen importlib._bootstrap_external>", line 843, in exec_module
  File "<frozen importlib._bootstrap>", line 219, in _call_with_frames_removed
  File "/opt/airflow/dags/google_analytics_data_etl.py", line 2, in <module>
    from airflow.operators import Pytho
ImportError: cannot import name 'Pytho' from 'airflow.operators' (/home/airflow/.local/lib/python3.8/site-packages/airflow/operators/__init__.py)
[2024-07-16T14:16:43.383+0000] {processor.py:842} WARNING - No viable dags retrieved from /opt/airflow/dags/google_analytics_data_etl.py
[2024-07-16T14:16:43.421+0000] {processor.py:183} INFO - Processing /opt/airflow/dags/google_analytics_data_etl.py took 0.144 seconds
[2024-07-16T14:17:09.360+0000] {processor.py:161} INFO - Started process (PID=5043) to work on /opt/airflow/dags/google_analytics_data_etl.py
[2024-07-16T14:17:09.364+0000] {processor.py:830} INFO - Processing file /opt/airflow/dags/google_analytics_data_etl.py for tasks to queue
[2024-07-16T14:17:09.374+0000] {logging_mixin.py:188} INFO - [2024-07-16T14:17:09.373+0000] {dagbag.py:538} INFO - Filling up the DagBag from /opt/airflow/dags/google_analytics_data_etl.py
[2024-07-16T14:17:09.657+0000] {processor.py:842} WARNING - No viable dags retrieved from /opt/airflow/dags/google_analytics_data_etl.py
[2024-07-16T14:17:09.694+0000] {processor.py:183} INFO - Processing /opt/airflow/dags/google_analytics_data_etl.py took 0.345 seconds
[2024-07-16T14:17:40.444+0000] {processor.py:161} INFO - Started process (PID=5099) to work on /opt/airflow/dags/google_analytics_data_etl.py
[2024-07-16T14:17:40.447+0000] {processor.py:830} INFO - Processing file /opt/airflow/dags/google_analytics_data_etl.py for tasks to queue
[2024-07-16T14:17:40.456+0000] {logging_mixin.py:188} INFO - [2024-07-16T14:17:40.455+0000] {dagbag.py:538} INFO - Filling up the DagBag from /opt/airflow/dags/google_analytics_data_etl.py
[2024-07-16T14:17:40.494+0000] {processor.py:842} WARNING - No viable dags retrieved from /opt/airflow/dags/google_analytics_data_etl.py
[2024-07-16T14:17:40.516+0000] {processor.py:183} INFO - Processing /opt/airflow/dags/google_analytics_data_etl.py took 0.084 seconds
[2024-07-16T14:18:04.126+0000] {processor.py:161} INFO - Started process (PID=5149) to work on /opt/airflow/dags/google_analytics_data_etl.py
[2024-07-16T14:18:04.127+0000] {processor.py:830} INFO - Processing file /opt/airflow/dags/google_analytics_data_etl.py for tasks to queue
[2024-07-16T14:18:04.129+0000] {logging_mixin.py:188} INFO - [2024-07-16T14:18:04.129+0000] {dagbag.py:538} INFO - Filling up the DagBag from /opt/airflow/dags/google_analytics_data_etl.py
[2024-07-16T14:18:04.192+0000] {logging_mixin.py:188} INFO - [2024-07-16T14:18:04.184+0000] {dagbag.py:348} ERROR - Failed to import: /opt/airflow/dags/google_analytics_data_etl.py
Traceback (most recent call last):
  File "/home/airflow/.local/lib/python3.8/site-packages/airflow/models/dagbag.py", line 344, in parse
    loader.exec_module(new_module)
  File "<frozen importlib._bootstrap_external>", line 843, in exec_module
  File "<frozen importlib._bootstrap>", line 219, in _call_with_frames_removed
  File "/opt/airflow/dags/google_analytics_data_etl.py", line 4, in <module>
    default
NameError: name 'default' is not defined
[2024-07-16T14:18:04.194+0000] {processor.py:842} WARNING - No viable dags retrieved from /opt/airflow/dags/google_analytics_data_etl.py
[2024-07-16T14:18:04.221+0000] {processor.py:183} INFO - Processing /opt/airflow/dags/google_analytics_data_etl.py took 0.099 seconds
[2024-07-16T14:18:08.637+0000] {processor.py:161} INFO - Started process (PID=5156) to work on /opt/airflow/dags/google_analytics_data_etl.py
[2024-07-16T14:18:08.639+0000] {processor.py:830} INFO - Processing file /opt/airflow/dags/google_analytics_data_etl.py for tasks to queue
[2024-07-16T14:18:08.643+0000] {logging_mixin.py:188} INFO - [2024-07-16T14:18:08.642+0000] {dagbag.py:538} INFO - Filling up the DagBag from /opt/airflow/dags/google_analytics_data_etl.py
[2024-07-16T14:18:08.671+0000] {logging_mixin.py:188} INFO - [2024-07-16T14:18:08.670+0000] {dagbag.py:348} ERROR - Failed to import: /opt/airflow/dags/google_analytics_data_etl.py
Traceback (most recent call last):
  File "/home/airflow/.local/lib/python3.8/site-packages/airflow/models/dagbag.py", line 344, in parse
    loader.exec_module(new_module)
  File "<frozen importlib._bootstrap_external>", line 839, in exec_module
  File "<frozen importlib._bootstrap_external>", line 976, in get_code
  File "<frozen importlib._bootstrap_external>", line 906, in source_to_code
  File "<frozen importlib._bootstrap>", line 219, in _call_with_frames_removed
  File "/opt/airflow/dags/google_analytics_data_etl.py", line 4
    default_args =
                  ^
SyntaxError: invalid syntax
[2024-07-16T14:18:08.672+0000] {processor.py:842} WARNING - No viable dags retrieved from /opt/airflow/dags/google_analytics_data_etl.py
[2024-07-16T14:18:08.691+0000] {processor.py:183} INFO - Processing /opt/airflow/dags/google_analytics_data_etl.py took 0.067 seconds
[2024-07-16T14:18:15.454+0000] {processor.py:161} INFO - Started process (PID=5168) to work on /opt/airflow/dags/google_analytics_data_etl.py
[2024-07-16T14:18:15.456+0000] {processor.py:830} INFO - Processing file /opt/airflow/dags/google_analytics_data_etl.py for tasks to queue
[2024-07-16T14:18:15.459+0000] {logging_mixin.py:188} INFO - [2024-07-16T14:18:15.459+0000] {dagbag.py:538} INFO - Filling up the DagBag from /opt/airflow/dags/google_analytics_data_etl.py
[2024-07-16T14:18:15.490+0000] {processor.py:842} WARNING - No viable dags retrieved from /opt/airflow/dags/google_analytics_data_etl.py
[2024-07-16T14:18:15.510+0000] {processor.py:183} INFO - Processing /opt/airflow/dags/google_analytics_data_etl.py took 0.059 seconds
[2024-07-16T14:18:23.094+0000] {processor.py:161} INFO - Started process (PID=5199) to work on /opt/airflow/dags/google_analytics_data_etl.py
[2024-07-16T14:18:23.098+0000] {processor.py:830} INFO - Processing file /opt/airflow/dags/google_analytics_data_etl.py for tasks to queue
[2024-07-16T14:18:23.102+0000] {logging_mixin.py:188} INFO - [2024-07-16T14:18:23.101+0000] {dagbag.py:538} INFO - Filling up the DagBag from /opt/airflow/dags/google_analytics_data_etl.py
[2024-07-16T14:18:23.134+0000] {processor.py:842} WARNING - No viable dags retrieved from /opt/airflow/dags/google_analytics_data_etl.py
[2024-07-16T14:18:23.148+0000] {processor.py:183} INFO - Processing /opt/airflow/dags/google_analytics_data_etl.py took 0.058 seconds
[2024-07-16T14:18:34.443+0000] {processor.py:161} INFO - Started process (PID=5208) to work on /opt/airflow/dags/google_analytics_data_etl.py
[2024-07-16T14:18:34.445+0000] {processor.py:830} INFO - Processing file /opt/airflow/dags/google_analytics_data_etl.py for tasks to queue
[2024-07-16T14:18:34.447+0000] {logging_mixin.py:188} INFO - [2024-07-16T14:18:34.447+0000] {dagbag.py:538} INFO - Filling up the DagBag from /opt/airflow/dags/google_analytics_data_etl.py
[2024-07-16T14:18:34.484+0000] {processor.py:842} WARNING - No viable dags retrieved from /opt/airflow/dags/google_analytics_data_etl.py
[2024-07-16T14:18:34.495+0000] {processor.py:183} INFO - Processing /opt/airflow/dags/google_analytics_data_etl.py took 0.054 seconds
[2024-07-16T14:18:49.385+0000] {processor.py:161} INFO - Started process (PID=5231) to work on /opt/airflow/dags/google_analytics_data_etl.py
[2024-07-16T14:18:49.387+0000] {processor.py:830} INFO - Processing file /opt/airflow/dags/google_analytics_data_etl.py for tasks to queue
[2024-07-16T14:18:49.393+0000] {logging_mixin.py:188} INFO - [2024-07-16T14:18:49.392+0000] {dagbag.py:538} INFO - Filling up the DagBag from /opt/airflow/dags/google_analytics_data_etl.py
[2024-07-16T14:18:49.413+0000] {logging_mixin.py:188} INFO - [2024-07-16T14:18:49.413+0000] {dagbag.py:348} ERROR - Failed to import: /opt/airflow/dags/google_analytics_data_etl.py
Traceback (most recent call last):
  File "/home/airflow/.local/lib/python3.8/site-packages/airflow/models/dagbag.py", line 344, in parse
    loader.exec_module(new_module)
  File "<frozen importlib._bootstrap_external>", line 839, in exec_module
  File "<frozen importlib._bootstrap_external>", line 976, in get_code
  File "<frozen importlib._bootstrap_external>", line 906, in source_to_code
  File "<frozen importlib._bootstrap>", line 219, in _call_with_frames_removed
  File "/opt/airflow/dags/google_analytics_data_etl.py", line 10
    }
    ^
SyntaxError: invalid syntax
[2024-07-16T14:18:49.414+0000] {processor.py:842} WARNING - No viable dags retrieved from /opt/airflow/dags/google_analytics_data_etl.py
[2024-07-16T14:18:49.431+0000] {processor.py:183} INFO - Processing /opt/airflow/dags/google_analytics_data_etl.py took 0.055 seconds
[2024-07-16T14:18:53.959+0000] {processor.py:161} INFO - Started process (PID=5259) to work on /opt/airflow/dags/google_analytics_data_etl.py
[2024-07-16T14:18:53.965+0000] {processor.py:830} INFO - Processing file /opt/airflow/dags/google_analytics_data_etl.py for tasks to queue
[2024-07-16T14:18:53.982+0000] {logging_mixin.py:188} INFO - [2024-07-16T14:18:53.981+0000] {dagbag.py:538} INFO - Filling up the DagBag from /opt/airflow/dags/google_analytics_data_etl.py
[2024-07-16T14:18:54.025+0000] {logging_mixin.py:188} INFO - [2024-07-16T14:18:54.023+0000] {dagbag.py:348} ERROR - Failed to import: /opt/airflow/dags/google_analytics_data_etl.py
Traceback (most recent call last):
  File "/home/airflow/.local/lib/python3.8/site-packages/airflow/models/dagbag.py", line 344, in parse
    loader.exec_module(new_module)
  File "<frozen importlib._bootstrap_external>", line 839, in exec_module
  File "<frozen importlib._bootstrap_external>", line 976, in get_code
  File "<frozen importlib._bootstrap_external>", line 906, in source_to_code
  File "<frozen importlib._bootstrap>", line 219, in _call_with_frames_removed
  File "/opt/airflow/dags/google_analytics_data_etl.py", line 8
    }
    ^
SyntaxError: invalid syntax
[2024-07-16T14:18:54.028+0000] {processor.py:842} WARNING - No viable dags retrieved from /opt/airflow/dags/google_analytics_data_etl.py
[2024-07-16T14:18:54.064+0000] {processor.py:183} INFO - Processing /opt/airflow/dags/google_analytics_data_etl.py took 0.111 seconds
[2024-07-16T14:19:24.171+0000] {processor.py:161} INFO - Started process (PID=5320) to work on /opt/airflow/dags/google_analytics_data_etl.py
[2024-07-16T14:19:24.172+0000] {processor.py:830} INFO - Processing file /opt/airflow/dags/google_analytics_data_etl.py for tasks to queue
[2024-07-16T14:19:24.175+0000] {logging_mixin.py:188} INFO - [2024-07-16T14:19:24.175+0000] {dagbag.py:538} INFO - Filling up the DagBag from /opt/airflow/dags/google_analytics_data_etl.py
[2024-07-16T14:19:24.206+0000] {logging_mixin.py:188} INFO - [2024-07-16T14:19:24.205+0000] {dagbag.py:348} ERROR - Failed to import: /opt/airflow/dags/google_analytics_data_etl.py
Traceback (most recent call last):
  File "/home/airflow/.local/lib/python3.8/site-packages/airflow/models/dagbag.py", line 344, in parse
    loader.exec_module(new_module)
  File "<frozen importlib._bootstrap_external>", line 839, in exec_module
  File "<frozen importlib._bootstrap_external>", line 976, in get_code
  File "<frozen importlib._bootstrap_external>", line 906, in source_to_code
  File "<frozen importlib._bootstrap>", line 219, in _call_with_frames_removed
  File "/opt/airflow/dags/google_analytics_data_etl.py", line 8
    }
    ^
SyntaxError: invalid syntax
[2024-07-16T14:19:24.207+0000] {processor.py:842} WARNING - No viable dags retrieved from /opt/airflow/dags/google_analytics_data_etl.py
[2024-07-16T14:19:24.226+0000] {processor.py:183} INFO - Processing /opt/airflow/dags/google_analytics_data_etl.py took 0.061 seconds
[2024-07-16T14:19:54.393+0000] {processor.py:161} INFO - Started process (PID=5373) to work on /opt/airflow/dags/google_analytics_data_etl.py
[2024-07-16T14:19:54.395+0000] {processor.py:830} INFO - Processing file /opt/airflow/dags/google_analytics_data_etl.py for tasks to queue
[2024-07-16T14:19:54.398+0000] {logging_mixin.py:188} INFO - [2024-07-16T14:19:54.397+0000] {dagbag.py:538} INFO - Filling up the DagBag from /opt/airflow/dags/google_analytics_data_etl.py
[2024-07-16T14:19:54.423+0000] {logging_mixin.py:188} INFO - [2024-07-16T14:19:54.422+0000] {dagbag.py:348} ERROR - Failed to import: /opt/airflow/dags/google_analytics_data_etl.py
Traceback (most recent call last):
  File "/home/airflow/.local/lib/python3.8/site-packages/airflow/models/dagbag.py", line 344, in parse
    loader.exec_module(new_module)
  File "<frozen importlib._bootstrap_external>", line 839, in exec_module
  File "<frozen importlib._bootstrap_external>", line 976, in get_code
  File "<frozen importlib._bootstrap_external>", line 906, in source_to_code
  File "<frozen importlib._bootstrap>", line 219, in _call_with_frames_removed
  File "/opt/airflow/dags/google_analytics_data_etl.py", line 8
    }
    ^
SyntaxError: invalid syntax
[2024-07-16T14:19:54.424+0000] {processor.py:842} WARNING - No viable dags retrieved from /opt/airflow/dags/google_analytics_data_etl.py
[2024-07-16T14:19:54.445+0000] {processor.py:183} INFO - Processing /opt/airflow/dags/google_analytics_data_etl.py took 0.056 seconds
[2024-07-16T14:20:25.145+0000] {processor.py:161} INFO - Started process (PID=5425) to work on /opt/airflow/dags/google_analytics_data_etl.py
[2024-07-16T14:20:25.147+0000] {processor.py:830} INFO - Processing file /opt/airflow/dags/google_analytics_data_etl.py for tasks to queue
[2024-07-16T14:20:25.152+0000] {logging_mixin.py:188} INFO - [2024-07-16T14:20:25.151+0000] {dagbag.py:538} INFO - Filling up the DagBag from /opt/airflow/dags/google_analytics_data_etl.py
[2024-07-16T14:20:25.233+0000] {logging_mixin.py:188} INFO - [2024-07-16T14:20:25.231+0000] {dagbag.py:348} ERROR - Failed to import: /opt/airflow/dags/google_analytics_data_etl.py
Traceback (most recent call last):
  File "/home/airflow/.local/lib/python3.8/site-packages/airflow/models/dagbag.py", line 344, in parse
    loader.exec_module(new_module)
  File "<frozen importlib._bootstrap_external>", line 839, in exec_module
  File "<frozen importlib._bootstrap_external>", line 976, in get_code
  File "<frozen importlib._bootstrap_external>", line 906, in source_to_code
  File "<frozen importlib._bootstrap>", line 219, in _call_with_frames_removed
  File "/opt/airflow/dags/google_analytics_data_etl.py", line 8
    }
    ^
SyntaxError: invalid syntax
[2024-07-16T14:20:25.234+0000] {processor.py:842} WARNING - No viable dags retrieved from /opt/airflow/dags/google_analytics_data_etl.py
[2024-07-16T14:20:25.253+0000] {processor.py:183} INFO - Processing /opt/airflow/dags/google_analytics_data_etl.py took 0.117 seconds
[2024-07-16T14:20:55.627+0000] {processor.py:161} INFO - Started process (PID=5478) to work on /opt/airflow/dags/google_analytics_data_etl.py
[2024-07-16T14:20:55.630+0000] {processor.py:830} INFO - Processing file /opt/airflow/dags/google_analytics_data_etl.py for tasks to queue
[2024-07-16T14:20:55.633+0000] {logging_mixin.py:188} INFO - [2024-07-16T14:20:55.632+0000] {dagbag.py:538} INFO - Filling up the DagBag from /opt/airflow/dags/google_analytics_data_etl.py
[2024-07-16T14:20:55.658+0000] {logging_mixin.py:188} INFO - [2024-07-16T14:20:55.658+0000] {dagbag.py:348} ERROR - Failed to import: /opt/airflow/dags/google_analytics_data_etl.py
Traceback (most recent call last):
  File "/home/airflow/.local/lib/python3.8/site-packages/airflow/models/dagbag.py", line 344, in parse
    loader.exec_module(new_module)
  File "<frozen importlib._bootstrap_external>", line 839, in exec_module
  File "<frozen importlib._bootstrap_external>", line 976, in get_code
  File "<frozen importlib._bootstrap_external>", line 906, in source_to_code
  File "<frozen importlib._bootstrap>", line 219, in _call_with_frames_removed
  File "/opt/airflow/dags/google_analytics_data_etl.py", line 8
    }
    ^
SyntaxError: invalid syntax
[2024-07-16T14:20:55.659+0000] {processor.py:842} WARNING - No viable dags retrieved from /opt/airflow/dags/google_analytics_data_etl.py
[2024-07-16T14:20:55.678+0000] {processor.py:183} INFO - Processing /opt/airflow/dags/google_analytics_data_etl.py took 0.058 seconds
[2024-07-16T14:21:26.467+0000] {processor.py:161} INFO - Started process (PID=5534) to work on /opt/airflow/dags/google_analytics_data_etl.py
[2024-07-16T14:21:26.470+0000] {processor.py:830} INFO - Processing file /opt/airflow/dags/google_analytics_data_etl.py for tasks to queue
[2024-07-16T14:21:26.479+0000] {logging_mixin.py:188} INFO - [2024-07-16T14:21:26.478+0000] {dagbag.py:538} INFO - Filling up the DagBag from /opt/airflow/dags/google_analytics_data_etl.py
[2024-07-16T14:21:26.625+0000] {logging_mixin.py:188} INFO - [2024-07-16T14:21:26.621+0000] {dagbag.py:348} ERROR - Failed to import: /opt/airflow/dags/google_analytics_data_etl.py
Traceback (most recent call last):
  File "/home/airflow/.local/lib/python3.8/site-packages/airflow/models/dagbag.py", line 344, in parse
    loader.exec_module(new_module)
  File "<frozen importlib._bootstrap_external>", line 839, in exec_module
  File "<frozen importlib._bootstrap_external>", line 976, in get_code
  File "<frozen importlib._bootstrap_external>", line 906, in source_to_code
  File "<frozen importlib._bootstrap>", line 219, in _call_with_frames_removed
  File "/opt/airflow/dags/google_analytics_data_etl.py", line 8
    }
    ^
SyntaxError: invalid syntax
[2024-07-16T14:21:26.628+0000] {processor.py:842} WARNING - No viable dags retrieved from /opt/airflow/dags/google_analytics_data_etl.py
[2024-07-16T14:21:26.668+0000] {processor.py:183} INFO - Processing /opt/airflow/dags/google_analytics_data_etl.py took 0.212 seconds
[2024-07-16T14:21:57.773+0000] {processor.py:161} INFO - Started process (PID=5589) to work on /opt/airflow/dags/google_analytics_data_etl.py
[2024-07-16T14:21:57.780+0000] {processor.py:830} INFO - Processing file /opt/airflow/dags/google_analytics_data_etl.py for tasks to queue
[2024-07-16T14:21:57.787+0000] {logging_mixin.py:188} INFO - [2024-07-16T14:21:57.787+0000] {dagbag.py:538} INFO - Filling up the DagBag from /opt/airflow/dags/google_analytics_data_etl.py
[2024-07-16T14:21:57.845+0000] {logging_mixin.py:188} INFO - [2024-07-16T14:21:57.841+0000] {dagbag.py:348} ERROR - Failed to import: /opt/airflow/dags/google_analytics_data_etl.py
Traceback (most recent call last):
  File "/home/airflow/.local/lib/python3.8/site-packages/airflow/models/dagbag.py", line 344, in parse
    loader.exec_module(new_module)
  File "<frozen importlib._bootstrap_external>", line 839, in exec_module
  File "<frozen importlib._bootstrap_external>", line 976, in get_code
  File "<frozen importlib._bootstrap_external>", line 906, in source_to_code
  File "<frozen importlib._bootstrap>", line 219, in _call_with_frames_removed
  File "/opt/airflow/dags/google_analytics_data_etl.py", line 8
    }
    ^
SyntaxError: invalid syntax
[2024-07-16T14:21:57.848+0000] {processor.py:842} WARNING - No viable dags retrieved from /opt/airflow/dags/google_analytics_data_etl.py
[2024-07-16T14:21:57.895+0000] {processor.py:183} INFO - Processing /opt/airflow/dags/google_analytics_data_etl.py took 0.138 seconds
[2024-07-16T14:22:14.381+0000] {processor.py:161} INFO - Started process (PID=5610) to work on /opt/airflow/dags/google_analytics_data_etl.py
[2024-07-16T14:22:14.383+0000] {processor.py:830} INFO - Processing file /opt/airflow/dags/google_analytics_data_etl.py for tasks to queue
[2024-07-16T14:22:14.387+0000] {logging_mixin.py:188} INFO - [2024-07-16T14:22:14.386+0000] {dagbag.py:538} INFO - Filling up the DagBag from /opt/airflow/dags/google_analytics_data_etl.py
[2024-07-16T14:22:14.433+0000] {logging_mixin.py:188} INFO - [2024-07-16T14:22:14.428+0000] {dagbag.py:348} ERROR - Failed to import: /opt/airflow/dags/google_analytics_data_etl.py
Traceback (most recent call last):
  File "/home/airflow/.local/lib/python3.8/site-packages/airflow/models/dagbag.py", line 344, in parse
    loader.exec_module(new_module)
  File "<frozen importlib._bootstrap_external>", line 843, in exec_module
  File "<frozen importlib._bootstrap>", line 219, in _call_with_frames_removed
  File "/opt/airflow/dags/google_analytics_data_etl.py", line 7, in <module>
    'start_date': datetime()
TypeError: function missing required argument 'year' (pos 1)
[2024-07-16T14:22:14.435+0000] {processor.py:842} WARNING - No viable dags retrieved from /opt/airflow/dags/google_analytics_data_etl.py
[2024-07-16T14:22:14.454+0000] {processor.py:183} INFO - Processing /opt/airflow/dags/google_analytics_data_etl.py took 0.078 seconds
[2024-07-16T14:22:18.959+0000] {processor.py:161} INFO - Started process (PID=5619) to work on /opt/airflow/dags/google_analytics_data_etl.py
[2024-07-16T14:22:18.960+0000] {processor.py:830} INFO - Processing file /opt/airflow/dags/google_analytics_data_etl.py for tasks to queue
[2024-07-16T14:22:18.963+0000] {logging_mixin.py:188} INFO - [2024-07-16T14:22:18.962+0000] {dagbag.py:538} INFO - Filling up the DagBag from /opt/airflow/dags/google_analytics_data_etl.py
[2024-07-16T14:22:19.001+0000] {logging_mixin.py:188} INFO - [2024-07-16T14:22:18.992+0000] {dagbag.py:348} ERROR - Failed to import: /opt/airflow/dags/google_analytics_data_etl.py
Traceback (most recent call last):
  File "/home/airflow/.local/lib/python3.8/site-packages/airflow/models/dagbag.py", line 344, in parse
    loader.exec_module(new_module)
  File "<frozen importlib._bootstrap_external>", line 843, in exec_module
  File "<frozen importlib._bootstrap>", line 219, in _call_with_frames_removed
  File "/opt/airflow/dags/google_analytics_data_etl.py", line 7, in <module>
    'start_date': datetime(2023, )
TypeError: function missing required argument 'month' (pos 2)
[2024-07-16T14:22:19.003+0000] {processor.py:842} WARNING - No viable dags retrieved from /opt/airflow/dags/google_analytics_data_etl.py
[2024-07-16T14:22:19.025+0000] {processor.py:183} INFO - Processing /opt/airflow/dags/google_analytics_data_etl.py took 0.069 seconds
[2024-07-16T14:22:22.599+0000] {processor.py:161} INFO - Started process (PID=5625) to work on /opt/airflow/dags/google_analytics_data_etl.py
[2024-07-16T14:22:22.603+0000] {processor.py:830} INFO - Processing file /opt/airflow/dags/google_analytics_data_etl.py for tasks to queue
[2024-07-16T14:22:22.608+0000] {logging_mixin.py:188} INFO - [2024-07-16T14:22:22.608+0000] {dagbag.py:538} INFO - Filling up the DagBag from /opt/airflow/dags/google_analytics_data_etl.py
[2024-07-16T14:22:22.665+0000] {logging_mixin.py:188} INFO - [2024-07-16T14:22:22.658+0000] {dagbag.py:348} ERROR - Failed to import: /opt/airflow/dags/google_analytics_data_etl.py
Traceback (most recent call last):
  File "/home/airflow/.local/lib/python3.8/site-packages/airflow/models/dagbag.py", line 344, in parse
    loader.exec_module(new_module)
  File "<frozen importlib._bootstrap_external>", line 843, in exec_module
  File "<frozen importlib._bootstrap>", line 219, in _call_with_frames_removed
  File "/opt/airflow/dags/google_analytics_data_etl.py", line 7, in <module>
    'start_date': datetime(2023, 8)
TypeError: function missing required argument 'day' (pos 3)
[2024-07-16T14:22:22.667+0000] {processor.py:842} WARNING - No viable dags retrieved from /opt/airflow/dags/google_analytics_data_etl.py
[2024-07-16T14:22:22.693+0000] {processor.py:183} INFO - Processing /opt/airflow/dags/google_analytics_data_etl.py took 0.114 seconds
[2024-07-16T14:22:32.309+0000] {processor.py:161} INFO - Started process (PID=5659) to work on /opt/airflow/dags/google_analytics_data_etl.py
[2024-07-16T14:22:32.310+0000] {processor.py:830} INFO - Processing file /opt/airflow/dags/google_analytics_data_etl.py for tasks to queue
[2024-07-16T14:22:32.312+0000] {logging_mixin.py:188} INFO - [2024-07-16T14:22:32.312+0000] {dagbag.py:538} INFO - Filling up the DagBag from /opt/airflow/dags/google_analytics_data_etl.py
[2024-07-16T14:22:32.338+0000] {logging_mixin.py:188} INFO - [2024-07-16T14:22:32.337+0000] {dagbag.py:348} ERROR - Failed to import: /opt/airflow/dags/google_analytics_data_etl.py
Traceback (most recent call last):
  File "/home/airflow/.local/lib/python3.8/site-packages/airflow/models/dagbag.py", line 344, in parse
    loader.exec_module(new_module)
  File "<frozen importlib._bootstrap_external>", line 839, in exec_module
  File "<frozen importlib._bootstrap_external>", line 976, in get_code
  File "<frozen importlib._bootstrap_external>", line 906, in source_to_code
  File "<frozen importlib._bootstrap>", line 219, in _call_with_frames_removed
  File "/opt/airflow/dags/google_analytics_data_etl.py", line 9
    }
    ^
SyntaxError: invalid syntax
[2024-07-16T14:22:32.339+0000] {processor.py:842} WARNING - No viable dags retrieved from /opt/airflow/dags/google_analytics_data_etl.py
[2024-07-16T14:22:32.362+0000] {processor.py:183} INFO - Processing /opt/airflow/dags/google_analytics_data_etl.py took 0.056 seconds
[2024-07-16T14:22:42.645+0000] {processor.py:161} INFO - Started process (PID=5664) to work on /opt/airflow/dags/google_analytics_data_etl.py
[2024-07-16T14:22:42.646+0000] {processor.py:830} INFO - Processing file /opt/airflow/dags/google_analytics_data_etl.py for tasks to queue
[2024-07-16T14:22:42.648+0000] {logging_mixin.py:188} INFO - [2024-07-16T14:22:42.648+0000] {dagbag.py:538} INFO - Filling up the DagBag from /opt/airflow/dags/google_analytics_data_etl.py
[2024-07-16T14:22:42.666+0000] {logging_mixin.py:188} INFO - [2024-07-16T14:22:42.665+0000] {dagbag.py:348} ERROR - Failed to import: /opt/airflow/dags/google_analytics_data_etl.py
Traceback (most recent call last):
  File "/home/airflow/.local/lib/python3.8/site-packages/airflow/models/dagbag.py", line 344, in parse
    loader.exec_module(new_module)
  File "<frozen importlib._bootstrap_external>", line 839, in exec_module
  File "<frozen importlib._bootstrap_external>", line 976, in get_code
  File "<frozen importlib._bootstrap_external>", line 906, in source_to_code
  File "<frozen importlib._bootstrap>", line 219, in _call_with_frames_removed
  File "/opt/airflow/dags/google_analytics_data_etl.py", line 9
    }
    ^
SyntaxError: invalid syntax
[2024-07-16T14:22:42.666+0000] {processor.py:842} WARNING - No viable dags retrieved from /opt/airflow/dags/google_analytics_data_etl.py
[2024-07-16T14:22:42.684+0000] {processor.py:183} INFO - Processing /opt/airflow/dags/google_analytics_data_etl.py took 0.042 seconds
[2024-07-16T14:22:48.764+0000] {processor.py:161} INFO - Started process (PID=5676) to work on /opt/airflow/dags/google_analytics_data_etl.py
[2024-07-16T14:22:48.768+0000] {processor.py:830} INFO - Processing file /opt/airflow/dags/google_analytics_data_etl.py for tasks to queue
[2024-07-16T14:22:48.775+0000] {logging_mixin.py:188} INFO - [2024-07-16T14:22:48.775+0000] {dagbag.py:538} INFO - Filling up the DagBag from /opt/airflow/dags/google_analytics_data_etl.py
[2024-07-16T14:22:48.807+0000] {logging_mixin.py:188} INFO - [2024-07-16T14:22:48.805+0000] {dagbag.py:348} ERROR - Failed to import: /opt/airflow/dags/google_analytics_data_etl.py
Traceback (most recent call last):
  File "/home/airflow/.local/lib/python3.8/site-packages/airflow/models/dagbag.py", line 344, in parse
    loader.exec_module(new_module)
  File "<frozen importlib._bootstrap_external>", line 839, in exec_module
  File "<frozen importlib._bootstrap_external>", line 976, in get_code
  File "<frozen importlib._bootstrap_external>", line 906, in source_to_code
  File "<frozen importlib._bootstrap>", line 219, in _call_with_frames_removed
  File "/opt/airflow/dags/google_analytics_data_etl.py", line 9
    }
    ^
SyntaxError: invalid syntax
[2024-07-16T14:22:48.808+0000] {processor.py:842} WARNING - No viable dags retrieved from /opt/airflow/dags/google_analytics_data_etl.py
[2024-07-16T14:22:48.835+0000] {processor.py:183} INFO - Processing /opt/airflow/dags/google_analytics_data_etl.py took 0.082 seconds
[2024-07-16T14:23:19.289+0000] {processor.py:161} INFO - Started process (PID=5731) to work on /opt/airflow/dags/google_analytics_data_etl.py
[2024-07-16T14:23:19.294+0000] {processor.py:830} INFO - Processing file /opt/airflow/dags/google_analytics_data_etl.py for tasks to queue
[2024-07-16T14:23:19.304+0000] {logging_mixin.py:188} INFO - [2024-07-16T14:23:19.303+0000] {dagbag.py:538} INFO - Filling up the DagBag from /opt/airflow/dags/google_analytics_data_etl.py
[2024-07-16T14:23:19.350+0000] {logging_mixin.py:188} INFO - [2024-07-16T14:23:19.350+0000] {dagbag.py:348} ERROR - Failed to import: /opt/airflow/dags/google_analytics_data_etl.py
Traceback (most recent call last):
  File "/home/airflow/.local/lib/python3.8/site-packages/airflow/models/dagbag.py", line 344, in parse
    loader.exec_module(new_module)
  File "<frozen importlib._bootstrap_external>", line 839, in exec_module
  File "<frozen importlib._bootstrap_external>", line 976, in get_code
  File "<frozen importlib._bootstrap_external>", line 906, in source_to_code
  File "<frozen importlib._bootstrap>", line 219, in _call_with_frames_removed
  File "/opt/airflow/dags/google_analytics_data_etl.py", line 9
    }
    ^
SyntaxError: invalid syntax
[2024-07-16T14:23:19.352+0000] {processor.py:842} WARNING - No viable dags retrieved from /opt/airflow/dags/google_analytics_data_etl.py
[2024-07-16T14:23:19.368+0000] {processor.py:183} INFO - Processing /opt/airflow/dags/google_analytics_data_etl.py took 0.098 seconds
[2024-07-16T14:23:22.825+0000] {processor.py:161} INFO - Started process (PID=5736) to work on /opt/airflow/dags/google_analytics_data_etl.py
[2024-07-16T14:23:22.832+0000] {processor.py:830} INFO - Processing file /opt/airflow/dags/google_analytics_data_etl.py for tasks to queue
[2024-07-16T14:23:22.834+0000] {logging_mixin.py:188} INFO - [2024-07-16T14:23:22.833+0000] {dagbag.py:538} INFO - Filling up the DagBag from /opt/airflow/dags/google_analytics_data_etl.py
[2024-07-16T14:23:22.899+0000] {processor.py:842} WARNING - No viable dags retrieved from /opt/airflow/dags/google_analytics_data_etl.py
[2024-07-16T14:23:22.916+0000] {processor.py:183} INFO - Processing /opt/airflow/dags/google_analytics_data_etl.py took 0.093 seconds
[2024-07-16T14:23:31.548+0000] {processor.py:161} INFO - Started process (PID=5772) to work on /opt/airflow/dags/google_analytics_data_etl.py
[2024-07-16T14:23:31.549+0000] {processor.py:830} INFO - Processing file /opt/airflow/dags/google_analytics_data_etl.py for tasks to queue
[2024-07-16T14:23:31.551+0000] {logging_mixin.py:188} INFO - [2024-07-16T14:23:31.551+0000] {dagbag.py:538} INFO - Filling up the DagBag from /opt/airflow/dags/google_analytics_data_etl.py
[2024-07-16T14:23:31.575+0000] {logging_mixin.py:188} INFO - [2024-07-16T14:23:31.575+0000] {dagbag.py:348} ERROR - Failed to import: /opt/airflow/dags/google_analytics_data_etl.py
Traceback (most recent call last):
  File "/home/airflow/.local/lib/python3.8/site-packages/airflow/models/dagbag.py", line 344, in parse
    loader.exec_module(new_module)
  File "<frozen importlib._bootstrap_external>", line 839, in exec_module
  File "<frozen importlib._bootstrap_external>", line 976, in get_code
  File "<frozen importlib._bootstrap_external>", line 906, in source_to_code
  File "<frozen importlib._bootstrap>", line 219, in _call_with_frames_removed
  File "/opt/airflow/dags/google_analytics_data_etl.py", line 12
    with DAG
           ^
SyntaxError: invalid syntax
[2024-07-16T14:23:31.576+0000] {processor.py:842} WARNING - No viable dags retrieved from /opt/airflow/dags/google_analytics_data_etl.py
[2024-07-16T14:23:31.601+0000] {processor.py:183} INFO - Processing /opt/airflow/dags/google_analytics_data_etl.py took 0.058 seconds
[2024-07-16T14:23:35.832+0000] {processor.py:161} INFO - Started process (PID=5773) to work on /opt/airflow/dags/google_analytics_data_etl.py
[2024-07-16T14:23:35.835+0000] {processor.py:830} INFO - Processing file /opt/airflow/dags/google_analytics_data_etl.py for tasks to queue
[2024-07-16T14:23:35.842+0000] {logging_mixin.py:188} INFO - [2024-07-16T14:23:35.841+0000] {dagbag.py:538} INFO - Filling up the DagBag from /opt/airflow/dags/google_analytics_data_etl.py
[2024-07-16T14:23:35.872+0000] {logging_mixin.py:188} INFO - [2024-07-16T14:23:35.871+0000] {dagbag.py:348} ERROR - Failed to import: /opt/airflow/dags/google_analytics_data_etl.py
Traceback (most recent call last):
  File "/home/airflow/.local/lib/python3.8/site-packages/airflow/models/dagbag.py", line 344, in parse
    loader.exec_module(new_module)
  File "<frozen importlib._bootstrap_external>", line 839, in exec_module
  File "<frozen importlib._bootstrap_external>", line 976, in get_code
  File "<frozen importlib._bootstrap_external>", line 906, in source_to_code
  File "<frozen importlib._bootstrap>", line 219, in _call_with_frames_removed
  File "/opt/airflow/dags/google_analytics_data_etl.py", line 12
    with DAG{
            ^
SyntaxError: invalid syntax
[2024-07-16T14:23:35.873+0000] {processor.py:842} WARNING - No viable dags retrieved from /opt/airflow/dags/google_analytics_data_etl.py
[2024-07-16T14:23:35.891+0000] {processor.py:183} INFO - Processing /opt/airflow/dags/google_analytics_data_etl.py took 0.065 seconds
[2024-07-16T14:23:46.653+0000] {processor.py:161} INFO - Started process (PID=5778) to work on /opt/airflow/dags/google_analytics_data_etl.py
[2024-07-16T14:23:46.654+0000] {processor.py:830} INFO - Processing file /opt/airflow/dags/google_analytics_data_etl.py for tasks to queue
[2024-07-16T14:23:46.656+0000] {logging_mixin.py:188} INFO - [2024-07-16T14:23:46.656+0000] {dagbag.py:538} INFO - Filling up the DagBag from /opt/airflow/dags/google_analytics_data_etl.py
[2024-07-16T14:23:46.742+0000] {logging_mixin.py:188} INFO - [2024-07-16T14:23:46.742+0000] {dagbag.py:348} ERROR - Failed to import: /opt/airflow/dags/google_analytics_data_etl.py
Traceback (most recent call last):
  File "/home/airflow/.local/lib/python3.8/site-packages/airflow/models/dagbag.py", line 344, in parse
    loader.exec_module(new_module)
  File "<frozen importlib._bootstrap_external>", line 839, in exec_module
  File "<frozen importlib._bootstrap_external>", line 976, in get_code
  File "<frozen importlib._bootstrap_external>", line 906, in source_to_code
  File "<frozen importlib._bootstrap>", line 219, in _call_with_frames_removed
  File "/opt/airflow/dags/google_analytics_data_etl.py", line 14
    )
    ^
SyntaxError: invalid syntax
[2024-07-16T14:23:46.769+0000] {processor.py:842} WARNING - No viable dags retrieved from /opt/airflow/dags/google_analytics_data_etl.py
[2024-07-16T14:23:46.793+0000] {processor.py:183} INFO - Processing /opt/airflow/dags/google_analytics_data_etl.py took 0.143 seconds
[2024-07-16T14:24:16.939+0000] {processor.py:161} INFO - Started process (PID=5835) to work on /opt/airflow/dags/google_analytics_data_etl.py
[2024-07-16T14:24:16.952+0000] {processor.py:830} INFO - Processing file /opt/airflow/dags/google_analytics_data_etl.py for tasks to queue
[2024-07-16T14:24:16.955+0000] {logging_mixin.py:188} INFO - [2024-07-16T14:24:16.955+0000] {dagbag.py:538} INFO - Filling up the DagBag from /opt/airflow/dags/google_analytics_data_etl.py
[2024-07-16T14:24:17.075+0000] {logging_mixin.py:188} INFO - [2024-07-16T14:24:17.074+0000] {dagbag.py:348} ERROR - Failed to import: /opt/airflow/dags/google_analytics_data_etl.py
Traceback (most recent call last):
  File "/home/airflow/.local/lib/python3.8/site-packages/airflow/models/dagbag.py", line 344, in parse
    loader.exec_module(new_module)
  File "<frozen importlib._bootstrap_external>", line 839, in exec_module
  File "<frozen importlib._bootstrap_external>", line 976, in get_code
  File "<frozen importlib._bootstrap_external>", line 906, in source_to_code
  File "<frozen importlib._bootstrap>", line 219, in _call_with_frames_removed
  File "/opt/airflow/dags/google_analytics_data_etl.py", line 14
    )
    ^
SyntaxError: invalid syntax
[2024-07-16T14:24:17.078+0000] {processor.py:842} WARNING - No viable dags retrieved from /opt/airflow/dags/google_analytics_data_etl.py
[2024-07-16T14:24:17.096+0000] {processor.py:183} INFO - Processing /opt/airflow/dags/google_analytics_data_etl.py took 0.160 seconds
[2024-07-16T14:24:29.646+0000] {processor.py:161} INFO - Started process (PID=5876) to work on /opt/airflow/dags/google_analytics_data_etl.py
[2024-07-16T14:24:29.647+0000] {processor.py:830} INFO - Processing file /opt/airflow/dags/google_analytics_data_etl.py for tasks to queue
[2024-07-16T14:24:29.649+0000] {logging_mixin.py:188} INFO - [2024-07-16T14:24:29.649+0000] {dagbag.py:538} INFO - Filling up the DagBag from /opt/airflow/dags/google_analytics_data_etl.py
[2024-07-16T14:24:29.666+0000] {logging_mixin.py:188} INFO - [2024-07-16T14:24:29.665+0000] {dagbag.py:348} ERROR - Failed to import: /opt/airflow/dags/google_analytics_data_etl.py
Traceback (most recent call last):
  File "/home/airflow/.local/lib/python3.8/site-packages/airflow/models/dagbag.py", line 344, in parse
    loader.exec_module(new_module)
  File "<frozen importlib._bootstrap_external>", line 839, in exec_module
  File "<frozen importlib._bootstrap_external>", line 976, in get_code
  File "<frozen importlib._bootstrap_external>", line 906, in source_to_code
  File "<frozen importlib._bootstrap>", line 219, in _call_with_frames_removed
  File "/opt/airflow/dags/google_analytics_data_etl.py", line 14
    )
    ^
SyntaxError: invalid syntax
[2024-07-16T14:24:29.666+0000] {processor.py:842} WARNING - No viable dags retrieved from /opt/airflow/dags/google_analytics_data_etl.py
[2024-07-16T14:24:29.684+0000] {processor.py:183} INFO - Processing /opt/airflow/dags/google_analytics_data_etl.py took 0.040 seconds
[2024-07-16T14:25:00.291+0000] {processor.py:161} INFO - Started process (PID=5932) to work on /opt/airflow/dags/google_analytics_data_etl.py
[2024-07-16T14:25:00.296+0000] {processor.py:830} INFO - Processing file /opt/airflow/dags/google_analytics_data_etl.py for tasks to queue
[2024-07-16T14:25:00.307+0000] {logging_mixin.py:188} INFO - [2024-07-16T14:25:00.306+0000] {dagbag.py:538} INFO - Filling up the DagBag from /opt/airflow/dags/google_analytics_data_etl.py
[2024-07-16T14:25:00.371+0000] {logging_mixin.py:188} INFO - [2024-07-16T14:25:00.368+0000] {dagbag.py:348} ERROR - Failed to import: /opt/airflow/dags/google_analytics_data_etl.py
Traceback (most recent call last):
  File "/home/airflow/.local/lib/python3.8/site-packages/airflow/models/dagbag.py", line 344, in parse
    loader.exec_module(new_module)
  File "<frozen importlib._bootstrap_external>", line 839, in exec_module
  File "<frozen importlib._bootstrap_external>", line 976, in get_code
  File "<frozen importlib._bootstrap_external>", line 906, in source_to_code
  File "<frozen importlib._bootstrap>", line 219, in _call_with_frames_removed
  File "/opt/airflow/dags/google_analytics_data_etl.py", line 14
    )
    ^
SyntaxError: invalid syntax
[2024-07-16T14:25:00.374+0000] {processor.py:842} WARNING - No viable dags retrieved from /opt/airflow/dags/google_analytics_data_etl.py
[2024-07-16T14:25:00.409+0000] {processor.py:183} INFO - Processing /opt/airflow/dags/google_analytics_data_etl.py took 0.134 seconds
[2024-07-16T14:25:02.494+0000] {processor.py:161} INFO - Started process (PID=5944) to work on /opt/airflow/dags/google_analytics_data_etl.py
[2024-07-16T14:25:02.501+0000] {processor.py:830} INFO - Processing file /opt/airflow/dags/google_analytics_data_etl.py for tasks to queue
[2024-07-16T14:25:02.507+0000] {logging_mixin.py:188} INFO - [2024-07-16T14:25:02.506+0000] {dagbag.py:538} INFO - Filling up the DagBag from /opt/airflow/dags/google_analytics_data_etl.py
[2024-07-16T14:25:02.531+0000] {logging_mixin.py:188} INFO - [2024-07-16T14:25:02.530+0000] {dagbag.py:348} ERROR - Failed to import: /opt/airflow/dags/google_analytics_data_etl.py
Traceback (most recent call last):
  File "/home/airflow/.local/lib/python3.8/site-packages/airflow/models/dagbag.py", line 344, in parse
    loader.exec_module(new_module)
  File "<frozen importlib._bootstrap_external>", line 839, in exec_module
  File "<frozen importlib._bootstrap_external>", line 976, in get_code
  File "<frozen importlib._bootstrap_external>", line 906, in source_to_code
  File "<frozen importlib._bootstrap>", line 219, in _call_with_frames_removed
  File "/opt/airflow/dags/google_analytics_data_etl.py", line 15
    )
    ^
SyntaxError: invalid syntax
[2024-07-16T14:25:02.532+0000] {processor.py:842} WARNING - No viable dags retrieved from /opt/airflow/dags/google_analytics_data_etl.py
[2024-07-16T14:25:02.552+0000] {processor.py:183} INFO - Processing /opt/airflow/dags/google_analytics_data_etl.py took 0.064 seconds
[2024-07-16T14:25:13.983+0000] {processor.py:161} INFO - Started process (PID=5947) to work on /opt/airflow/dags/google_analytics_data_etl.py
[2024-07-16T14:25:13.985+0000] {processor.py:830} INFO - Processing file /opt/airflow/dags/google_analytics_data_etl.py for tasks to queue
[2024-07-16T14:25:13.990+0000] {logging_mixin.py:188} INFO - [2024-07-16T14:25:13.989+0000] {dagbag.py:538} INFO - Filling up the DagBag from /opt/airflow/dags/google_analytics_data_etl.py
[2024-07-16T14:25:14.021+0000] {logging_mixin.py:188} INFO - [2024-07-16T14:25:14.020+0000] {dagbag.py:348} ERROR - Failed to import: /opt/airflow/dags/google_analytics_data_etl.py
Traceback (most recent call last):
  File "/home/airflow/.local/lib/python3.8/site-packages/airflow/models/dagbag.py", line 344, in parse
    loader.exec_module(new_module)
  File "<frozen importlib._bootstrap_external>", line 839, in exec_module
  File "<frozen importlib._bootstrap_external>", line 976, in get_code
  File "<frozen importlib._bootstrap_external>", line 906, in source_to_code
  File "<frozen importlib._bootstrap>", line 219, in _call_with_frames_removed
  File "/opt/airflow/dags/google_analytics_data_etl.py", line 15
    )
    ^
SyntaxError: invalid syntax
[2024-07-16T14:25:14.023+0000] {processor.py:842} WARNING - No viable dags retrieved from /opt/airflow/dags/google_analytics_data_etl.py
[2024-07-16T14:25:14.069+0000] {processor.py:183} INFO - Processing /opt/airflow/dags/google_analytics_data_etl.py took 0.089 seconds
[2024-07-16T14:25:38.091+0000] {processor.py:161} INFO - Started process (PID=6001) to work on /opt/airflow/dags/google_analytics_data_etl.py
[2024-07-16T14:25:38.094+0000] {processor.py:830} INFO - Processing file /opt/airflow/dags/google_analytics_data_etl.py for tasks to queue
[2024-07-16T14:25:38.102+0000] {logging_mixin.py:188} INFO - [2024-07-16T14:25:38.101+0000] {dagbag.py:538} INFO - Filling up the DagBag from /opt/airflow/dags/google_analytics_data_etl.py
[2024-07-16T14:25:38.253+0000] {logging_mixin.py:188} INFO - [2024-07-16T14:25:38.248+0000] {dagbag.py:348} ERROR - Failed to import: /opt/airflow/dags/google_analytics_data_etl.py
Traceback (most recent call last):
  File "/home/airflow/.local/lib/python3.8/site-packages/airflow/models/dagbag.py", line 344, in parse
    loader.exec_module(new_module)
  File "<frozen importlib._bootstrap_external>", line 839, in exec_module
  File "<frozen importlib._bootstrap_external>", line 976, in get_code
  File "<frozen importlib._bootstrap_external>", line 906, in source_to_code
  File "<frozen importlib._bootstrap>", line 219, in _call_with_frames_removed
  File "/opt/airflow/dags/google_analytics_data_etl.py", line 16
    )
    ^
SyntaxError: invalid syntax
[2024-07-16T14:25:38.256+0000] {processor.py:842} WARNING - No viable dags retrieved from /opt/airflow/dags/google_analytics_data_etl.py
[2024-07-16T14:25:38.320+0000] {processor.py:183} INFO - Processing /opt/airflow/dags/google_analytics_data_etl.py took 0.240 seconds
[2024-07-16T14:25:42.141+0000] {processor.py:161} INFO - Started process (PID=6002) to work on /opt/airflow/dags/google_analytics_data_etl.py
[2024-07-16T14:25:42.143+0000] {processor.py:830} INFO - Processing file /opt/airflow/dags/google_analytics_data_etl.py for tasks to queue
[2024-07-16T14:25:42.147+0000] {logging_mixin.py:188} INFO - [2024-07-16T14:25:42.146+0000] {dagbag.py:538} INFO - Filling up the DagBag from /opt/airflow/dags/google_analytics_data_etl.py
[2024-07-16T14:25:42.172+0000] {logging_mixin.py:188} INFO - [2024-07-16T14:25:42.171+0000] {dagbag.py:348} ERROR - Failed to import: /opt/airflow/dags/google_analytics_data_etl.py
Traceback (most recent call last):
  File "/home/airflow/.local/lib/python3.8/site-packages/airflow/models/dagbag.py", line 344, in parse
    loader.exec_module(new_module)
  File "<frozen importlib._bootstrap_external>", line 839, in exec_module
  File "<frozen importlib._bootstrap_external>", line 976, in get_code
  File "<frozen importlib._bootstrap_external>", line 906, in source_to_code
  File "<frozen importlib._bootstrap>", line 219, in _call_with_frames_removed
  File "/opt/airflow/dags/google_analytics_data_etl.py", line 16
    )
    ^
SyntaxError: invalid syntax
[2024-07-16T14:25:42.173+0000] {processor.py:842} WARNING - No viable dags retrieved from /opt/airflow/dags/google_analytics_data_etl.py
[2024-07-16T14:25:42.192+0000] {processor.py:183} INFO - Processing /opt/airflow/dags/google_analytics_data_etl.py took 0.056 seconds
[2024-07-16T14:25:45.470+0000] {processor.py:161} INFO - Started process (PID=6005) to work on /opt/airflow/dags/google_analytics_data_etl.py
[2024-07-16T14:25:45.472+0000] {processor.py:830} INFO - Processing file /opt/airflow/dags/google_analytics_data_etl.py for tasks to queue
[2024-07-16T14:25:45.474+0000] {logging_mixin.py:188} INFO - [2024-07-16T14:25:45.474+0000] {dagbag.py:538} INFO - Filling up the DagBag from /opt/airflow/dags/google_analytics_data_etl.py
[2024-07-16T14:25:45.492+0000] {logging_mixin.py:188} INFO - [2024-07-16T14:25:45.491+0000] {dagbag.py:348} ERROR - Failed to import: /opt/airflow/dags/google_analytics_data_etl.py
Traceback (most recent call last):
  File "/home/airflow/.local/lib/python3.8/site-packages/airflow/models/dagbag.py", line 344, in parse
    loader.exec_module(new_module)
  File "<frozen importlib._bootstrap_external>", line 839, in exec_module
  File "<frozen importlib._bootstrap_external>", line 976, in get_code
  File "<frozen importlib._bootstrap_external>", line 906, in source_to_code
  File "<frozen importlib._bootstrap>", line 219, in _call_with_frames_removed
  File "/opt/airflow/dags/google_analytics_data_etl.py", line 17
    )
    ^
SyntaxError: invalid syntax
[2024-07-16T14:25:45.492+0000] {processor.py:842} WARNING - No viable dags retrieved from /opt/airflow/dags/google_analytics_data_etl.py
[2024-07-16T14:25:45.518+0000] {processor.py:183} INFO - Processing /opt/airflow/dags/google_analytics_data_etl.py took 0.050 seconds
[2024-07-16T14:25:49.822+0000] {processor.py:161} INFO - Started process (PID=6009) to work on /opt/airflow/dags/google_analytics_data_etl.py
[2024-07-16T14:25:49.826+0000] {processor.py:830} INFO - Processing file /opt/airflow/dags/google_analytics_data_etl.py for tasks to queue
[2024-07-16T14:25:49.841+0000] {logging_mixin.py:188} INFO - [2024-07-16T14:25:49.833+0000] {dagbag.py:538} INFO - Filling up the DagBag from /opt/airflow/dags/google_analytics_data_etl.py
[2024-07-16T14:25:49.883+0000] {logging_mixin.py:188} INFO - [2024-07-16T14:25:49.880+0000] {dagbag.py:348} ERROR - Failed to import: /opt/airflow/dags/google_analytics_data_etl.py
Traceback (most recent call last):
  File "/home/airflow/.local/lib/python3.8/site-packages/airflow/models/dagbag.py", line 344, in parse
    loader.exec_module(new_module)
  File "<frozen importlib._bootstrap_external>", line 839, in exec_module
  File "<frozen importlib._bootstrap_external>", line 976, in get_code
  File "<frozen importlib._bootstrap_external>", line 906, in source_to_code
  File "<frozen importlib._bootstrap>", line 219, in _call_with_frames_removed
  File "/opt/airflow/dags/google_analytics_data_etl.py", line 17
    )
    ^
SyntaxError: invalid syntax
[2024-07-16T14:25:49.884+0000] {processor.py:842} WARNING - No viable dags retrieved from /opt/airflow/dags/google_analytics_data_etl.py
[2024-07-16T14:25:49.903+0000] {processor.py:183} INFO - Processing /opt/airflow/dags/google_analytics_data_etl.py took 0.093 seconds
[2024-07-16T14:25:53.556+0000] {processor.py:161} INFO - Started process (PID=6022) to work on /opt/airflow/dags/google_analytics_data_etl.py
[2024-07-16T14:25:53.559+0000] {processor.py:830} INFO - Processing file /opt/airflow/dags/google_analytics_data_etl.py for tasks to queue
[2024-07-16T14:25:53.563+0000] {logging_mixin.py:188} INFO - [2024-07-16T14:25:53.562+0000] {dagbag.py:538} INFO - Filling up the DagBag from /opt/airflow/dags/google_analytics_data_etl.py
[2024-07-16T14:25:53.605+0000] {logging_mixin.py:188} INFO - [2024-07-16T14:25:53.605+0000] {dagbag.py:348} ERROR - Failed to import: /opt/airflow/dags/google_analytics_data_etl.py
Traceback (most recent call last):
  File "/home/airflow/.local/lib/python3.8/site-packages/airflow/models/dagbag.py", line 344, in parse
    loader.exec_module(new_module)
  File "<frozen importlib._bootstrap_external>", line 839, in exec_module
  File "<frozen importlib._bootstrap_external>", line 976, in get_code
  File "<frozen importlib._bootstrap_external>", line 906, in source_to_code
  File "<frozen importlib._bootstrap>", line 219, in _call_with_frames_removed
  File "/opt/airflow/dags/google_analytics_data_etl.py", line 17
    )
    ^
SyntaxError: invalid syntax
[2024-07-16T14:25:53.608+0000] {processor.py:842} WARNING - No viable dags retrieved from /opt/airflow/dags/google_analytics_data_etl.py
[2024-07-16T14:25:53.631+0000] {processor.py:183} INFO - Processing /opt/airflow/dags/google_analytics_data_etl.py took 0.081 seconds
[2024-07-16T14:26:23.938+0000] {processor.py:161} INFO - Started process (PID=6078) to work on /opt/airflow/dags/google_analytics_data_etl.py
[2024-07-16T14:26:23.939+0000] {processor.py:830} INFO - Processing file /opt/airflow/dags/google_analytics_data_etl.py for tasks to queue
[2024-07-16T14:26:23.944+0000] {logging_mixin.py:188} INFO - [2024-07-16T14:26:23.943+0000] {dagbag.py:538} INFO - Filling up the DagBag from /opt/airflow/dags/google_analytics_data_etl.py
[2024-07-16T14:26:24.040+0000] {logging_mixin.py:188} INFO - [2024-07-16T14:26:24.037+0000] {dagbag.py:348} ERROR - Failed to import: /opt/airflow/dags/google_analytics_data_etl.py
Traceback (most recent call last):
  File "/home/airflow/.local/lib/python3.8/site-packages/airflow/models/dagbag.py", line 344, in parse
    loader.exec_module(new_module)
  File "<frozen importlib._bootstrap_external>", line 839, in exec_module
  File "<frozen importlib._bootstrap_external>", line 976, in get_code
  File "<frozen importlib._bootstrap_external>", line 906, in source_to_code
  File "<frozen importlib._bootstrap>", line 219, in _call_with_frames_removed
  File "/opt/airflow/dags/google_analytics_data_etl.py", line 17
    )
    ^
SyntaxError: invalid syntax
[2024-07-16T14:26:24.052+0000] {processor.py:842} WARNING - No viable dags retrieved from /opt/airflow/dags/google_analytics_data_etl.py
[2024-07-16T14:26:24.128+0000] {processor.py:183} INFO - Processing /opt/airflow/dags/google_analytics_data_etl.py took 0.197 seconds
[2024-07-16T14:26:54.745+0000] {processor.py:161} INFO - Started process (PID=6132) to work on /opt/airflow/dags/google_analytics_data_etl.py
[2024-07-16T14:26:54.746+0000] {processor.py:830} INFO - Processing file /opt/airflow/dags/google_analytics_data_etl.py for tasks to queue
[2024-07-16T14:26:54.750+0000] {logging_mixin.py:188} INFO - [2024-07-16T14:26:54.750+0000] {dagbag.py:538} INFO - Filling up the DagBag from /opt/airflow/dags/google_analytics_data_etl.py
[2024-07-16T14:26:54.771+0000] {logging_mixin.py:188} INFO - [2024-07-16T14:26:54.770+0000] {dagbag.py:348} ERROR - Failed to import: /opt/airflow/dags/google_analytics_data_etl.py
Traceback (most recent call last):
  File "/home/airflow/.local/lib/python3.8/site-packages/airflow/models/dagbag.py", line 344, in parse
    loader.exec_module(new_module)
  File "<frozen importlib._bootstrap_external>", line 839, in exec_module
  File "<frozen importlib._bootstrap_external>", line 976, in get_code
  File "<frozen importlib._bootstrap_external>", line 906, in source_to_code
  File "<frozen importlib._bootstrap>", line 219, in _call_with_frames_removed
  File "/opt/airflow/dags/google_analytics_data_etl.py", line 17
    )
    ^
SyntaxError: invalid syntax
[2024-07-16T14:26:54.772+0000] {processor.py:842} WARNING - No viable dags retrieved from /opt/airflow/dags/google_analytics_data_etl.py
[2024-07-16T14:26:54.791+0000] {processor.py:183} INFO - Processing /opt/airflow/dags/google_analytics_data_etl.py took 0.053 seconds
[2024-07-16T14:27:25.355+0000] {processor.py:161} INFO - Started process (PID=6187) to work on /opt/airflow/dags/google_analytics_data_etl.py
[2024-07-16T14:27:25.359+0000] {processor.py:830} INFO - Processing file /opt/airflow/dags/google_analytics_data_etl.py for tasks to queue
[2024-07-16T14:27:25.366+0000] {logging_mixin.py:188} INFO - [2024-07-16T14:27:25.365+0000] {dagbag.py:538} INFO - Filling up the DagBag from /opt/airflow/dags/google_analytics_data_etl.py
[2024-07-16T14:27:25.443+0000] {logging_mixin.py:188} INFO - [2024-07-16T14:27:25.441+0000] {dagbag.py:348} ERROR - Failed to import: /opt/airflow/dags/google_analytics_data_etl.py
Traceback (most recent call last):
  File "/home/airflow/.local/lib/python3.8/site-packages/airflow/models/dagbag.py", line 344, in parse
    loader.exec_module(new_module)
  File "<frozen importlib._bootstrap_external>", line 839, in exec_module
  File "<frozen importlib._bootstrap_external>", line 976, in get_code
  File "<frozen importlib._bootstrap_external>", line 906, in source_to_code
  File "<frozen importlib._bootstrap>", line 219, in _call_with_frames_removed
  File "/opt/airflow/dags/google_analytics_data_etl.py", line 17
    )
    ^
SyntaxError: invalid syntax
[2024-07-16T14:27:25.444+0000] {processor.py:842} WARNING - No viable dags retrieved from /opt/airflow/dags/google_analytics_data_etl.py
[2024-07-16T14:27:25.475+0000] {processor.py:183} INFO - Processing /opt/airflow/dags/google_analytics_data_etl.py took 0.131 seconds
[2024-07-16T14:27:38.723+0000] {processor.py:161} INFO - Started process (PID=6228) to work on /opt/airflow/dags/google_analytics_data_etl.py
[2024-07-16T14:27:38.726+0000] {processor.py:830} INFO - Processing file /opt/airflow/dags/google_analytics_data_etl.py for tasks to queue
[2024-07-16T14:27:38.731+0000] {logging_mixin.py:188} INFO - [2024-07-16T14:27:38.730+0000] {dagbag.py:538} INFO - Filling up the DagBag from /opt/airflow/dags/google_analytics_data_etl.py
[2024-07-16T14:27:38.781+0000] {logging_mixin.py:188} INFO - [2024-07-16T14:27:38.776+0000] {dagbag.py:348} ERROR - Failed to import: /opt/airflow/dags/google_analytics_data_etl.py
Traceback (most recent call last):
  File "/home/airflow/.local/lib/python3.8/site-packages/airflow/models/dagbag.py", line 344, in parse
    loader.exec_module(new_module)
  File "<frozen importlib._bootstrap_external>", line 839, in exec_module
  File "<frozen importlib._bootstrap_external>", line 976, in get_code
  File "<frozen importlib._bootstrap_external>", line 906, in source_to_code
  File "<frozen importlib._bootstrap>", line 219, in _call_with_frames_removed
  File "/opt/airflow/dags/google_analytics_data_etl.py", line 13
    
    ^
SyntaxError: unexpected EOF while parsing
[2024-07-16T14:27:38.786+0000] {processor.py:842} WARNING - No viable dags retrieved from /opt/airflow/dags/google_analytics_data_etl.py
[2024-07-16T14:27:38.838+0000] {processor.py:183} INFO - Processing /opt/airflow/dags/google_analytics_data_etl.py took 0.117 seconds
[2024-07-16T14:27:50.371+0000] {processor.py:161} INFO - Started process (PID=6233) to work on /opt/airflow/dags/google_analytics_data_etl.py
[2024-07-16T14:27:50.373+0000] {processor.py:830} INFO - Processing file /opt/airflow/dags/google_analytics_data_etl.py for tasks to queue
[2024-07-16T14:27:50.379+0000] {logging_mixin.py:188} INFO - [2024-07-16T14:27:50.379+0000] {dagbag.py:538} INFO - Filling up the DagBag from /opt/airflow/dags/google_analytics_data_etl.py
[2024-07-16T14:27:50.427+0000] {logging_mixin.py:188} INFO - [2024-07-16T14:27:50.427+0000] {dagbag.py:348} ERROR - Failed to import: /opt/airflow/dags/google_analytics_data_etl.py
Traceback (most recent call last):
  File "/home/airflow/.local/lib/python3.8/site-packages/airflow/models/dagbag.py", line 344, in parse
    loader.exec_module(new_module)
  File "<frozen importlib._bootstrap_external>", line 839, in exec_module
  File "<frozen importlib._bootstrap_external>", line 976, in get_code
  File "<frozen importlib._bootstrap_external>", line 906, in source_to_code
  File "<frozen importlib._bootstrap>", line 219, in _call_with_frames_removed
  File "/opt/airflow/dags/google_analytics_data_etl.py", line 14
    task_1 =
            ^
SyntaxError: invalid syntax
[2024-07-16T14:27:50.428+0000] {processor.py:842} WARNING - No viable dags retrieved from /opt/airflow/dags/google_analytics_data_etl.py
[2024-07-16T14:27:50.444+0000] {processor.py:183} INFO - Processing /opt/airflow/dags/google_analytics_data_etl.py took 0.079 seconds
[2024-07-16T14:28:20.704+0000] {processor.py:161} INFO - Started process (PID=6288) to work on /opt/airflow/dags/google_analytics_data_etl.py
[2024-07-16T14:28:20.708+0000] {processor.py:830} INFO - Processing file /opt/airflow/dags/google_analytics_data_etl.py for tasks to queue
[2024-07-16T14:28:20.719+0000] {logging_mixin.py:188} INFO - [2024-07-16T14:28:20.718+0000] {dagbag.py:538} INFO - Filling up the DagBag from /opt/airflow/dags/google_analytics_data_etl.py
[2024-07-16T14:28:20.754+0000] {logging_mixin.py:188} INFO - [2024-07-16T14:28:20.753+0000] {dagbag.py:348} ERROR - Failed to import: /opt/airflow/dags/google_analytics_data_etl.py
Traceback (most recent call last):
  File "/home/airflow/.local/lib/python3.8/site-packages/airflow/models/dagbag.py", line 344, in parse
    loader.exec_module(new_module)
  File "<frozen importlib._bootstrap_external>", line 839, in exec_module
  File "<frozen importlib._bootstrap_external>", line 976, in get_code
  File "<frozen importlib._bootstrap_external>", line 906, in source_to_code
  File "<frozen importlib._bootstrap>", line 219, in _call_with_frames_removed
  File "/opt/airflow/dags/google_analytics_data_etl.py", line 14
    task_1 =
            ^
SyntaxError: invalid syntax
[2024-07-16T14:28:20.756+0000] {processor.py:842} WARNING - No viable dags retrieved from /opt/airflow/dags/google_analytics_data_etl.py
[2024-07-16T14:28:20.775+0000] {processor.py:183} INFO - Processing /opt/airflow/dags/google_analytics_data_etl.py took 0.088 seconds
[2024-07-16T14:28:39.677+0000] {processor.py:161} INFO - Started process (PID=6339) to work on /opt/airflow/dags/google_analytics_data_etl.py
[2024-07-16T14:28:39.682+0000] {processor.py:830} INFO - Processing file /opt/airflow/dags/google_analytics_data_etl.py for tasks to queue
[2024-07-16T14:28:39.693+0000] {logging_mixin.py:188} INFO - [2024-07-16T14:28:39.692+0000] {dagbag.py:538} INFO - Filling up the DagBag from /opt/airflow/dags/google_analytics_data_etl.py
[2024-07-16T14:28:39.861+0000] {processor.py:840} INFO - DAG(s) 'google_analytics_data_etl' retrieved from /opt/airflow/dags/google_analytics_data_etl.py
[2024-07-16T14:28:40.206+0000] {logging_mixin.py:188} INFO - [2024-07-16T14:28:40.205+0000] {override.py:1769} INFO - Created Permission View: can delete on DAG:google_analytics_data_etl
[2024-07-16T14:28:40.225+0000] {logging_mixin.py:188} INFO - [2024-07-16T14:28:40.225+0000] {override.py:1769} INFO - Created Permission View: can edit on DAG:google_analytics_data_etl
[2024-07-16T14:28:40.236+0000] {logging_mixin.py:188} INFO - [2024-07-16T14:28:40.235+0000] {override.py:1769} INFO - Created Permission View: can read on DAG:google_analytics_data_etl
[2024-07-16T14:28:40.244+0000] {logging_mixin.py:188} INFO - [2024-07-16T14:28:40.244+0000] {dag.py:3033} INFO - Sync 1 DAGs
[2024-07-16T14:28:40.280+0000] {logging_mixin.py:188} INFO - [2024-07-16T14:28:40.280+0000] {dag.py:3055} INFO - Creating ORM DAG for google_analytics_data_etl
[2024-07-16T14:28:40.282+0000] {logging_mixin.py:188} INFO - [2024-07-16T14:28:40.282+0000] {dag.py:3820} INFO - Setting next_dagrun for google_analytics_data_etl to None, run_after=None
[2024-07-16T14:28:40.324+0000] {processor.py:183} INFO - Processing /opt/airflow/dags/google_analytics_data_etl.py took 0.661 seconds
[2024-07-16T14:29:11.215+0000] {processor.py:161} INFO - Started process (PID=6395) to work on /opt/airflow/dags/google_analytics_data_etl.py
[2024-07-16T14:29:11.218+0000] {processor.py:830} INFO - Processing file /opt/airflow/dags/google_analytics_data_etl.py for tasks to queue
[2024-07-16T14:29:11.228+0000] {logging_mixin.py:188} INFO - [2024-07-16T14:29:11.227+0000] {dagbag.py:538} INFO - Filling up the DagBag from /opt/airflow/dags/google_analytics_data_etl.py
[2024-07-16T14:29:11.286+0000] {processor.py:840} INFO - DAG(s) 'google_analytics_data_etl' retrieved from /opt/airflow/dags/google_analytics_data_etl.py
[2024-07-16T14:29:11.308+0000] {logging_mixin.py:188} INFO - [2024-07-16T14:29:11.308+0000] {dag.py:3033} INFO - Sync 1 DAGs
[2024-07-16T14:29:11.324+0000] {logging_mixin.py:188} INFO - [2024-07-16T14:29:11.323+0000] {dag.py:3820} INFO - Setting next_dagrun for google_analytics_data_etl to None, run_after=None
[2024-07-16T14:29:11.347+0000] {processor.py:183} INFO - Processing /opt/airflow/dags/google_analytics_data_etl.py took 0.145 seconds
[2024-07-16T14:29:42.279+0000] {processor.py:161} INFO - Started process (PID=6450) to work on /opt/airflow/dags/google_analytics_data_etl.py
[2024-07-16T14:29:42.286+0000] {processor.py:830} INFO - Processing file /opt/airflow/dags/google_analytics_data_etl.py for tasks to queue
[2024-07-16T14:29:42.307+0000] {logging_mixin.py:188} INFO - [2024-07-16T14:29:42.306+0000] {dagbag.py:538} INFO - Filling up the DagBag from /opt/airflow/dags/google_analytics_data_etl.py
[2024-07-16T14:29:42.425+0000] {processor.py:840} INFO - DAG(s) 'google_analytics_data_etl' retrieved from /opt/airflow/dags/google_analytics_data_etl.py
[2024-07-16T14:29:42.515+0000] {logging_mixin.py:188} INFO - [2024-07-16T14:29:42.514+0000] {dag.py:3033} INFO - Sync 1 DAGs
[2024-07-16T14:29:42.570+0000] {logging_mixin.py:188} INFO - [2024-07-16T14:29:42.569+0000] {dag.py:3820} INFO - Setting next_dagrun for google_analytics_data_etl to None, run_after=None
[2024-07-16T14:29:42.626+0000] {processor.py:183} INFO - Processing /opt/airflow/dags/google_analytics_data_etl.py took 0.357 seconds
[2024-07-16T14:30:12.969+0000] {processor.py:161} INFO - Started process (PID=6507) to work on /opt/airflow/dags/google_analytics_data_etl.py
[2024-07-16T14:30:12.974+0000] {processor.py:830} INFO - Processing file /opt/airflow/dags/google_analytics_data_etl.py for tasks to queue
[2024-07-16T14:30:12.986+0000] {logging_mixin.py:188} INFO - [2024-07-16T14:30:12.985+0000] {dagbag.py:538} INFO - Filling up the DagBag from /opt/airflow/dags/google_analytics_data_etl.py
[2024-07-16T14:30:13.044+0000] {processor.py:840} INFO - DAG(s) 'google_analytics_data_etl' retrieved from /opt/airflow/dags/google_analytics_data_etl.py
[2024-07-16T14:30:13.105+0000] {logging_mixin.py:188} INFO - [2024-07-16T14:30:13.105+0000] {dag.py:3033} INFO - Sync 1 DAGs
[2024-07-16T14:30:13.145+0000] {logging_mixin.py:188} INFO - [2024-07-16T14:30:13.144+0000] {dag.py:3820} INFO - Setting next_dagrun for google_analytics_data_etl to None, run_after=None
[2024-07-16T14:30:13.185+0000] {processor.py:183} INFO - Processing /opt/airflow/dags/google_analytics_data_etl.py took 0.231 seconds
[2024-07-16T14:30:43.821+0000] {processor.py:161} INFO - Started process (PID=6563) to work on /opt/airflow/dags/google_analytics_data_etl.py
[2024-07-16T14:30:43.825+0000] {processor.py:830} INFO - Processing file /opt/airflow/dags/google_analytics_data_etl.py for tasks to queue
[2024-07-16T14:30:43.838+0000] {logging_mixin.py:188} INFO - [2024-07-16T14:30:43.837+0000] {dagbag.py:538} INFO - Filling up the DagBag from /opt/airflow/dags/google_analytics_data_etl.py
[2024-07-16T14:30:43.998+0000] {processor.py:840} INFO - DAG(s) 'google_analytics_data_etl' retrieved from /opt/airflow/dags/google_analytics_data_etl.py
[2024-07-16T14:30:44.065+0000] {logging_mixin.py:188} INFO - [2024-07-16T14:30:44.065+0000] {dag.py:3033} INFO - Sync 1 DAGs
[2024-07-16T14:30:44.096+0000] {logging_mixin.py:188} INFO - [2024-07-16T14:30:44.095+0000] {dag.py:3820} INFO - Setting next_dagrun for google_analytics_data_etl to None, run_after=None
[2024-07-16T14:30:44.166+0000] {processor.py:183} INFO - Processing /opt/airflow/dags/google_analytics_data_etl.py took 0.369 seconds
[2024-07-16T14:31:14.900+0000] {processor.py:161} INFO - Started process (PID=6619) to work on /opt/airflow/dags/google_analytics_data_etl.py
[2024-07-16T14:31:14.904+0000] {processor.py:830} INFO - Processing file /opt/airflow/dags/google_analytics_data_etl.py for tasks to queue
[2024-07-16T14:31:14.913+0000] {logging_mixin.py:188} INFO - [2024-07-16T14:31:14.912+0000] {dagbag.py:538} INFO - Filling up the DagBag from /opt/airflow/dags/google_analytics_data_etl.py
[2024-07-16T14:31:14.988+0000] {processor.py:840} INFO - DAG(s) 'google_analytics_data_etl' retrieved from /opt/airflow/dags/google_analytics_data_etl.py
[2024-07-16T14:31:15.056+0000] {logging_mixin.py:188} INFO - [2024-07-16T14:31:15.056+0000] {dag.py:3033} INFO - Sync 1 DAGs
[2024-07-16T14:31:15.073+0000] {logging_mixin.py:188} INFO - [2024-07-16T14:31:15.073+0000] {dag.py:3820} INFO - Setting next_dagrun for google_analytics_data_etl to None, run_after=None
[2024-07-16T14:31:15.092+0000] {processor.py:183} INFO - Processing /opt/airflow/dags/google_analytics_data_etl.py took 0.209 seconds
[2024-07-16T14:31:45.802+0000] {processor.py:161} INFO - Started process (PID=6675) to work on /opt/airflow/dags/google_analytics_data_etl.py
[2024-07-16T14:31:45.805+0000] {processor.py:830} INFO - Processing file /opt/airflow/dags/google_analytics_data_etl.py for tasks to queue
[2024-07-16T14:31:45.815+0000] {logging_mixin.py:188} INFO - [2024-07-16T14:31:45.814+0000] {dagbag.py:538} INFO - Filling up the DagBag from /opt/airflow/dags/google_analytics_data_etl.py
[2024-07-16T14:31:45.958+0000] {processor.py:840} INFO - DAG(s) 'google_analytics_data_etl' retrieved from /opt/airflow/dags/google_analytics_data_etl.py
[2024-07-16T14:31:45.976+0000] {logging_mixin.py:188} INFO - [2024-07-16T14:31:45.975+0000] {dag.py:3033} INFO - Sync 1 DAGs
[2024-07-16T14:31:45.999+0000] {logging_mixin.py:188} INFO - [2024-07-16T14:31:45.998+0000] {dag.py:3820} INFO - Setting next_dagrun for google_analytics_data_etl to None, run_after=None
[2024-07-16T14:31:46.039+0000] {processor.py:183} INFO - Processing /opt/airflow/dags/google_analytics_data_etl.py took 0.244 seconds
[2024-07-16T14:32:17.177+0000] {processor.py:161} INFO - Started process (PID=6730) to work on /opt/airflow/dags/google_analytics_data_etl.py
[2024-07-16T14:32:17.179+0000] {processor.py:830} INFO - Processing file /opt/airflow/dags/google_analytics_data_etl.py for tasks to queue
[2024-07-16T14:32:17.183+0000] {logging_mixin.py:188} INFO - [2024-07-16T14:32:17.182+0000] {dagbag.py:538} INFO - Filling up the DagBag from /opt/airflow/dags/google_analytics_data_etl.py
[2024-07-16T14:32:17.302+0000] {processor.py:840} INFO - DAG(s) 'google_analytics_data_etl' retrieved from /opt/airflow/dags/google_analytics_data_etl.py
[2024-07-16T14:32:17.320+0000] {logging_mixin.py:188} INFO - [2024-07-16T14:32:17.320+0000] {dag.py:3033} INFO - Sync 1 DAGs
[2024-07-16T14:32:17.340+0000] {logging_mixin.py:188} INFO - [2024-07-16T14:32:17.339+0000] {dag.py:3820} INFO - Setting next_dagrun for google_analytics_data_etl to None, run_after=None
[2024-07-16T14:32:17.370+0000] {processor.py:183} INFO - Processing /opt/airflow/dags/google_analytics_data_etl.py took 0.200 seconds
[2024-07-16T14:32:47.545+0000] {processor.py:161} INFO - Started process (PID=6786) to work on /opt/airflow/dags/google_analytics_data_etl.py
[2024-07-16T14:32:47.546+0000] {processor.py:830} INFO - Processing file /opt/airflow/dags/google_analytics_data_etl.py for tasks to queue
[2024-07-16T14:32:47.549+0000] {logging_mixin.py:188} INFO - [2024-07-16T14:32:47.549+0000] {dagbag.py:538} INFO - Filling up the DagBag from /opt/airflow/dags/google_analytics_data_etl.py
[2024-07-16T14:32:47.567+0000] {processor.py:840} INFO - DAG(s) 'google_analytics_data_etl' retrieved from /opt/airflow/dags/google_analytics_data_etl.py
[2024-07-16T14:32:47.586+0000] {logging_mixin.py:188} INFO - [2024-07-16T14:32:47.586+0000] {dag.py:3033} INFO - Sync 1 DAGs
[2024-07-16T14:32:47.603+0000] {logging_mixin.py:188} INFO - [2024-07-16T14:32:47.603+0000] {dag.py:3820} INFO - Setting next_dagrun for google_analytics_data_etl to None, run_after=None
[2024-07-16T14:32:47.639+0000] {processor.py:183} INFO - Processing /opt/airflow/dags/google_analytics_data_etl.py took 0.098 seconds
[2024-07-16T14:33:18.180+0000] {processor.py:161} INFO - Started process (PID=6841) to work on /opt/airflow/dags/google_analytics_data_etl.py
[2024-07-16T14:33:18.185+0000] {processor.py:830} INFO - Processing file /opt/airflow/dags/google_analytics_data_etl.py for tasks to queue
[2024-07-16T14:33:18.198+0000] {logging_mixin.py:188} INFO - [2024-07-16T14:33:18.198+0000] {dagbag.py:538} INFO - Filling up the DagBag from /opt/airflow/dags/google_analytics_data_etl.py
[2024-07-16T14:33:18.271+0000] {processor.py:840} INFO - DAG(s) 'google_analytics_data_etl' retrieved from /opt/airflow/dags/google_analytics_data_etl.py
[2024-07-16T14:33:18.334+0000] {logging_mixin.py:188} INFO - [2024-07-16T14:33:18.333+0000] {dag.py:3033} INFO - Sync 1 DAGs
[2024-07-16T14:33:18.402+0000] {logging_mixin.py:188} INFO - [2024-07-16T14:33:18.401+0000] {dag.py:3820} INFO - Setting next_dagrun for google_analytics_data_etl to None, run_after=None
[2024-07-16T14:33:18.517+0000] {processor.py:183} INFO - Processing /opt/airflow/dags/google_analytics_data_etl.py took 0.356 seconds
[2024-07-16T14:33:49.583+0000] {processor.py:161} INFO - Started process (PID=6897) to work on /opt/airflow/dags/google_analytics_data_etl.py
[2024-07-16T14:33:49.592+0000] {processor.py:830} INFO - Processing file /opt/airflow/dags/google_analytics_data_etl.py for tasks to queue
[2024-07-16T14:33:49.609+0000] {logging_mixin.py:188} INFO - [2024-07-16T14:33:49.607+0000] {dagbag.py:538} INFO - Filling up the DagBag from /opt/airflow/dags/google_analytics_data_etl.py
[2024-07-16T14:33:49.831+0000] {processor.py:840} INFO - DAG(s) 'google_analytics_data_etl' retrieved from /opt/airflow/dags/google_analytics_data_etl.py
[2024-07-16T14:33:49.856+0000] {logging_mixin.py:188} INFO - [2024-07-16T14:33:49.856+0000] {dag.py:3033} INFO - Sync 1 DAGs
[2024-07-16T14:33:49.868+0000] {logging_mixin.py:188} INFO - [2024-07-16T14:33:49.868+0000] {dag.py:3820} INFO - Setting next_dagrun for google_analytics_data_etl to None, run_after=None
[2024-07-16T14:33:49.890+0000] {processor.py:183} INFO - Processing /opt/airflow/dags/google_analytics_data_etl.py took 0.324 seconds
[2024-07-16T14:34:20.217+0000] {processor.py:161} INFO - Started process (PID=6953) to work on /opt/airflow/dags/google_analytics_data_etl.py
[2024-07-16T14:34:20.221+0000] {processor.py:830} INFO - Processing file /opt/airflow/dags/google_analytics_data_etl.py for tasks to queue
[2024-07-16T14:34:20.235+0000] {logging_mixin.py:188} INFO - [2024-07-16T14:34:20.234+0000] {dagbag.py:538} INFO - Filling up the DagBag from /opt/airflow/dags/google_analytics_data_etl.py
[2024-07-16T14:34:20.313+0000] {processor.py:840} INFO - DAG(s) 'google_analytics_data_etl' retrieved from /opt/airflow/dags/google_analytics_data_etl.py
[2024-07-16T14:34:20.341+0000] {logging_mixin.py:188} INFO - [2024-07-16T14:34:20.341+0000] {dag.py:3033} INFO - Sync 1 DAGs
[2024-07-16T14:34:20.357+0000] {logging_mixin.py:188} INFO - [2024-07-16T14:34:20.357+0000] {dag.py:3820} INFO - Setting next_dagrun for google_analytics_data_etl to None, run_after=None
[2024-07-16T14:34:20.378+0000] {processor.py:183} INFO - Processing /opt/airflow/dags/google_analytics_data_etl.py took 0.177 seconds
[2024-07-16T14:34:51.029+0000] {processor.py:161} INFO - Started process (PID=7009) to work on /opt/airflow/dags/google_analytics_data_etl.py
[2024-07-16T14:34:51.033+0000] {processor.py:830} INFO - Processing file /opt/airflow/dags/google_analytics_data_etl.py for tasks to queue
[2024-07-16T14:34:51.044+0000] {logging_mixin.py:188} INFO - [2024-07-16T14:34:51.043+0000] {dagbag.py:538} INFO - Filling up the DagBag from /opt/airflow/dags/google_analytics_data_etl.py
[2024-07-16T14:34:51.230+0000] {processor.py:840} INFO - DAG(s) 'google_analytics_data_etl' retrieved from /opt/airflow/dags/google_analytics_data_etl.py
[2024-07-16T14:34:51.307+0000] {logging_mixin.py:188} INFO - [2024-07-16T14:34:51.307+0000] {dag.py:3033} INFO - Sync 1 DAGs
[2024-07-16T14:34:51.335+0000] {logging_mixin.py:188} INFO - [2024-07-16T14:34:51.334+0000] {dag.py:3820} INFO - Setting next_dagrun for google_analytics_data_etl to None, run_after=None
[2024-07-16T14:34:51.395+0000] {processor.py:183} INFO - Processing /opt/airflow/dags/google_analytics_data_etl.py took 0.378 seconds
[2024-07-16T14:35:21.670+0000] {processor.py:161} INFO - Started process (PID=7065) to work on /opt/airflow/dags/google_analytics_data_etl.py
[2024-07-16T14:35:21.675+0000] {processor.py:830} INFO - Processing file /opt/airflow/dags/google_analytics_data_etl.py for tasks to queue
[2024-07-16T14:35:21.690+0000] {logging_mixin.py:188} INFO - [2024-07-16T14:35:21.690+0000] {dagbag.py:538} INFO - Filling up the DagBag from /opt/airflow/dags/google_analytics_data_etl.py
[2024-07-16T14:35:21.755+0000] {processor.py:840} INFO - DAG(s) 'google_analytics_data_etl' retrieved from /opt/airflow/dags/google_analytics_data_etl.py
[2024-07-16T14:35:21.794+0000] {logging_mixin.py:188} INFO - [2024-07-16T14:35:21.793+0000] {dag.py:3033} INFO - Sync 1 DAGs
[2024-07-16T14:35:21.814+0000] {logging_mixin.py:188} INFO - [2024-07-16T14:35:21.814+0000] {dag.py:3820} INFO - Setting next_dagrun for google_analytics_data_etl to None, run_after=None
[2024-07-16T14:35:21.871+0000] {processor.py:183} INFO - Processing /opt/airflow/dags/google_analytics_data_etl.py took 0.204 seconds
[2024-07-16T14:35:52.509+0000] {processor.py:161} INFO - Started process (PID=7121) to work on /opt/airflow/dags/google_analytics_data_etl.py
[2024-07-16T14:35:52.512+0000] {processor.py:830} INFO - Processing file /opt/airflow/dags/google_analytics_data_etl.py for tasks to queue
[2024-07-16T14:35:52.516+0000] {logging_mixin.py:188} INFO - [2024-07-16T14:35:52.515+0000] {dagbag.py:538} INFO - Filling up the DagBag from /opt/airflow/dags/google_analytics_data_etl.py
[2024-07-16T14:35:52.535+0000] {processor.py:840} INFO - DAG(s) 'google_analytics_data_etl' retrieved from /opt/airflow/dags/google_analytics_data_etl.py
[2024-07-16T14:35:52.553+0000] {logging_mixin.py:188} INFO - [2024-07-16T14:35:52.553+0000] {dag.py:3033} INFO - Sync 1 DAGs
[2024-07-16T14:35:52.564+0000] {logging_mixin.py:188} INFO - [2024-07-16T14:35:52.564+0000] {dag.py:3820} INFO - Setting next_dagrun for google_analytics_data_etl to None, run_after=None
[2024-07-16T14:35:52.581+0000] {processor.py:183} INFO - Processing /opt/airflow/dags/google_analytics_data_etl.py took 0.076 seconds
[2024-07-16T14:36:23.314+0000] {processor.py:161} INFO - Started process (PID=7177) to work on /opt/airflow/dags/google_analytics_data_etl.py
[2024-07-16T14:36:23.322+0000] {processor.py:830} INFO - Processing file /opt/airflow/dags/google_analytics_data_etl.py for tasks to queue
[2024-07-16T14:36:23.337+0000] {logging_mixin.py:188} INFO - [2024-07-16T14:36:23.336+0000] {dagbag.py:538} INFO - Filling up the DagBag from /opt/airflow/dags/google_analytics_data_etl.py
[2024-07-16T14:36:23.417+0000] {processor.py:840} INFO - DAG(s) 'google_analytics_data_etl' retrieved from /opt/airflow/dags/google_analytics_data_etl.py
[2024-07-16T14:36:23.458+0000] {logging_mixin.py:188} INFO - [2024-07-16T14:36:23.457+0000] {dag.py:3033} INFO - Sync 1 DAGs
[2024-07-16T14:36:23.469+0000] {logging_mixin.py:188} INFO - [2024-07-16T14:36:23.469+0000] {dag.py:3820} INFO - Setting next_dagrun for google_analytics_data_etl to None, run_after=None
[2024-07-16T14:36:23.489+0000] {processor.py:183} INFO - Processing /opt/airflow/dags/google_analytics_data_etl.py took 0.190 seconds
[2024-07-16T14:36:24.736+0000] {processor.py:161} INFO - Started process (PID=7180) to work on /opt/airflow/dags/google_analytics_data_etl.py
[2024-07-16T14:36:24.738+0000] {processor.py:830} INFO - Processing file /opt/airflow/dags/google_analytics_data_etl.py for tasks to queue
[2024-07-16T14:36:24.741+0000] {logging_mixin.py:188} INFO - [2024-07-16T14:36:24.741+0000] {dagbag.py:538} INFO - Filling up the DagBag from /opt/airflow/dags/google_analytics_data_etl.py
[2024-07-16T14:36:24.860+0000] {logging_mixin.py:188} INFO - [2024-07-16T14:36:24.829+0000] {dagbag.py:348} ERROR - Failed to import: /opt/airflow/dags/google_analytics_data_etl.py
Traceback (most recent call last):
  File "/home/airflow/.local/lib/python3.8/site-packages/airflow/models/dagbag.py", line 344, in parse
    loader.exec_module(new_module)
  File "<frozen importlib._bootstrap_external>", line 843, in exec_module
  File "<frozen importlib._bootstrap>", line 219, in _call_with_frames_removed
  File "/opt/airflow/dags/google_analytics_data_etl.py", line 14, in <module>
    task_1 = PythonOperator()
  File "/home/airflow/.local/lib/python3.8/site-packages/airflow/models/baseoperator.py", line 420, in apply_defaults
    raise AirflowException(f"missing keyword argument {missing_args.pop()!r}")
airflow.exceptions.AirflowException: missing keyword argument 'python_callable'
[2024-07-16T14:36:24.868+0000] {processor.py:842} WARNING - No viable dags retrieved from /opt/airflow/dags/google_analytics_data_etl.py
[2024-07-16T14:36:24.906+0000] {processor.py:183} INFO - Processing /opt/airflow/dags/google_analytics_data_etl.py took 0.176 seconds
[2024-07-16T14:36:55.350+0000] {processor.py:161} INFO - Started process (PID=7236) to work on /opt/airflow/dags/google_analytics_data_etl.py
[2024-07-16T14:36:55.361+0000] {processor.py:830} INFO - Processing file /opt/airflow/dags/google_analytics_data_etl.py for tasks to queue
[2024-07-16T14:36:55.372+0000] {logging_mixin.py:188} INFO - [2024-07-16T14:36:55.371+0000] {dagbag.py:538} INFO - Filling up the DagBag from /opt/airflow/dags/google_analytics_data_etl.py
[2024-07-16T14:36:55.481+0000] {logging_mixin.py:188} INFO - [2024-07-16T14:36:55.456+0000] {dagbag.py:348} ERROR - Failed to import: /opt/airflow/dags/google_analytics_data_etl.py
Traceback (most recent call last):
  File "/home/airflow/.local/lib/python3.8/site-packages/airflow/models/dagbag.py", line 344, in parse
    loader.exec_module(new_module)
  File "<frozen importlib._bootstrap_external>", line 843, in exec_module
  File "<frozen importlib._bootstrap>", line 219, in _call_with_frames_removed
  File "/opt/airflow/dags/google_analytics_data_etl.py", line 14, in <module>
    task_1 = PythonOperator()
  File "/home/airflow/.local/lib/python3.8/site-packages/airflow/models/baseoperator.py", line 420, in apply_defaults
    raise AirflowException(f"missing keyword argument {missing_args.pop()!r}")
airflow.exceptions.AirflowException: missing keyword argument 'python_callable'
[2024-07-16T14:36:55.490+0000] {processor.py:842} WARNING - No viable dags retrieved from /opt/airflow/dags/google_analytics_data_etl.py
[2024-07-16T14:36:55.556+0000] {processor.py:183} INFO - Processing /opt/airflow/dags/google_analytics_data_etl.py took 0.222 seconds
[2024-07-16T14:37:25.940+0000] {processor.py:161} INFO - Started process (PID=7292) to work on /opt/airflow/dags/google_analytics_data_etl.py
[2024-07-16T14:37:25.948+0000] {processor.py:830} INFO - Processing file /opt/airflow/dags/google_analytics_data_etl.py for tasks to queue
[2024-07-16T14:37:25.962+0000] {logging_mixin.py:188} INFO - [2024-07-16T14:37:25.960+0000] {dagbag.py:538} INFO - Filling up the DagBag from /opt/airflow/dags/google_analytics_data_etl.py
[2024-07-16T14:37:26.172+0000] {logging_mixin.py:188} INFO - [2024-07-16T14:37:26.133+0000] {dagbag.py:348} ERROR - Failed to import: /opt/airflow/dags/google_analytics_data_etl.py
Traceback (most recent call last):
  File "/home/airflow/.local/lib/python3.8/site-packages/airflow/models/dagbag.py", line 344, in parse
    loader.exec_module(new_module)
  File "<frozen importlib._bootstrap_external>", line 843, in exec_module
  File "<frozen importlib._bootstrap>", line 219, in _call_with_frames_removed
  File "/opt/airflow/dags/google_analytics_data_etl.py", line 14, in <module>
    task_1 = PythonOperator()
  File "/home/airflow/.local/lib/python3.8/site-packages/airflow/models/baseoperator.py", line 420, in apply_defaults
    raise AirflowException(f"missing keyword argument {missing_args.pop()!r}")
airflow.exceptions.AirflowException: missing keyword argument 'python_callable'
[2024-07-16T14:37:26.188+0000] {processor.py:842} WARNING - No viable dags retrieved from /opt/airflow/dags/google_analytics_data_etl.py
[2024-07-16T14:37:26.248+0000] {processor.py:183} INFO - Processing /opt/airflow/dags/google_analytics_data_etl.py took 0.325 seconds
[2024-07-16T14:37:56.934+0000] {processor.py:161} INFO - Started process (PID=7348) to work on /opt/airflow/dags/google_analytics_data_etl.py
[2024-07-16T14:37:56.936+0000] {processor.py:830} INFO - Processing file /opt/airflow/dags/google_analytics_data_etl.py for tasks to queue
[2024-07-16T14:37:56.940+0000] {logging_mixin.py:188} INFO - [2024-07-16T14:37:56.939+0000] {dagbag.py:538} INFO - Filling up the DagBag from /opt/airflow/dags/google_analytics_data_etl.py
[2024-07-16T14:37:56.984+0000] {logging_mixin.py:188} INFO - [2024-07-16T14:37:56.973+0000] {dagbag.py:348} ERROR - Failed to import: /opt/airflow/dags/google_analytics_data_etl.py
Traceback (most recent call last):
  File "/home/airflow/.local/lib/python3.8/site-packages/airflow/models/dagbag.py", line 344, in parse
    loader.exec_module(new_module)
  File "<frozen importlib._bootstrap_external>", line 843, in exec_module
  File "<frozen importlib._bootstrap>", line 219, in _call_with_frames_removed
  File "/opt/airflow/dags/google_analytics_data_etl.py", line 14, in <module>
    task_1 = PythonOperator()
  File "/home/airflow/.local/lib/python3.8/site-packages/airflow/models/baseoperator.py", line 420, in apply_defaults
    raise AirflowException(f"missing keyword argument {missing_args.pop()!r}")
airflow.exceptions.AirflowException: missing keyword argument 'python_callable'
[2024-07-16T14:37:56.988+0000] {processor.py:842} WARNING - No viable dags retrieved from /opt/airflow/dags/google_analytics_data_etl.py
[2024-07-16T14:37:57.045+0000] {processor.py:183} INFO - Processing /opt/airflow/dags/google_analytics_data_etl.py took 0.119 seconds
[2024-07-16T14:38:27.552+0000] {processor.py:161} INFO - Started process (PID=7403) to work on /opt/airflow/dags/google_analytics_data_etl.py
[2024-07-16T14:38:27.554+0000] {processor.py:830} INFO - Processing file /opt/airflow/dags/google_analytics_data_etl.py for tasks to queue
[2024-07-16T14:38:27.557+0000] {logging_mixin.py:188} INFO - [2024-07-16T14:38:27.556+0000] {dagbag.py:538} INFO - Filling up the DagBag from /opt/airflow/dags/google_analytics_data_etl.py
[2024-07-16T14:38:27.604+0000] {logging_mixin.py:188} INFO - [2024-07-16T14:38:27.589+0000] {dagbag.py:348} ERROR - Failed to import: /opt/airflow/dags/google_analytics_data_etl.py
Traceback (most recent call last):
  File "/home/airflow/.local/lib/python3.8/site-packages/airflow/models/dagbag.py", line 344, in parse
    loader.exec_module(new_module)
  File "<frozen importlib._bootstrap_external>", line 843, in exec_module
  File "<frozen importlib._bootstrap>", line 219, in _call_with_frames_removed
  File "/opt/airflow/dags/google_analytics_data_etl.py", line 14, in <module>
    task_1 = PythonOperator()
  File "/home/airflow/.local/lib/python3.8/site-packages/airflow/models/baseoperator.py", line 420, in apply_defaults
    raise AirflowException(f"missing keyword argument {missing_args.pop()!r}")
airflow.exceptions.AirflowException: missing keyword argument 'python_callable'
[2024-07-16T14:38:27.607+0000] {processor.py:842} WARNING - No viable dags retrieved from /opt/airflow/dags/google_analytics_data_etl.py
[2024-07-16T14:38:27.639+0000] {processor.py:183} INFO - Processing /opt/airflow/dags/google_analytics_data_etl.py took 0.096 seconds
[2024-07-16T14:38:58.134+0000] {processor.py:161} INFO - Started process (PID=7459) to work on /opt/airflow/dags/google_analytics_data_etl.py
[2024-07-16T14:38:58.136+0000] {processor.py:830} INFO - Processing file /opt/airflow/dags/google_analytics_data_etl.py for tasks to queue
[2024-07-16T14:38:58.138+0000] {logging_mixin.py:188} INFO - [2024-07-16T14:38:58.138+0000] {dagbag.py:538} INFO - Filling up the DagBag from /opt/airflow/dags/google_analytics_data_etl.py
[2024-07-16T14:38:58.186+0000] {logging_mixin.py:188} INFO - [2024-07-16T14:38:58.181+0000] {dagbag.py:348} ERROR - Failed to import: /opt/airflow/dags/google_analytics_data_etl.py
Traceback (most recent call last):
  File "/home/airflow/.local/lib/python3.8/site-packages/airflow/models/dagbag.py", line 344, in parse
    loader.exec_module(new_module)
  File "<frozen importlib._bootstrap_external>", line 843, in exec_module
  File "<frozen importlib._bootstrap>", line 219, in _call_with_frames_removed
  File "/opt/airflow/dags/google_analytics_data_etl.py", line 14, in <module>
    task_1 = PythonOperator()
  File "/home/airflow/.local/lib/python3.8/site-packages/airflow/models/baseoperator.py", line 420, in apply_defaults
    raise AirflowException(f"missing keyword argument {missing_args.pop()!r}")
airflow.exceptions.AirflowException: missing keyword argument 'python_callable'
[2024-07-16T14:38:58.187+0000] {processor.py:842} WARNING - No viable dags retrieved from /opt/airflow/dags/google_analytics_data_etl.py
[2024-07-16T14:38:58.214+0000] {processor.py:183} INFO - Processing /opt/airflow/dags/google_analytics_data_etl.py took 0.083 seconds
[2024-07-16T14:39:29.150+0000] {processor.py:161} INFO - Started process (PID=7521) to work on /opt/airflow/dags/google_analytics_data_etl.py
[2024-07-16T14:39:29.157+0000] {processor.py:830} INFO - Processing file /opt/airflow/dags/google_analytics_data_etl.py for tasks to queue
[2024-07-16T14:39:29.171+0000] {logging_mixin.py:188} INFO - [2024-07-16T14:39:29.170+0000] {dagbag.py:538} INFO - Filling up the DagBag from /opt/airflow/dags/google_analytics_data_etl.py
[2024-07-16T14:39:29.407+0000] {logging_mixin.py:188} INFO - [2024-07-16T14:39:29.369+0000] {dagbag.py:348} ERROR - Failed to import: /opt/airflow/dags/google_analytics_data_etl.py
Traceback (most recent call last):
  File "/home/airflow/.local/lib/python3.8/site-packages/airflow/models/dagbag.py", line 344, in parse
    loader.exec_module(new_module)
  File "<frozen importlib._bootstrap_external>", line 843, in exec_module
  File "<frozen importlib._bootstrap>", line 219, in _call_with_frames_removed
  File "/opt/airflow/dags/google_analytics_data_etl.py", line 14, in <module>
    task_1 = PythonOperator()
  File "/home/airflow/.local/lib/python3.8/site-packages/airflow/models/baseoperator.py", line 420, in apply_defaults
    raise AirflowException(f"missing keyword argument {missing_args.pop()!r}")
airflow.exceptions.AirflowException: missing keyword argument 'python_callable'
[2024-07-16T14:39:29.410+0000] {processor.py:842} WARNING - No viable dags retrieved from /opt/airflow/dags/google_analytics_data_etl.py
[2024-07-16T14:39:29.425+0000] {processor.py:183} INFO - Processing /opt/airflow/dags/google_analytics_data_etl.py took 0.292 seconds
[2024-07-16T14:39:59.646+0000] {processor.py:161} INFO - Started process (PID=7577) to work on /opt/airflow/dags/google_analytics_data_etl.py
[2024-07-16T14:39:59.648+0000] {processor.py:830} INFO - Processing file /opt/airflow/dags/google_analytics_data_etl.py for tasks to queue
[2024-07-16T14:39:59.652+0000] {logging_mixin.py:188} INFO - [2024-07-16T14:39:59.651+0000] {dagbag.py:538} INFO - Filling up the DagBag from /opt/airflow/dags/google_analytics_data_etl.py
[2024-07-16T14:39:59.735+0000] {logging_mixin.py:188} INFO - [2024-07-16T14:39:59.702+0000] {dagbag.py:348} ERROR - Failed to import: /opt/airflow/dags/google_analytics_data_etl.py
Traceback (most recent call last):
  File "/home/airflow/.local/lib/python3.8/site-packages/airflow/models/dagbag.py", line 344, in parse
    loader.exec_module(new_module)
  File "<frozen importlib._bootstrap_external>", line 843, in exec_module
  File "<frozen importlib._bootstrap>", line 219, in _call_with_frames_removed
  File "/opt/airflow/dags/google_analytics_data_etl.py", line 14, in <module>
    task_1 = PythonOperator()
  File "/home/airflow/.local/lib/python3.8/site-packages/airflow/models/baseoperator.py", line 420, in apply_defaults
    raise AirflowException(f"missing keyword argument {missing_args.pop()!r}")
airflow.exceptions.AirflowException: missing keyword argument 'python_callable'
[2024-07-16T14:39:59.740+0000] {processor.py:842} WARNING - No viable dags retrieved from /opt/airflow/dags/google_analytics_data_etl.py
[2024-07-16T14:39:59.830+0000] {processor.py:183} INFO - Processing /opt/airflow/dags/google_analytics_data_etl.py took 0.190 seconds
[2024-07-16T14:40:30.027+0000] {processor.py:161} INFO - Started process (PID=7633) to work on /opt/airflow/dags/google_analytics_data_etl.py
[2024-07-16T14:40:30.031+0000] {processor.py:830} INFO - Processing file /opt/airflow/dags/google_analytics_data_etl.py for tasks to queue
[2024-07-16T14:40:30.034+0000] {logging_mixin.py:188} INFO - [2024-07-16T14:40:30.033+0000] {dagbag.py:538} INFO - Filling up the DagBag from /opt/airflow/dags/google_analytics_data_etl.py
[2024-07-16T14:40:30.088+0000] {logging_mixin.py:188} INFO - [2024-07-16T14:40:30.083+0000] {dagbag.py:348} ERROR - Failed to import: /opt/airflow/dags/google_analytics_data_etl.py
Traceback (most recent call last):
  File "/home/airflow/.local/lib/python3.8/site-packages/airflow/models/dagbag.py", line 344, in parse
    loader.exec_module(new_module)
  File "<frozen importlib._bootstrap_external>", line 843, in exec_module
  File "<frozen importlib._bootstrap>", line 219, in _call_with_frames_removed
  File "/opt/airflow/dags/google_analytics_data_etl.py", line 14, in <module>
    task_1 = PythonOperator()
  File "/home/airflow/.local/lib/python3.8/site-packages/airflow/models/baseoperator.py", line 420, in apply_defaults
    raise AirflowException(f"missing keyword argument {missing_args.pop()!r}")
airflow.exceptions.AirflowException: missing keyword argument 'python_callable'
[2024-07-16T14:40:30.090+0000] {processor.py:842} WARNING - No viable dags retrieved from /opt/airflow/dags/google_analytics_data_etl.py
[2024-07-16T14:40:30.104+0000] {processor.py:183} INFO - Processing /opt/airflow/dags/google_analytics_data_etl.py took 0.087 seconds
[2024-07-16T14:41:00.565+0000] {processor.py:161} INFO - Started process (PID=7689) to work on /opt/airflow/dags/google_analytics_data_etl.py
[2024-07-16T14:41:00.566+0000] {processor.py:830} INFO - Processing file /opt/airflow/dags/google_analytics_data_etl.py for tasks to queue
[2024-07-16T14:41:00.567+0000] {logging_mixin.py:188} INFO - [2024-07-16T14:41:00.567+0000] {dagbag.py:538} INFO - Filling up the DagBag from /opt/airflow/dags/google_analytics_data_etl.py
[2024-07-16T14:41:00.587+0000] {logging_mixin.py:188} INFO - [2024-07-16T14:41:00.581+0000] {dagbag.py:348} ERROR - Failed to import: /opt/airflow/dags/google_analytics_data_etl.py
Traceback (most recent call last):
  File "/home/airflow/.local/lib/python3.8/site-packages/airflow/models/dagbag.py", line 344, in parse
    loader.exec_module(new_module)
  File "<frozen importlib._bootstrap_external>", line 843, in exec_module
  File "<frozen importlib._bootstrap>", line 219, in _call_with_frames_removed
  File "/opt/airflow/dags/google_analytics_data_etl.py", line 14, in <module>
    task_1 = PythonOperator()
  File "/home/airflow/.local/lib/python3.8/site-packages/airflow/models/baseoperator.py", line 420, in apply_defaults
    raise AirflowException(f"missing keyword argument {missing_args.pop()!r}")
airflow.exceptions.AirflowException: missing keyword argument 'python_callable'
[2024-07-16T14:41:00.590+0000] {processor.py:842} WARNING - No viable dags retrieved from /opt/airflow/dags/google_analytics_data_etl.py
[2024-07-16T14:41:00.637+0000] {processor.py:183} INFO - Processing /opt/airflow/dags/google_analytics_data_etl.py took 0.075 seconds
[2024-07-16T14:41:30.896+0000] {processor.py:161} INFO - Started process (PID=7745) to work on /opt/airflow/dags/google_analytics_data_etl.py
[2024-07-16T14:41:30.897+0000] {processor.py:830} INFO - Processing file /opt/airflow/dags/google_analytics_data_etl.py for tasks to queue
[2024-07-16T14:41:30.899+0000] {logging_mixin.py:188} INFO - [2024-07-16T14:41:30.898+0000] {dagbag.py:538} INFO - Filling up the DagBag from /opt/airflow/dags/google_analytics_data_etl.py
[2024-07-16T14:41:30.924+0000] {logging_mixin.py:188} INFO - [2024-07-16T14:41:30.919+0000] {dagbag.py:348} ERROR - Failed to import: /opt/airflow/dags/google_analytics_data_etl.py
Traceback (most recent call last):
  File "/home/airflow/.local/lib/python3.8/site-packages/airflow/models/dagbag.py", line 344, in parse
    loader.exec_module(new_module)
  File "<frozen importlib._bootstrap_external>", line 843, in exec_module
  File "<frozen importlib._bootstrap>", line 219, in _call_with_frames_removed
  File "/opt/airflow/dags/google_analytics_data_etl.py", line 14, in <module>
    task_1 = PythonOperator()
  File "/home/airflow/.local/lib/python3.8/site-packages/airflow/models/baseoperator.py", line 420, in apply_defaults
    raise AirflowException(f"missing keyword argument {missing_args.pop()!r}")
airflow.exceptions.AirflowException: missing keyword argument 'python_callable'
[2024-07-16T14:41:30.927+0000] {processor.py:842} WARNING - No viable dags retrieved from /opt/airflow/dags/google_analytics_data_etl.py
[2024-07-16T14:41:30.942+0000] {processor.py:183} INFO - Processing /opt/airflow/dags/google_analytics_data_etl.py took 0.050 seconds
[2024-07-16T14:42:01.274+0000] {processor.py:161} INFO - Started process (PID=7801) to work on /opt/airflow/dags/google_analytics_data_etl.py
[2024-07-16T14:42:01.275+0000] {processor.py:830} INFO - Processing file /opt/airflow/dags/google_analytics_data_etl.py for tasks to queue
[2024-07-16T14:42:01.276+0000] {logging_mixin.py:188} INFO - [2024-07-16T14:42:01.276+0000] {dagbag.py:538} INFO - Filling up the DagBag from /opt/airflow/dags/google_analytics_data_etl.py
[2024-07-16T14:42:01.312+0000] {logging_mixin.py:188} INFO - [2024-07-16T14:42:01.301+0000] {dagbag.py:348} ERROR - Failed to import: /opt/airflow/dags/google_analytics_data_etl.py
Traceback (most recent call last):
  File "/home/airflow/.local/lib/python3.8/site-packages/airflow/models/dagbag.py", line 344, in parse
    loader.exec_module(new_module)
  File "<frozen importlib._bootstrap_external>", line 843, in exec_module
  File "<frozen importlib._bootstrap>", line 219, in _call_with_frames_removed
  File "/opt/airflow/dags/google_analytics_data_etl.py", line 14, in <module>
    task_1 = PythonOperator()
  File "/home/airflow/.local/lib/python3.8/site-packages/airflow/models/baseoperator.py", line 420, in apply_defaults
    raise AirflowException(f"missing keyword argument {missing_args.pop()!r}")
airflow.exceptions.AirflowException: missing keyword argument 'python_callable'
[2024-07-16T14:42:01.314+0000] {processor.py:842} WARNING - No viable dags retrieved from /opt/airflow/dags/google_analytics_data_etl.py
[2024-07-16T14:42:01.331+0000] {processor.py:183} INFO - Processing /opt/airflow/dags/google_analytics_data_etl.py took 0.063 seconds
[2024-07-16T14:42:31.755+0000] {processor.py:161} INFO - Started process (PID=7857) to work on /opt/airflow/dags/google_analytics_data_etl.py
[2024-07-16T14:42:31.760+0000] {processor.py:830} INFO - Processing file /opt/airflow/dags/google_analytics_data_etl.py for tasks to queue
[2024-07-16T14:42:31.764+0000] {logging_mixin.py:188} INFO - [2024-07-16T14:42:31.762+0000] {dagbag.py:538} INFO - Filling up the DagBag from /opt/airflow/dags/google_analytics_data_etl.py
[2024-07-16T14:42:31.863+0000] {logging_mixin.py:188} INFO - [2024-07-16T14:42:31.836+0000] {dagbag.py:348} ERROR - Failed to import: /opt/airflow/dags/google_analytics_data_etl.py
Traceback (most recent call last):
  File "/home/airflow/.local/lib/python3.8/site-packages/airflow/models/dagbag.py", line 344, in parse
    loader.exec_module(new_module)
  File "<frozen importlib._bootstrap_external>", line 843, in exec_module
  File "<frozen importlib._bootstrap>", line 219, in _call_with_frames_removed
  File "/opt/airflow/dags/google_analytics_data_etl.py", line 14, in <module>
    task_1 = PythonOperator()
  File "/home/airflow/.local/lib/python3.8/site-packages/airflow/models/baseoperator.py", line 420, in apply_defaults
    raise AirflowException(f"missing keyword argument {missing_args.pop()!r}")
airflow.exceptions.AirflowException: missing keyword argument 'python_callable'
[2024-07-16T14:42:31.869+0000] {processor.py:842} WARNING - No viable dags retrieved from /opt/airflow/dags/google_analytics_data_etl.py
[2024-07-16T14:42:31.886+0000] {processor.py:183} INFO - Processing /opt/airflow/dags/google_analytics_data_etl.py took 0.140 seconds
[2024-07-16T14:43:02.145+0000] {processor.py:161} INFO - Started process (PID=7913) to work on /opt/airflow/dags/google_analytics_data_etl.py
[2024-07-16T14:43:02.155+0000] {processor.py:830} INFO - Processing file /opt/airflow/dags/google_analytics_data_etl.py for tasks to queue
[2024-07-16T14:43:02.161+0000] {logging_mixin.py:188} INFO - [2024-07-16T14:43:02.159+0000] {dagbag.py:538} INFO - Filling up the DagBag from /opt/airflow/dags/google_analytics_data_etl.py
[2024-07-16T14:43:02.299+0000] {logging_mixin.py:188} INFO - [2024-07-16T14:43:02.276+0000] {dagbag.py:348} ERROR - Failed to import: /opt/airflow/dags/google_analytics_data_etl.py
Traceback (most recent call last):
  File "/home/airflow/.local/lib/python3.8/site-packages/airflow/models/dagbag.py", line 344, in parse
    loader.exec_module(new_module)
  File "<frozen importlib._bootstrap_external>", line 843, in exec_module
  File "<frozen importlib._bootstrap>", line 219, in _call_with_frames_removed
  File "/opt/airflow/dags/google_analytics_data_etl.py", line 14, in <module>
    task_1 = PythonOperator()
  File "/home/airflow/.local/lib/python3.8/site-packages/airflow/models/baseoperator.py", line 420, in apply_defaults
    raise AirflowException(f"missing keyword argument {missing_args.pop()!r}")
airflow.exceptions.AirflowException: missing keyword argument 'python_callable'
[2024-07-16T14:43:02.307+0000] {processor.py:842} WARNING - No viable dags retrieved from /opt/airflow/dags/google_analytics_data_etl.py
[2024-07-16T14:43:02.377+0000] {processor.py:183} INFO - Processing /opt/airflow/dags/google_analytics_data_etl.py took 0.250 seconds
[2024-07-16T14:43:32.509+0000] {processor.py:161} INFO - Started process (PID=7969) to work on /opt/airflow/dags/google_analytics_data_etl.py
[2024-07-16T14:43:32.511+0000] {processor.py:830} INFO - Processing file /opt/airflow/dags/google_analytics_data_etl.py for tasks to queue
[2024-07-16T14:43:32.512+0000] {logging_mixin.py:188} INFO - [2024-07-16T14:43:32.512+0000] {dagbag.py:538} INFO - Filling up the DagBag from /opt/airflow/dags/google_analytics_data_etl.py
[2024-07-16T14:43:32.594+0000] {logging_mixin.py:188} INFO - [2024-07-16T14:43:32.571+0000] {dagbag.py:348} ERROR - Failed to import: /opt/airflow/dags/google_analytics_data_etl.py
Traceback (most recent call last):
  File "/home/airflow/.local/lib/python3.8/site-packages/airflow/models/dagbag.py", line 344, in parse
    loader.exec_module(new_module)
  File "<frozen importlib._bootstrap_external>", line 843, in exec_module
  File "<frozen importlib._bootstrap>", line 219, in _call_with_frames_removed
  File "/opt/airflow/dags/google_analytics_data_etl.py", line 14, in <module>
    task_1 = PythonOperator()
  File "/home/airflow/.local/lib/python3.8/site-packages/airflow/models/baseoperator.py", line 420, in apply_defaults
    raise AirflowException(f"missing keyword argument {missing_args.pop()!r}")
airflow.exceptions.AirflowException: missing keyword argument 'python_callable'
[2024-07-16T14:43:32.620+0000] {processor.py:842} WARNING - No viable dags retrieved from /opt/airflow/dags/google_analytics_data_etl.py
[2024-07-16T14:43:32.689+0000] {processor.py:183} INFO - Processing /opt/airflow/dags/google_analytics_data_etl.py took 0.183 seconds
[2024-07-16T14:44:03.317+0000] {processor.py:161} INFO - Started process (PID=8025) to work on /opt/airflow/dags/google_analytics_data_etl.py
[2024-07-16T14:44:03.322+0000] {processor.py:830} INFO - Processing file /opt/airflow/dags/google_analytics_data_etl.py for tasks to queue
[2024-07-16T14:44:03.327+0000] {logging_mixin.py:188} INFO - [2024-07-16T14:44:03.325+0000] {dagbag.py:538} INFO - Filling up the DagBag from /opt/airflow/dags/google_analytics_data_etl.py
[2024-07-16T14:44:03.385+0000] {logging_mixin.py:188} INFO - [2024-07-16T14:44:03.381+0000] {dagbag.py:348} ERROR - Failed to import: /opt/airflow/dags/google_analytics_data_etl.py
Traceback (most recent call last):
  File "/home/airflow/.local/lib/python3.8/site-packages/airflow/models/dagbag.py", line 344, in parse
    loader.exec_module(new_module)
  File "<frozen importlib._bootstrap_external>", line 843, in exec_module
  File "<frozen importlib._bootstrap>", line 219, in _call_with_frames_removed
  File "/opt/airflow/dags/google_analytics_data_etl.py", line 14, in <module>
    task_1 = PythonOperator()
  File "/home/airflow/.local/lib/python3.8/site-packages/airflow/models/baseoperator.py", line 420, in apply_defaults
    raise AirflowException(f"missing keyword argument {missing_args.pop()!r}")
airflow.exceptions.AirflowException: missing keyword argument 'python_callable'
[2024-07-16T14:44:03.387+0000] {processor.py:842} WARNING - No viable dags retrieved from /opt/airflow/dags/google_analytics_data_etl.py
[2024-07-16T14:44:03.409+0000] {processor.py:183} INFO - Processing /opt/airflow/dags/google_analytics_data_etl.py took 0.104 seconds
[2024-07-16T14:44:33.548+0000] {processor.py:161} INFO - Started process (PID=8081) to work on /opt/airflow/dags/google_analytics_data_etl.py
[2024-07-16T14:44:33.550+0000] {processor.py:830} INFO - Processing file /opt/airflow/dags/google_analytics_data_etl.py for tasks to queue
[2024-07-16T14:44:33.553+0000] {logging_mixin.py:188} INFO - [2024-07-16T14:44:33.553+0000] {dagbag.py:538} INFO - Filling up the DagBag from /opt/airflow/dags/google_analytics_data_etl.py
[2024-07-16T14:44:33.592+0000] {logging_mixin.py:188} INFO - [2024-07-16T14:44:33.585+0000] {dagbag.py:348} ERROR - Failed to import: /opt/airflow/dags/google_analytics_data_etl.py
Traceback (most recent call last):
  File "/home/airflow/.local/lib/python3.8/site-packages/airflow/models/dagbag.py", line 344, in parse
    loader.exec_module(new_module)
  File "<frozen importlib._bootstrap_external>", line 843, in exec_module
  File "<frozen importlib._bootstrap>", line 219, in _call_with_frames_removed
  File "/opt/airflow/dags/google_analytics_data_etl.py", line 14, in <module>
    task_1 = PythonOperator()
  File "/home/airflow/.local/lib/python3.8/site-packages/airflow/models/baseoperator.py", line 420, in apply_defaults
    raise AirflowException(f"missing keyword argument {missing_args.pop()!r}")
airflow.exceptions.AirflowException: missing keyword argument 'python_callable'
[2024-07-16T14:44:33.594+0000] {processor.py:842} WARNING - No viable dags retrieved from /opt/airflow/dags/google_analytics_data_etl.py
[2024-07-16T14:44:33.611+0000] {processor.py:183} INFO - Processing /opt/airflow/dags/google_analytics_data_etl.py took 0.074 seconds
[2024-07-16T14:45:03.992+0000] {processor.py:161} INFO - Started process (PID=8136) to work on /opt/airflow/dags/google_analytics_data_etl.py
[2024-07-16T14:45:03.993+0000] {processor.py:830} INFO - Processing file /opt/airflow/dags/google_analytics_data_etl.py for tasks to queue
[2024-07-16T14:45:03.994+0000] {logging_mixin.py:188} INFO - [2024-07-16T14:45:03.994+0000] {dagbag.py:538} INFO - Filling up the DagBag from /opt/airflow/dags/google_analytics_data_etl.py
[2024-07-16T14:45:04.016+0000] {logging_mixin.py:188} INFO - [2024-07-16T14:45:04.011+0000] {dagbag.py:348} ERROR - Failed to import: /opt/airflow/dags/google_analytics_data_etl.py
Traceback (most recent call last):
  File "/home/airflow/.local/lib/python3.8/site-packages/airflow/models/dagbag.py", line 344, in parse
    loader.exec_module(new_module)
  File "<frozen importlib._bootstrap_external>", line 843, in exec_module
  File "<frozen importlib._bootstrap>", line 219, in _call_with_frames_removed
  File "/opt/airflow/dags/google_analytics_data_etl.py", line 14, in <module>
    task_1 = PythonOperator()
  File "/home/airflow/.local/lib/python3.8/site-packages/airflow/models/baseoperator.py", line 420, in apply_defaults
    raise AirflowException(f"missing keyword argument {missing_args.pop()!r}")
airflow.exceptions.AirflowException: missing keyword argument 'python_callable'
[2024-07-16T14:45:04.018+0000] {processor.py:842} WARNING - No viable dags retrieved from /opt/airflow/dags/google_analytics_data_etl.py
[2024-07-16T14:45:04.033+0000] {processor.py:183} INFO - Processing /opt/airflow/dags/google_analytics_data_etl.py took 0.043 seconds
[2024-07-16T14:45:34.088+0000] {processor.py:161} INFO - Started process (PID=8191) to work on /opt/airflow/dags/google_analytics_data_etl.py
[2024-07-16T14:45:34.089+0000] {processor.py:830} INFO - Processing file /opt/airflow/dags/google_analytics_data_etl.py for tasks to queue
[2024-07-16T14:45:34.090+0000] {logging_mixin.py:188} INFO - [2024-07-16T14:45:34.089+0000] {dagbag.py:538} INFO - Filling up the DagBag from /opt/airflow/dags/google_analytics_data_etl.py
[2024-07-16T14:45:34.113+0000] {logging_mixin.py:188} INFO - [2024-07-16T14:45:34.098+0000] {dagbag.py:348} ERROR - Failed to import: /opt/airflow/dags/google_analytics_data_etl.py
Traceback (most recent call last):
  File "/home/airflow/.local/lib/python3.8/site-packages/airflow/models/dagbag.py", line 344, in parse
    loader.exec_module(new_module)
  File "<frozen importlib._bootstrap_external>", line 843, in exec_module
  File "<frozen importlib._bootstrap>", line 219, in _call_with_frames_removed
  File "/opt/airflow/dags/google_analytics_data_etl.py", line 14, in <module>
    task_1 = PythonOperator()
  File "/home/airflow/.local/lib/python3.8/site-packages/airflow/models/baseoperator.py", line 420, in apply_defaults
    raise AirflowException(f"missing keyword argument {missing_args.pop()!r}")
airflow.exceptions.AirflowException: missing keyword argument 'python_callable'
[2024-07-16T14:45:34.115+0000] {processor.py:842} WARNING - No viable dags retrieved from /opt/airflow/dags/google_analytics_data_etl.py
[2024-07-16T14:45:34.131+0000] {processor.py:183} INFO - Processing /opt/airflow/dags/google_analytics_data_etl.py took 0.045 seconds
[2024-07-16T14:46:04.944+0000] {processor.py:161} INFO - Started process (PID=8246) to work on /opt/airflow/dags/google_analytics_data_etl.py
[2024-07-16T14:46:04.946+0000] {processor.py:830} INFO - Processing file /opt/airflow/dags/google_analytics_data_etl.py for tasks to queue
[2024-07-16T14:46:04.947+0000] {logging_mixin.py:188} INFO - [2024-07-16T14:46:04.946+0000] {dagbag.py:538} INFO - Filling up the DagBag from /opt/airflow/dags/google_analytics_data_etl.py
[2024-07-16T14:46:05.062+0000] {logging_mixin.py:188} INFO - [2024-07-16T14:46:05.033+0000] {dagbag.py:348} ERROR - Failed to import: /opt/airflow/dags/google_analytics_data_etl.py
Traceback (most recent call last):
  File "/home/airflow/.local/lib/python3.8/site-packages/airflow/models/dagbag.py", line 344, in parse
    loader.exec_module(new_module)
  File "<frozen importlib._bootstrap_external>", line 843, in exec_module
  File "<frozen importlib._bootstrap>", line 219, in _call_with_frames_removed
  File "/opt/airflow/dags/google_analytics_data_etl.py", line 14, in <module>
    task_1 = PythonOperator()
  File "/home/airflow/.local/lib/python3.8/site-packages/airflow/models/baseoperator.py", line 420, in apply_defaults
    raise AirflowException(f"missing keyword argument {missing_args.pop()!r}")
airflow.exceptions.AirflowException: missing keyword argument 'python_callable'
[2024-07-16T14:46:05.065+0000] {processor.py:842} WARNING - No viable dags retrieved from /opt/airflow/dags/google_analytics_data_etl.py
[2024-07-16T14:46:05.079+0000] {processor.py:183} INFO - Processing /opt/airflow/dags/google_analytics_data_etl.py took 0.137 seconds
[2024-07-16T14:46:35.255+0000] {processor.py:161} INFO - Started process (PID=8301) to work on /opt/airflow/dags/google_analytics_data_etl.py
[2024-07-16T14:46:35.257+0000] {processor.py:830} INFO - Processing file /opt/airflow/dags/google_analytics_data_etl.py for tasks to queue
[2024-07-16T14:46:35.259+0000] {logging_mixin.py:188} INFO - [2024-07-16T14:46:35.259+0000] {dagbag.py:538} INFO - Filling up the DagBag from /opt/airflow/dags/google_analytics_data_etl.py
[2024-07-16T14:46:35.313+0000] {logging_mixin.py:188} INFO - [2024-07-16T14:46:35.303+0000] {dagbag.py:348} ERROR - Failed to import: /opt/airflow/dags/google_analytics_data_etl.py
Traceback (most recent call last):
  File "/home/airflow/.local/lib/python3.8/site-packages/airflow/models/dagbag.py", line 344, in parse
    loader.exec_module(new_module)
  File "<frozen importlib._bootstrap_external>", line 843, in exec_module
  File "<frozen importlib._bootstrap>", line 219, in _call_with_frames_removed
  File "/opt/airflow/dags/google_analytics_data_etl.py", line 14, in <module>
    task_1 = PythonOperator()
  File "/home/airflow/.local/lib/python3.8/site-packages/airflow/models/baseoperator.py", line 420, in apply_defaults
    raise AirflowException(f"missing keyword argument {missing_args.pop()!r}")
airflow.exceptions.AirflowException: missing keyword argument 'python_callable'
[2024-07-16T14:46:35.316+0000] {processor.py:842} WARNING - No viable dags retrieved from /opt/airflow/dags/google_analytics_data_etl.py
[2024-07-16T14:46:35.332+0000] {processor.py:183} INFO - Processing /opt/airflow/dags/google_analytics_data_etl.py took 0.084 seconds
[2024-07-16T14:47:05.873+0000] {processor.py:161} INFO - Started process (PID=8355) to work on /opt/airflow/dags/google_analytics_data_etl.py
[2024-07-16T14:47:05.876+0000] {processor.py:830} INFO - Processing file /opt/airflow/dags/google_analytics_data_etl.py for tasks to queue
[2024-07-16T14:47:05.877+0000] {logging_mixin.py:188} INFO - [2024-07-16T14:47:05.876+0000] {dagbag.py:538} INFO - Filling up the DagBag from /opt/airflow/dags/google_analytics_data_etl.py
[2024-07-16T14:47:05.915+0000] {logging_mixin.py:188} INFO - [2024-07-16T14:47:05.901+0000] {dagbag.py:348} ERROR - Failed to import: /opt/airflow/dags/google_analytics_data_etl.py
Traceback (most recent call last):
  File "/home/airflow/.local/lib/python3.8/site-packages/airflow/models/dagbag.py", line 344, in parse
    loader.exec_module(new_module)
  File "<frozen importlib._bootstrap_external>", line 843, in exec_module
  File "<frozen importlib._bootstrap>", line 219, in _call_with_frames_removed
  File "/opt/airflow/dags/google_analytics_data_etl.py", line 14, in <module>
    task_1 = PythonOperator()
  File "/home/airflow/.local/lib/python3.8/site-packages/airflow/models/baseoperator.py", line 420, in apply_defaults
    raise AirflowException(f"missing keyword argument {missing_args.pop()!r}")
airflow.exceptions.AirflowException: missing keyword argument 'python_callable'
[2024-07-16T14:47:05.920+0000] {processor.py:842} WARNING - No viable dags retrieved from /opt/airflow/dags/google_analytics_data_etl.py
[2024-07-16T14:47:05.943+0000] {processor.py:183} INFO - Processing /opt/airflow/dags/google_analytics_data_etl.py took 0.082 seconds
[2024-07-16T14:47:36.773+0000] {processor.py:161} INFO - Started process (PID=8411) to work on /opt/airflow/dags/google_analytics_data_etl.py
[2024-07-16T14:47:36.777+0000] {processor.py:830} INFO - Processing file /opt/airflow/dags/google_analytics_data_etl.py for tasks to queue
[2024-07-16T14:47:36.781+0000] {logging_mixin.py:188} INFO - [2024-07-16T14:47:36.780+0000] {dagbag.py:538} INFO - Filling up the DagBag from /opt/airflow/dags/google_analytics_data_etl.py
[2024-07-16T14:47:36.854+0000] {logging_mixin.py:188} INFO - [2024-07-16T14:47:36.846+0000] {dagbag.py:348} ERROR - Failed to import: /opt/airflow/dags/google_analytics_data_etl.py
Traceback (most recent call last):
  File "/home/airflow/.local/lib/python3.8/site-packages/airflow/models/dagbag.py", line 344, in parse
    loader.exec_module(new_module)
  File "<frozen importlib._bootstrap_external>", line 843, in exec_module
  File "<frozen importlib._bootstrap>", line 219, in _call_with_frames_removed
  File "/opt/airflow/dags/google_analytics_data_etl.py", line 14, in <module>
    task_1 = PythonOperator()
  File "/home/airflow/.local/lib/python3.8/site-packages/airflow/models/baseoperator.py", line 420, in apply_defaults
    raise AirflowException(f"missing keyword argument {missing_args.pop()!r}")
airflow.exceptions.AirflowException: missing keyword argument 'python_callable'
[2024-07-16T14:47:36.862+0000] {processor.py:842} WARNING - No viable dags retrieved from /opt/airflow/dags/google_analytics_data_etl.py
[2024-07-16T14:47:36.908+0000] {processor.py:183} INFO - Processing /opt/airflow/dags/google_analytics_data_etl.py took 0.148 seconds
[2024-07-16T14:48:06.957+0000] {processor.py:161} INFO - Started process (PID=8468) to work on /opt/airflow/dags/google_analytics_data_etl.py
[2024-07-16T14:48:06.958+0000] {processor.py:830} INFO - Processing file /opt/airflow/dags/google_analytics_data_etl.py for tasks to queue
[2024-07-16T14:48:06.959+0000] {logging_mixin.py:188} INFO - [2024-07-16T14:48:06.959+0000] {dagbag.py:538} INFO - Filling up the DagBag from /opt/airflow/dags/google_analytics_data_etl.py
[2024-07-16T14:48:06.985+0000] {logging_mixin.py:188} INFO - [2024-07-16T14:48:06.979+0000] {dagbag.py:348} ERROR - Failed to import: /opt/airflow/dags/google_analytics_data_etl.py
Traceback (most recent call last):
  File "/home/airflow/.local/lib/python3.8/site-packages/airflow/models/dagbag.py", line 344, in parse
    loader.exec_module(new_module)
  File "<frozen importlib._bootstrap_external>", line 843, in exec_module
  File "<frozen importlib._bootstrap>", line 219, in _call_with_frames_removed
  File "/opt/airflow/dags/google_analytics_data_etl.py", line 14, in <module>
    task_1 = PythonOperator()
  File "/home/airflow/.local/lib/python3.8/site-packages/airflow/models/baseoperator.py", line 420, in apply_defaults
    raise AirflowException(f"missing keyword argument {missing_args.pop()!r}")
airflow.exceptions.AirflowException: missing keyword argument 'python_callable'
[2024-07-16T14:48:06.987+0000] {processor.py:842} WARNING - No viable dags retrieved from /opt/airflow/dags/google_analytics_data_etl.py
[2024-07-16T14:48:07.003+0000] {processor.py:183} INFO - Processing /opt/airflow/dags/google_analytics_data_etl.py took 0.048 seconds
[2024-07-16T14:48:37.617+0000] {processor.py:161} INFO - Started process (PID=8524) to work on /opt/airflow/dags/google_analytics_data_etl.py
[2024-07-16T14:48:37.625+0000] {processor.py:830} INFO - Processing file /opt/airflow/dags/google_analytics_data_etl.py for tasks to queue
[2024-07-16T14:48:37.632+0000] {logging_mixin.py:188} INFO - [2024-07-16T14:48:37.631+0000] {dagbag.py:538} INFO - Filling up the DagBag from /opt/airflow/dags/google_analytics_data_etl.py
[2024-07-16T14:48:37.789+0000] {logging_mixin.py:188} INFO - [2024-07-16T14:48:37.759+0000] {dagbag.py:348} ERROR - Failed to import: /opt/airflow/dags/google_analytics_data_etl.py
Traceback (most recent call last):
  File "/home/airflow/.local/lib/python3.8/site-packages/airflow/models/dagbag.py", line 344, in parse
    loader.exec_module(new_module)
  File "<frozen importlib._bootstrap_external>", line 843, in exec_module
  File "<frozen importlib._bootstrap>", line 219, in _call_with_frames_removed
  File "/opt/airflow/dags/google_analytics_data_etl.py", line 14, in <module>
    task_1 = PythonOperator()
  File "/home/airflow/.local/lib/python3.8/site-packages/airflow/models/baseoperator.py", line 420, in apply_defaults
    raise AirflowException(f"missing keyword argument {missing_args.pop()!r}")
airflow.exceptions.AirflowException: missing keyword argument 'python_callable'
[2024-07-16T14:48:37.791+0000] {processor.py:842} WARNING - No viable dags retrieved from /opt/airflow/dags/google_analytics_data_etl.py
[2024-07-16T14:48:37.811+0000] {processor.py:183} INFO - Processing /opt/airflow/dags/google_analytics_data_etl.py took 0.215 seconds
[2024-07-16T14:49:08.064+0000] {processor.py:161} INFO - Started process (PID=8580) to work on /opt/airflow/dags/google_analytics_data_etl.py
[2024-07-16T14:49:08.067+0000] {processor.py:830} INFO - Processing file /opt/airflow/dags/google_analytics_data_etl.py for tasks to queue
[2024-07-16T14:49:08.070+0000] {logging_mixin.py:188} INFO - [2024-07-16T14:49:08.069+0000] {dagbag.py:538} INFO - Filling up the DagBag from /opt/airflow/dags/google_analytics_data_etl.py
[2024-07-16T14:49:08.214+0000] {logging_mixin.py:188} INFO - [2024-07-16T14:49:08.131+0000] {dagbag.py:348} ERROR - Failed to import: /opt/airflow/dags/google_analytics_data_etl.py
Traceback (most recent call last):
  File "/home/airflow/.local/lib/python3.8/site-packages/airflow/models/dagbag.py", line 344, in parse
    loader.exec_module(new_module)
  File "<frozen importlib._bootstrap_external>", line 843, in exec_module
  File "<frozen importlib._bootstrap>", line 219, in _call_with_frames_removed
  File "/opt/airflow/dags/google_analytics_data_etl.py", line 14, in <module>
    task_1 = PythonOperator()
  File "/home/airflow/.local/lib/python3.8/site-packages/airflow/models/baseoperator.py", line 420, in apply_defaults
    raise AirflowException(f"missing keyword argument {missing_args.pop()!r}")
airflow.exceptions.AirflowException: missing keyword argument 'python_callable'
[2024-07-16T14:49:08.229+0000] {processor.py:842} WARNING - No viable dags retrieved from /opt/airflow/dags/google_analytics_data_etl.py
[2024-07-16T14:49:08.273+0000] {processor.py:183} INFO - Processing /opt/airflow/dags/google_analytics_data_etl.py took 0.215 seconds
[2024-07-16T14:49:38.541+0000] {processor.py:161} INFO - Started process (PID=8636) to work on /opt/airflow/dags/google_analytics_data_etl.py
[2024-07-16T14:49:38.543+0000] {processor.py:830} INFO - Processing file /opt/airflow/dags/google_analytics_data_etl.py for tasks to queue
[2024-07-16T14:49:38.545+0000] {logging_mixin.py:188} INFO - [2024-07-16T14:49:38.545+0000] {dagbag.py:538} INFO - Filling up the DagBag from /opt/airflow/dags/google_analytics_data_etl.py
[2024-07-16T14:49:38.580+0000] {logging_mixin.py:188} INFO - [2024-07-16T14:49:38.572+0000] {dagbag.py:348} ERROR - Failed to import: /opt/airflow/dags/google_analytics_data_etl.py
Traceback (most recent call last):
  File "/home/airflow/.local/lib/python3.8/site-packages/airflow/models/dagbag.py", line 344, in parse
    loader.exec_module(new_module)
  File "<frozen importlib._bootstrap_external>", line 843, in exec_module
  File "<frozen importlib._bootstrap>", line 219, in _call_with_frames_removed
  File "/opt/airflow/dags/google_analytics_data_etl.py", line 14, in <module>
    task_1 = PythonOperator()
  File "/home/airflow/.local/lib/python3.8/site-packages/airflow/models/baseoperator.py", line 420, in apply_defaults
    raise AirflowException(f"missing keyword argument {missing_args.pop()!r}")
airflow.exceptions.AirflowException: missing keyword argument 'python_callable'
[2024-07-16T14:49:38.584+0000] {processor.py:842} WARNING - No viable dags retrieved from /opt/airflow/dags/google_analytics_data_etl.py
[2024-07-16T14:49:38.607+0000] {processor.py:183} INFO - Processing /opt/airflow/dags/google_analytics_data_etl.py took 0.070 seconds
[2024-07-16T14:50:08.936+0000] {processor.py:161} INFO - Started process (PID=8691) to work on /opt/airflow/dags/google_analytics_data_etl.py
[2024-07-16T14:50:08.940+0000] {processor.py:830} INFO - Processing file /opt/airflow/dags/google_analytics_data_etl.py for tasks to queue
[2024-07-16T14:50:08.943+0000] {logging_mixin.py:188} INFO - [2024-07-16T14:50:08.942+0000] {dagbag.py:538} INFO - Filling up the DagBag from /opt/airflow/dags/google_analytics_data_etl.py
[2024-07-16T14:50:09.025+0000] {logging_mixin.py:188} INFO - [2024-07-16T14:50:09.011+0000] {dagbag.py:348} ERROR - Failed to import: /opt/airflow/dags/google_analytics_data_etl.py
Traceback (most recent call last):
  File "/home/airflow/.local/lib/python3.8/site-packages/airflow/models/dagbag.py", line 344, in parse
    loader.exec_module(new_module)
  File "<frozen importlib._bootstrap_external>", line 843, in exec_module
  File "<frozen importlib._bootstrap>", line 219, in _call_with_frames_removed
  File "/opt/airflow/dags/google_analytics_data_etl.py", line 14, in <module>
    task_1 = PythonOperator()
  File "/home/airflow/.local/lib/python3.8/site-packages/airflow/models/baseoperator.py", line 420, in apply_defaults
    raise AirflowException(f"missing keyword argument {missing_args.pop()!r}")
airflow.exceptions.AirflowException: missing keyword argument 'python_callable'
[2024-07-16T14:50:09.029+0000] {processor.py:842} WARNING - No viable dags retrieved from /opt/airflow/dags/google_analytics_data_etl.py
[2024-07-16T14:50:09.050+0000] {processor.py:183} INFO - Processing /opt/airflow/dags/google_analytics_data_etl.py took 0.119 seconds
[2024-07-16T14:50:20.996+0000] {processor.py:161} INFO - Started process (PID=8706) to work on /opt/airflow/dags/google_analytics_data_etl.py
[2024-07-16T14:50:20.998+0000] {processor.py:830} INFO - Processing file /opt/airflow/dags/google_analytics_data_etl.py for tasks to queue
[2024-07-16T14:50:20.999+0000] {logging_mixin.py:188} INFO - [2024-07-16T14:50:20.999+0000] {dagbag.py:538} INFO - Filling up the DagBag from /opt/airflow/dags/google_analytics_data_etl.py
[2024-07-16T14:50:21.047+0000] {logging_mixin.py:188} INFO - [2024-07-16T14:50:21.036+0000] {dagbag.py:348} ERROR - Failed to import: /opt/airflow/dags/google_analytics_data_etl.py
Traceback (most recent call last):
  File "/home/airflow/.local/lib/python3.8/site-packages/airflow/models/dagbag.py", line 344, in parse
    loader.exec_module(new_module)
  File "<frozen importlib._bootstrap_external>", line 843, in exec_module
  File "<frozen importlib._bootstrap>", line 219, in _call_with_frames_removed
  File "/opt/airflow/dags/google_analytics_data_etl.py", line 14, in <module>
    extraction_data = PythonOperator()
  File "/home/airflow/.local/lib/python3.8/site-packages/airflow/models/baseoperator.py", line 420, in apply_defaults
    raise AirflowException(f"missing keyword argument {missing_args.pop()!r}")
airflow.exceptions.AirflowException: missing keyword argument 'python_callable'
[2024-07-16T14:50:21.049+0000] {processor.py:842} WARNING - No viable dags retrieved from /opt/airflow/dags/google_analytics_data_etl.py
[2024-07-16T14:50:21.067+0000] {processor.py:183} INFO - Processing /opt/airflow/dags/google_analytics_data_etl.py took 0.076 seconds
[2024-07-16T14:50:51.309+0000] {processor.py:161} INFO - Started process (PID=8762) to work on /opt/airflow/dags/google_analytics_data_etl.py
[2024-07-16T14:50:51.310+0000] {processor.py:830} INFO - Processing file /opt/airflow/dags/google_analytics_data_etl.py for tasks to queue
[2024-07-16T14:50:51.311+0000] {logging_mixin.py:188} INFO - [2024-07-16T14:50:51.311+0000] {dagbag.py:538} INFO - Filling up the DagBag from /opt/airflow/dags/google_analytics_data_etl.py
[2024-07-16T14:50:51.328+0000] {logging_mixin.py:188} INFO - [2024-07-16T14:50:51.323+0000] {dagbag.py:348} ERROR - Failed to import: /opt/airflow/dags/google_analytics_data_etl.py
Traceback (most recent call last):
  File "/home/airflow/.local/lib/python3.8/site-packages/airflow/models/dagbag.py", line 344, in parse
    loader.exec_module(new_module)
  File "<frozen importlib._bootstrap_external>", line 843, in exec_module
  File "<frozen importlib._bootstrap>", line 219, in _call_with_frames_removed
  File "/opt/airflow/dags/google_analytics_data_etl.py", line 14, in <module>
    extraction_data = PythonOperator()
  File "/home/airflow/.local/lib/python3.8/site-packages/airflow/models/baseoperator.py", line 420, in apply_defaults
    raise AirflowException(f"missing keyword argument {missing_args.pop()!r}")
airflow.exceptions.AirflowException: missing keyword argument 'python_callable'
[2024-07-16T14:50:51.330+0000] {processor.py:842} WARNING - No viable dags retrieved from /opt/airflow/dags/google_analytics_data_etl.py
[2024-07-16T14:50:51.348+0000] {processor.py:183} INFO - Processing /opt/airflow/dags/google_analytics_data_etl.py took 0.042 seconds
[2024-07-16T14:51:21.809+0000] {processor.py:161} INFO - Started process (PID=8817) to work on /opt/airflow/dags/google_analytics_data_etl.py
[2024-07-16T14:51:21.812+0000] {processor.py:830} INFO - Processing file /opt/airflow/dags/google_analytics_data_etl.py for tasks to queue
[2024-07-16T14:51:21.814+0000] {logging_mixin.py:188} INFO - [2024-07-16T14:51:21.813+0000] {dagbag.py:538} INFO - Filling up the DagBag from /opt/airflow/dags/google_analytics_data_etl.py
[2024-07-16T14:51:21.916+0000] {logging_mixin.py:188} INFO - [2024-07-16T14:51:21.893+0000] {dagbag.py:348} ERROR - Failed to import: /opt/airflow/dags/google_analytics_data_etl.py
Traceback (most recent call last):
  File "/home/airflow/.local/lib/python3.8/site-packages/airflow/models/dagbag.py", line 344, in parse
    loader.exec_module(new_module)
  File "<frozen importlib._bootstrap_external>", line 843, in exec_module
  File "<frozen importlib._bootstrap>", line 219, in _call_with_frames_removed
  File "/opt/airflow/dags/google_analytics_data_etl.py", line 14, in <module>
    extraction_data = PythonOperator()
  File "/home/airflow/.local/lib/python3.8/site-packages/airflow/models/baseoperator.py", line 420, in apply_defaults
    raise AirflowException(f"missing keyword argument {missing_args.pop()!r}")
airflow.exceptions.AirflowException: missing keyword argument 'python_callable'
[2024-07-16T14:51:21.920+0000] {processor.py:842} WARNING - No viable dags retrieved from /opt/airflow/dags/google_analytics_data_etl.py
[2024-07-16T14:51:21.950+0000] {processor.py:183} INFO - Processing /opt/airflow/dags/google_analytics_data_etl.py took 0.153 seconds
[2024-07-16T14:51:37.404+0000] {processor.py:161} INFO - Started process (PID=8854) to work on /opt/airflow/dags/google_analytics_data_etl.py
[2024-07-16T14:51:37.407+0000] {processor.py:830} INFO - Processing file /opt/airflow/dags/google_analytics_data_etl.py for tasks to queue
[2024-07-16T14:51:37.417+0000] {logging_mixin.py:188} INFO - [2024-07-16T14:51:37.417+0000] {dagbag.py:538} INFO - Filling up the DagBag from /opt/airflow/dags/google_analytics_data_etl.py
[2024-07-16T14:51:37.519+0000] {logging_mixin.py:188} INFO - [2024-07-16T14:51:37.481+0000] {dagbag.py:348} ERROR - Failed to import: /opt/airflow/dags/google_analytics_data_etl.py
Traceback (most recent call last):
  File "/home/airflow/.local/lib/python3.8/site-packages/airflow/models/dagbag.py", line 344, in parse
    loader.exec_module(new_module)
  File "<frozen importlib._bootstrap_external>", line 843, in exec_module
  File "<frozen importlib._bootstrap>", line 219, in _call_with_frames_removed
  File "/opt/airflow/dags/google_analytics_data_etl.py", line 14, in <module>
    task_extraction_data = PythonOperator(
  File "/home/airflow/.local/lib/python3.8/site-packages/airflow/models/baseoperator.py", line 420, in apply_defaults
    raise AirflowException(f"missing keyword argument {missing_args.pop()!r}")
airflow.exceptions.AirflowException: missing keyword argument 'python_callable'
[2024-07-16T14:51:37.533+0000] {processor.py:842} WARNING - No viable dags retrieved from /opt/airflow/dags/google_analytics_data_etl.py
[2024-07-16T14:51:37.578+0000] {processor.py:183} INFO - Processing /opt/airflow/dags/google_analytics_data_etl.py took 0.179 seconds
[2024-07-16T14:52:03.111+0000] {processor.py:161} INFO - Started process (PID=8900) to work on /opt/airflow/dags/google_analytics_data_etl.py
[2024-07-16T14:52:03.113+0000] {processor.py:830} INFO - Processing file /opt/airflow/dags/google_analytics_data_etl.py for tasks to queue
[2024-07-16T14:52:03.119+0000] {logging_mixin.py:188} INFO - [2024-07-16T14:52:03.117+0000] {dagbag.py:538} INFO - Filling up the DagBag from /opt/airflow/dags/google_analytics_data_etl.py
[2024-07-16T14:52:03.175+0000] {logging_mixin.py:188} INFO - [2024-07-16T14:52:03.173+0000] {dagbag.py:348} ERROR - Failed to import: /opt/airflow/dags/google_analytics_data_etl.py
Traceback (most recent call last):
  File "/home/airflow/.local/lib/python3.8/site-packages/airflow/models/dagbag.py", line 344, in parse
    loader.exec_module(new_module)
  File "<frozen importlib._bootstrap_external>", line 839, in exec_module
  File "<frozen importlib._bootstrap_external>", line 976, in get_code
  File "<frozen importlib._bootstrap_external>", line 906, in source_to_code
  File "<frozen importlib._bootstrap>", line 219, in _call_with_frames_removed
  File "/opt/airflow/dags/google_analytics_data_etl.py", line 17
    )
    ^
SyntaxError: invalid syntax
[2024-07-16T14:52:03.176+0000] {processor.py:842} WARNING - No viable dags retrieved from /opt/airflow/dags/google_analytics_data_etl.py
[2024-07-16T14:52:03.196+0000] {processor.py:183} INFO - Processing /opt/airflow/dags/google_analytics_data_etl.py took 0.096 seconds
[2024-07-16T14:52:34.308+0000] {processor.py:161} INFO - Started process (PID=8955) to work on /opt/airflow/dags/google_analytics_data_etl.py
[2024-07-16T14:52:34.319+0000] {processor.py:830} INFO - Processing file /opt/airflow/dags/google_analytics_data_etl.py for tasks to queue
[2024-07-16T14:52:34.326+0000] {logging_mixin.py:188} INFO - [2024-07-16T14:52:34.324+0000] {dagbag.py:538} INFO - Filling up the DagBag from /opt/airflow/dags/google_analytics_data_etl.py
[2024-07-16T14:52:34.459+0000] {logging_mixin.py:188} INFO - [2024-07-16T14:52:34.457+0000] {dagbag.py:348} ERROR - Failed to import: /opt/airflow/dags/google_analytics_data_etl.py
Traceback (most recent call last):
  File "/home/airflow/.local/lib/python3.8/site-packages/airflow/models/dagbag.py", line 344, in parse
    loader.exec_module(new_module)
  File "<frozen importlib._bootstrap_external>", line 839, in exec_module
  File "<frozen importlib._bootstrap_external>", line 976, in get_code
  File "<frozen importlib._bootstrap_external>", line 906, in source_to_code
  File "<frozen importlib._bootstrap>", line 219, in _call_with_frames_removed
  File "/opt/airflow/dags/google_analytics_data_etl.py", line 17
    )
    ^
SyntaxError: invalid syntax
[2024-07-16T14:52:34.462+0000] {processor.py:842} WARNING - No viable dags retrieved from /opt/airflow/dags/google_analytics_data_etl.py
[2024-07-16T14:52:34.661+0000] {processor.py:183} INFO - Processing /opt/airflow/dags/google_analytics_data_etl.py took 0.365 seconds
[2024-07-16T14:53:05.430+0000] {processor.py:161} INFO - Started process (PID=9010) to work on /opt/airflow/dags/google_analytics_data_etl.py
[2024-07-16T14:53:05.435+0000] {processor.py:830} INFO - Processing file /opt/airflow/dags/google_analytics_data_etl.py for tasks to queue
[2024-07-16T14:53:05.437+0000] {logging_mixin.py:188} INFO - [2024-07-16T14:53:05.436+0000] {dagbag.py:538} INFO - Filling up the DagBag from /opt/airflow/dags/google_analytics_data_etl.py
[2024-07-16T14:53:05.484+0000] {logging_mixin.py:188} INFO - [2024-07-16T14:53:05.483+0000] {dagbag.py:348} ERROR - Failed to import: /opt/airflow/dags/google_analytics_data_etl.py
Traceback (most recent call last):
  File "/home/airflow/.local/lib/python3.8/site-packages/airflow/models/dagbag.py", line 344, in parse
    loader.exec_module(new_module)
  File "<frozen importlib._bootstrap_external>", line 839, in exec_module
  File "<frozen importlib._bootstrap_external>", line 976, in get_code
  File "<frozen importlib._bootstrap_external>", line 906, in source_to_code
  File "<frozen importlib._bootstrap>", line 219, in _call_with_frames_removed
  File "/opt/airflow/dags/google_analytics_data_etl.py", line 17
    )
    ^
SyntaxError: invalid syntax
[2024-07-16T14:53:05.485+0000] {processor.py:842} WARNING - No viable dags retrieved from /opt/airflow/dags/google_analytics_data_etl.py
[2024-07-16T14:53:05.510+0000] {processor.py:183} INFO - Processing /opt/airflow/dags/google_analytics_data_etl.py took 0.087 seconds
[2024-07-16T14:53:35.960+0000] {processor.py:161} INFO - Started process (PID=9066) to work on /opt/airflow/dags/google_analytics_data_etl.py
[2024-07-16T14:53:35.965+0000] {processor.py:830} INFO - Processing file /opt/airflow/dags/google_analytics_data_etl.py for tasks to queue
[2024-07-16T14:53:35.969+0000] {logging_mixin.py:188} INFO - [2024-07-16T14:53:35.969+0000] {dagbag.py:538} INFO - Filling up the DagBag from /opt/airflow/dags/google_analytics_data_etl.py
[2024-07-16T14:53:36.010+0000] {logging_mixin.py:188} INFO - [2024-07-16T14:53:36.009+0000] {dagbag.py:348} ERROR - Failed to import: /opt/airflow/dags/google_analytics_data_etl.py
Traceback (most recent call last):
  File "/home/airflow/.local/lib/python3.8/site-packages/airflow/models/dagbag.py", line 344, in parse
    loader.exec_module(new_module)
  File "<frozen importlib._bootstrap_external>", line 839, in exec_module
  File "<frozen importlib._bootstrap_external>", line 976, in get_code
  File "<frozen importlib._bootstrap_external>", line 906, in source_to_code
  File "<frozen importlib._bootstrap>", line 219, in _call_with_frames_removed
  File "/opt/airflow/dags/google_analytics_data_etl.py", line 17
    )
    ^
SyntaxError: invalid syntax
[2024-07-16T14:53:36.011+0000] {processor.py:842} WARNING - No viable dags retrieved from /opt/airflow/dags/google_analytics_data_etl.py
[2024-07-16T14:53:36.030+0000] {processor.py:183} INFO - Processing /opt/airflow/dags/google_analytics_data_etl.py took 0.086 seconds
[2024-07-16T14:54:06.236+0000] {processor.py:161} INFO - Started process (PID=9122) to work on /opt/airflow/dags/google_analytics_data_etl.py
[2024-07-16T14:54:06.238+0000] {processor.py:830} INFO - Processing file /opt/airflow/dags/google_analytics_data_etl.py for tasks to queue
[2024-07-16T14:54:06.240+0000] {logging_mixin.py:188} INFO - [2024-07-16T14:54:06.240+0000] {dagbag.py:538} INFO - Filling up the DagBag from /opt/airflow/dags/google_analytics_data_etl.py
[2024-07-16T14:54:06.275+0000] {logging_mixin.py:188} INFO - [2024-07-16T14:54:06.275+0000] {dagbag.py:348} ERROR - Failed to import: /opt/airflow/dags/google_analytics_data_etl.py
Traceback (most recent call last):
  File "/home/airflow/.local/lib/python3.8/site-packages/airflow/models/dagbag.py", line 344, in parse
    loader.exec_module(new_module)
  File "<frozen importlib._bootstrap_external>", line 839, in exec_module
  File "<frozen importlib._bootstrap_external>", line 976, in get_code
  File "<frozen importlib._bootstrap_external>", line 906, in source_to_code
  File "<frozen importlib._bootstrap>", line 219, in _call_with_frames_removed
  File "/opt/airflow/dags/google_analytics_data_etl.py", line 17
    )
    ^
SyntaxError: invalid syntax
[2024-07-16T14:54:06.276+0000] {processor.py:842} WARNING - No viable dags retrieved from /opt/airflow/dags/google_analytics_data_etl.py
[2024-07-16T14:54:06.297+0000] {processor.py:183} INFO - Processing /opt/airflow/dags/google_analytics_data_etl.py took 0.067 seconds
[2024-07-16T14:54:36.674+0000] {processor.py:161} INFO - Started process (PID=9178) to work on /opt/airflow/dags/google_analytics_data_etl.py
[2024-07-16T14:54:36.678+0000] {processor.py:830} INFO - Processing file /opt/airflow/dags/google_analytics_data_etl.py for tasks to queue
[2024-07-16T14:54:36.682+0000] {logging_mixin.py:188} INFO - [2024-07-16T14:54:36.681+0000] {dagbag.py:538} INFO - Filling up the DagBag from /opt/airflow/dags/google_analytics_data_etl.py
[2024-07-16T14:54:36.750+0000] {logging_mixin.py:188} INFO - [2024-07-16T14:54:36.749+0000] {dagbag.py:348} ERROR - Failed to import: /opt/airflow/dags/google_analytics_data_etl.py
Traceback (most recent call last):
  File "/home/airflow/.local/lib/python3.8/site-packages/airflow/models/dagbag.py", line 344, in parse
    loader.exec_module(new_module)
  File "<frozen importlib._bootstrap_external>", line 839, in exec_module
  File "<frozen importlib._bootstrap_external>", line 976, in get_code
  File "<frozen importlib._bootstrap_external>", line 906, in source_to_code
  File "<frozen importlib._bootstrap>", line 219, in _call_with_frames_removed
  File "/opt/airflow/dags/google_analytics_data_etl.py", line 17
    )
    ^
SyntaxError: invalid syntax
[2024-07-16T14:54:36.751+0000] {processor.py:842} WARNING - No viable dags retrieved from /opt/airflow/dags/google_analytics_data_etl.py
[2024-07-16T14:54:36.779+0000] {processor.py:183} INFO - Processing /opt/airflow/dags/google_analytics_data_etl.py took 0.117 seconds
[2024-07-16T14:55:07.271+0000] {processor.py:161} INFO - Started process (PID=9234) to work on /opt/airflow/dags/google_analytics_data_etl.py
[2024-07-16T14:55:07.273+0000] {processor.py:830} INFO - Processing file /opt/airflow/dags/google_analytics_data_etl.py for tasks to queue
[2024-07-16T14:55:07.275+0000] {logging_mixin.py:188} INFO - [2024-07-16T14:55:07.274+0000] {dagbag.py:538} INFO - Filling up the DagBag from /opt/airflow/dags/google_analytics_data_etl.py
[2024-07-16T14:55:07.296+0000] {logging_mixin.py:188} INFO - [2024-07-16T14:55:07.294+0000] {dagbag.py:348} ERROR - Failed to import: /opt/airflow/dags/google_analytics_data_etl.py
Traceback (most recent call last):
  File "/home/airflow/.local/lib/python3.8/site-packages/airflow/models/dagbag.py", line 344, in parse
    loader.exec_module(new_module)
  File "<frozen importlib._bootstrap_external>", line 839, in exec_module
  File "<frozen importlib._bootstrap_external>", line 976, in get_code
  File "<frozen importlib._bootstrap_external>", line 906, in source_to_code
  File "<frozen importlib._bootstrap>", line 219, in _call_with_frames_removed
  File "/opt/airflow/dags/google_analytics_data_etl.py", line 17
    )
    ^
SyntaxError: invalid syntax
[2024-07-16T14:55:07.296+0000] {processor.py:842} WARNING - No viable dags retrieved from /opt/airflow/dags/google_analytics_data_etl.py
[2024-07-16T14:55:07.319+0000] {processor.py:183} INFO - Processing /opt/airflow/dags/google_analytics_data_etl.py took 0.051 seconds
[2024-07-16T14:55:37.802+0000] {processor.py:161} INFO - Started process (PID=9290) to work on /opt/airflow/dags/google_analytics_data_etl.py
[2024-07-16T14:55:37.804+0000] {processor.py:830} INFO - Processing file /opt/airflow/dags/google_analytics_data_etl.py for tasks to queue
[2024-07-16T14:55:37.807+0000] {logging_mixin.py:188} INFO - [2024-07-16T14:55:37.806+0000] {dagbag.py:538} INFO - Filling up the DagBag from /opt/airflow/dags/google_analytics_data_etl.py
[2024-07-16T14:55:37.827+0000] {logging_mixin.py:188} INFO - [2024-07-16T14:55:37.826+0000] {dagbag.py:348} ERROR - Failed to import: /opt/airflow/dags/google_analytics_data_etl.py
Traceback (most recent call last):
  File "/home/airflow/.local/lib/python3.8/site-packages/airflow/models/dagbag.py", line 344, in parse
    loader.exec_module(new_module)
  File "<frozen importlib._bootstrap_external>", line 839, in exec_module
  File "<frozen importlib._bootstrap_external>", line 976, in get_code
  File "<frozen importlib._bootstrap_external>", line 906, in source_to_code
  File "<frozen importlib._bootstrap>", line 219, in _call_with_frames_removed
  File "/opt/airflow/dags/google_analytics_data_etl.py", line 17
    )
    ^
SyntaxError: invalid syntax
[2024-07-16T14:55:37.828+0000] {processor.py:842} WARNING - No viable dags retrieved from /opt/airflow/dags/google_analytics_data_etl.py
[2024-07-16T14:55:37.877+0000] {processor.py:183} INFO - Processing /opt/airflow/dags/google_analytics_data_etl.py took 0.079 seconds
[2024-07-16T14:56:08.064+0000] {processor.py:161} INFO - Started process (PID=9346) to work on /opt/airflow/dags/google_analytics_data_etl.py
[2024-07-16T14:56:08.067+0000] {processor.py:830} INFO - Processing file /opt/airflow/dags/google_analytics_data_etl.py for tasks to queue
[2024-07-16T14:56:08.072+0000] {logging_mixin.py:188} INFO - [2024-07-16T14:56:08.071+0000] {dagbag.py:538} INFO - Filling up the DagBag from /opt/airflow/dags/google_analytics_data_etl.py
[2024-07-16T14:56:08.139+0000] {logging_mixin.py:188} INFO - [2024-07-16T14:56:08.138+0000] {dagbag.py:348} ERROR - Failed to import: /opt/airflow/dags/google_analytics_data_etl.py
Traceback (most recent call last):
  File "/home/airflow/.local/lib/python3.8/site-packages/airflow/models/dagbag.py", line 344, in parse
    loader.exec_module(new_module)
  File "<frozen importlib._bootstrap_external>", line 839, in exec_module
  File "<frozen importlib._bootstrap_external>", line 976, in get_code
  File "<frozen importlib._bootstrap_external>", line 906, in source_to_code
  File "<frozen importlib._bootstrap>", line 219, in _call_with_frames_removed
  File "/opt/airflow/dags/google_analytics_data_etl.py", line 17
    )
    ^
SyntaxError: invalid syntax
[2024-07-16T14:56:08.142+0000] {processor.py:842} WARNING - No viable dags retrieved from /opt/airflow/dags/google_analytics_data_etl.py
[2024-07-16T14:56:08.191+0000] {processor.py:183} INFO - Processing /opt/airflow/dags/google_analytics_data_etl.py took 0.138 seconds
[2024-07-16T14:56:38.800+0000] {processor.py:161} INFO - Started process (PID=9401) to work on /opt/airflow/dags/google_analytics_data_etl.py
[2024-07-16T14:56:38.812+0000] {processor.py:830} INFO - Processing file /opt/airflow/dags/google_analytics_data_etl.py for tasks to queue
[2024-07-16T14:56:38.817+0000] {logging_mixin.py:188} INFO - [2024-07-16T14:56:38.816+0000] {dagbag.py:538} INFO - Filling up the DagBag from /opt/airflow/dags/google_analytics_data_etl.py
[2024-07-16T14:56:38.898+0000] {logging_mixin.py:188} INFO - [2024-07-16T14:56:38.897+0000] {dagbag.py:348} ERROR - Failed to import: /opt/airflow/dags/google_analytics_data_etl.py
Traceback (most recent call last):
  File "/home/airflow/.local/lib/python3.8/site-packages/airflow/models/dagbag.py", line 344, in parse
    loader.exec_module(new_module)
  File "<frozen importlib._bootstrap_external>", line 839, in exec_module
  File "<frozen importlib._bootstrap_external>", line 976, in get_code
  File "<frozen importlib._bootstrap_external>", line 906, in source_to_code
  File "<frozen importlib._bootstrap>", line 219, in _call_with_frames_removed
  File "/opt/airflow/dags/google_analytics_data_etl.py", line 17
    )
    ^
SyntaxError: invalid syntax
[2024-07-16T14:56:38.899+0000] {processor.py:842} WARNING - No viable dags retrieved from /opt/airflow/dags/google_analytics_data_etl.py
[2024-07-16T14:56:38.932+0000] {processor.py:183} INFO - Processing /opt/airflow/dags/google_analytics_data_etl.py took 0.141 seconds
[2024-07-16T14:57:09.506+0000] {processor.py:161} INFO - Started process (PID=9457) to work on /opt/airflow/dags/google_analytics_data_etl.py
[2024-07-16T14:57:09.508+0000] {processor.py:830} INFO - Processing file /opt/airflow/dags/google_analytics_data_etl.py for tasks to queue
[2024-07-16T14:57:09.519+0000] {logging_mixin.py:188} INFO - [2024-07-16T14:57:09.518+0000] {dagbag.py:538} INFO - Filling up the DagBag from /opt/airflow/dags/google_analytics_data_etl.py
[2024-07-16T14:57:09.530+0000] {logging_mixin.py:188} INFO - [2024-07-16T14:57:09.529+0000] {dagbag.py:348} ERROR - Failed to import: /opt/airflow/dags/google_analytics_data_etl.py
Traceback (most recent call last):
  File "/home/airflow/.local/lib/python3.8/site-packages/airflow/models/dagbag.py", line 344, in parse
    loader.exec_module(new_module)
  File "<frozen importlib._bootstrap_external>", line 839, in exec_module
  File "<frozen importlib._bootstrap_external>", line 976, in get_code
  File "<frozen importlib._bootstrap_external>", line 906, in source_to_code
  File "<frozen importlib._bootstrap>", line 219, in _call_with_frames_removed
  File "/opt/airflow/dags/google_analytics_data_etl.py", line 17
    )
    ^
SyntaxError: invalid syntax
[2024-07-16T14:57:09.538+0000] {processor.py:842} WARNING - No viable dags retrieved from /opt/airflow/dags/google_analytics_data_etl.py
[2024-07-16T14:57:09.576+0000] {processor.py:183} INFO - Processing /opt/airflow/dags/google_analytics_data_etl.py took 0.072 seconds
[2024-07-16T14:57:39.882+0000] {processor.py:161} INFO - Started process (PID=9513) to work on /opt/airflow/dags/google_analytics_data_etl.py
[2024-07-16T14:57:39.884+0000] {processor.py:830} INFO - Processing file /opt/airflow/dags/google_analytics_data_etl.py for tasks to queue
[2024-07-16T14:57:39.886+0000] {logging_mixin.py:188} INFO - [2024-07-16T14:57:39.885+0000] {dagbag.py:538} INFO - Filling up the DagBag from /opt/airflow/dags/google_analytics_data_etl.py
[2024-07-16T14:57:39.918+0000] {logging_mixin.py:188} INFO - [2024-07-16T14:57:39.917+0000] {dagbag.py:348} ERROR - Failed to import: /opt/airflow/dags/google_analytics_data_etl.py
Traceback (most recent call last):
  File "/home/airflow/.local/lib/python3.8/site-packages/airflow/models/dagbag.py", line 344, in parse
    loader.exec_module(new_module)
  File "<frozen importlib._bootstrap_external>", line 839, in exec_module
  File "<frozen importlib._bootstrap_external>", line 976, in get_code
  File "<frozen importlib._bootstrap_external>", line 906, in source_to_code
  File "<frozen importlib._bootstrap>", line 219, in _call_with_frames_removed
  File "/opt/airflow/dags/google_analytics_data_etl.py", line 17
    )
    ^
SyntaxError: invalid syntax
[2024-07-16T14:57:39.919+0000] {processor.py:842} WARNING - No viable dags retrieved from /opt/airflow/dags/google_analytics_data_etl.py
[2024-07-16T14:57:39.944+0000] {processor.py:183} INFO - Processing /opt/airflow/dags/google_analytics_data_etl.py took 0.067 seconds
[2024-07-16T14:58:10.560+0000] {processor.py:161} INFO - Started process (PID=9569) to work on /opt/airflow/dags/google_analytics_data_etl.py
[2024-07-16T14:58:10.563+0000] {processor.py:830} INFO - Processing file /opt/airflow/dags/google_analytics_data_etl.py for tasks to queue
[2024-07-16T14:58:10.569+0000] {logging_mixin.py:188} INFO - [2024-07-16T14:58:10.568+0000] {dagbag.py:538} INFO - Filling up the DagBag from /opt/airflow/dags/google_analytics_data_etl.py
[2024-07-16T14:58:10.694+0000] {logging_mixin.py:188} INFO - [2024-07-16T14:58:10.693+0000] {dagbag.py:348} ERROR - Failed to import: /opt/airflow/dags/google_analytics_data_etl.py
Traceback (most recent call last):
  File "/home/airflow/.local/lib/python3.8/site-packages/airflow/models/dagbag.py", line 344, in parse
    loader.exec_module(new_module)
  File "<frozen importlib._bootstrap_external>", line 839, in exec_module
  File "<frozen importlib._bootstrap_external>", line 976, in get_code
  File "<frozen importlib._bootstrap_external>", line 906, in source_to_code
  File "<frozen importlib._bootstrap>", line 219, in _call_with_frames_removed
  File "/opt/airflow/dags/google_analytics_data_etl.py", line 17
    )
    ^
SyntaxError: invalid syntax
[2024-07-16T14:58:10.695+0000] {processor.py:842} WARNING - No viable dags retrieved from /opt/airflow/dags/google_analytics_data_etl.py
[2024-07-16T14:58:10.715+0000] {processor.py:183} INFO - Processing /opt/airflow/dags/google_analytics_data_etl.py took 0.170 seconds
[2024-07-16T14:58:29.472+0000] {processor.py:161} INFO - Started process (PID=9599) to work on /opt/airflow/dags/google_analytics_data_etl.py
[2024-07-16T14:58:29.473+0000] {processor.py:830} INFO - Processing file /opt/airflow/dags/google_analytics_data_etl.py for tasks to queue
[2024-07-16T14:58:29.474+0000] {logging_mixin.py:188} INFO - [2024-07-16T14:58:29.474+0000] {dagbag.py:538} INFO - Filling up the DagBag from /opt/airflow/dags/google_analytics_data_etl.py
[2024-07-16T14:58:29.517+0000] {logging_mixin.py:188} INFO - [2024-07-16T14:58:29.508+0000] {dagbag.py:348} ERROR - Failed to import: /opt/airflow/dags/google_analytics_data_etl.py
Traceback (most recent call last):
  File "/home/airflow/.local/lib/python3.8/site-packages/airflow/models/dagbag.py", line 344, in parse
    loader.exec_module(new_module)
  File "<frozen importlib._bootstrap_external>", line 843, in exec_module
  File "<frozen importlib._bootstrap>", line 219, in _call_with_frames_removed
  File "/opt/airflow/dags/google_analytics_data_etl.py", line 4, in <module>
    from logics import extract
ModuleNotFoundError: No module named 'logics'
[2024-07-16T14:58:29.521+0000] {processor.py:842} WARNING - No viable dags retrieved from /opt/airflow/dags/google_analytics_data_etl.py
[2024-07-16T14:58:29.550+0000] {processor.py:183} INFO - Processing /opt/airflow/dags/google_analytics_data_etl.py took 0.081 seconds
[2024-07-16T14:58:53.967+0000] {processor.py:161} INFO - Started process (PID=9643) to work on /opt/airflow/dags/google_analytics_data_etl.py
[2024-07-16T14:58:53.972+0000] {processor.py:830} INFO - Processing file /opt/airflow/dags/google_analytics_data_etl.py for tasks to queue
[2024-07-16T14:58:53.975+0000] {logging_mixin.py:188} INFO - [2024-07-16T14:58:53.974+0000] {dagbag.py:538} INFO - Filling up the DagBag from /opt/airflow/dags/google_analytics_data_etl.py
[2024-07-16T14:58:54.015+0000] {logging_mixin.py:188} INFO - [2024-07-16T14:58:54.013+0000] {dagbag.py:348} ERROR - Failed to import: /opt/airflow/dags/google_analytics_data_etl.py
Traceback (most recent call last):
  File "/home/airflow/.local/lib/python3.8/site-packages/airflow/models/dagbag.py", line 344, in parse
    loader.exec_module(new_module)
  File "<frozen importlib._bootstrap_external>", line 839, in exec_module
  File "<frozen importlib._bootstrap_external>", line 976, in get_code
  File "<frozen importlib._bootstrap_external>", line 906, in source_to_code
  File "<frozen importlib._bootstrap>", line 219, in _call_with_frames_removed
  File "/opt/airflow/dags/google_analytics_data_etl.py", line 19
    )
    ^
SyntaxError: invalid syntax
[2024-07-16T14:58:54.016+0000] {processor.py:842} WARNING - No viable dags retrieved from /opt/airflow/dags/google_analytics_data_etl.py
[2024-07-16T14:58:54.053+0000] {processor.py:183} INFO - Processing /opt/airflow/dags/google_analytics_data_etl.py took 0.103 seconds
[2024-07-16T14:59:24.318+0000] {processor.py:161} INFO - Started process (PID=9700) to work on /opt/airflow/dags/google_analytics_data_etl.py
[2024-07-16T14:59:24.321+0000] {processor.py:830} INFO - Processing file /opt/airflow/dags/google_analytics_data_etl.py for tasks to queue
[2024-07-16T14:59:24.323+0000] {logging_mixin.py:188} INFO - [2024-07-16T14:59:24.323+0000] {dagbag.py:538} INFO - Filling up the DagBag from /opt/airflow/dags/google_analytics_data_etl.py
[2024-07-16T14:59:24.354+0000] {logging_mixin.py:188} INFO - [2024-07-16T14:59:24.352+0000] {dagbag.py:348} ERROR - Failed to import: /opt/airflow/dags/google_analytics_data_etl.py
Traceback (most recent call last):
  File "/home/airflow/.local/lib/python3.8/site-packages/airflow/models/dagbag.py", line 344, in parse
    loader.exec_module(new_module)
  File "<frozen importlib._bootstrap_external>", line 839, in exec_module
  File "<frozen importlib._bootstrap_external>", line 976, in get_code
  File "<frozen importlib._bootstrap_external>", line 906, in source_to_code
  File "<frozen importlib._bootstrap>", line 219, in _call_with_frames_removed
  File "/opt/airflow/dags/google_analytics_data_etl.py", line 19
    )
    ^
SyntaxError: invalid syntax
[2024-07-16T14:59:24.372+0000] {processor.py:842} WARNING - No viable dags retrieved from /opt/airflow/dags/google_analytics_data_etl.py
[2024-07-16T14:59:24.401+0000] {processor.py:183} INFO - Processing /opt/airflow/dags/google_analytics_data_etl.py took 0.086 seconds
[2024-07-16T14:59:45.587+0000] {processor.py:161} INFO - Started process (PID=9746) to work on /opt/airflow/dags/google_analytics_data_etl.py
[2024-07-16T14:59:45.588+0000] {processor.py:830} INFO - Processing file /opt/airflow/dags/google_analytics_data_etl.py for tasks to queue
[2024-07-16T14:59:45.593+0000] {logging_mixin.py:188} INFO - [2024-07-16T14:59:45.592+0000] {dagbag.py:538} INFO - Filling up the DagBag from /opt/airflow/dags/google_analytics_data_etl.py
[2024-07-16T14:59:45.634+0000] {logging_mixin.py:188} INFO - [2024-07-16T14:59:45.628+0000] {dagbag.py:348} ERROR - Failed to import: /opt/airflow/dags/google_analytics_data_etl.py
Traceback (most recent call last):
  File "/home/airflow/.local/lib/python3.8/site-packages/airflow/models/dagbag.py", line 344, in parse
    loader.exec_module(new_module)
  File "<frozen importlib._bootstrap_external>", line 843, in exec_module
  File "<frozen importlib._bootstrap>", line 219, in _call_with_frames_removed
  File "/opt/airflow/dags/google_analytics_data_etl.py", line 4, in <module>
    from logics import extract
ModuleNotFoundError: No module named 'logics'
[2024-07-16T14:59:45.637+0000] {processor.py:842} WARNING - No viable dags retrieved from /opt/airflow/dags/google_analytics_data_etl.py
[2024-07-16T14:59:45.658+0000] {processor.py:183} INFO - Processing /opt/airflow/dags/google_analytics_data_etl.py took 0.075 seconds
[2024-07-16T15:00:15.970+0000] {processor.py:161} INFO - Started process (PID=9802) to work on /opt/airflow/dags/google_analytics_data_etl.py
[2024-07-16T15:00:15.972+0000] {processor.py:830} INFO - Processing file /opt/airflow/dags/google_analytics_data_etl.py for tasks to queue
[2024-07-16T15:00:15.973+0000] {logging_mixin.py:188} INFO - [2024-07-16T15:00:15.973+0000] {dagbag.py:538} INFO - Filling up the DagBag from /opt/airflow/dags/google_analytics_data_etl.py
[2024-07-16T15:00:16.011+0000] {logging_mixin.py:188} INFO - [2024-07-16T15:00:16.006+0000] {dagbag.py:348} ERROR - Failed to import: /opt/airflow/dags/google_analytics_data_etl.py
Traceback (most recent call last):
  File "/home/airflow/.local/lib/python3.8/site-packages/airflow/models/dagbag.py", line 344, in parse
    loader.exec_module(new_module)
  File "<frozen importlib._bootstrap_external>", line 843, in exec_module
  File "<frozen importlib._bootstrap>", line 219, in _call_with_frames_removed
  File "/opt/airflow/dags/google_analytics_data_etl.py", line 4, in <module>
    from logics import extract
ModuleNotFoundError: No module named 'logics'
[2024-07-16T15:00:16.013+0000] {processor.py:842} WARNING - No viable dags retrieved from /opt/airflow/dags/google_analytics_data_etl.py
[2024-07-16T15:00:16.041+0000] {processor.py:183} INFO - Processing /opt/airflow/dags/google_analytics_data_etl.py took 0.074 seconds
[2024-07-16T15:00:46.292+0000] {processor.py:161} INFO - Started process (PID=9858) to work on /opt/airflow/dags/google_analytics_data_etl.py
[2024-07-16T15:00:46.294+0000] {processor.py:830} INFO - Processing file /opt/airflow/dags/google_analytics_data_etl.py for tasks to queue
[2024-07-16T15:00:46.295+0000] {logging_mixin.py:188} INFO - [2024-07-16T15:00:46.295+0000] {dagbag.py:538} INFO - Filling up the DagBag from /opt/airflow/dags/google_analytics_data_etl.py
[2024-07-16T15:00:46.341+0000] {logging_mixin.py:188} INFO - [2024-07-16T15:00:46.331+0000] {dagbag.py:348} ERROR - Failed to import: /opt/airflow/dags/google_analytics_data_etl.py
Traceback (most recent call last):
  File "/home/airflow/.local/lib/python3.8/site-packages/airflow/models/dagbag.py", line 344, in parse
    loader.exec_module(new_module)
  File "<frozen importlib._bootstrap_external>", line 843, in exec_module
  File "<frozen importlib._bootstrap>", line 219, in _call_with_frames_removed
  File "/opt/airflow/dags/google_analytics_data_etl.py", line 4, in <module>
    from logics import extract
ModuleNotFoundError: No module named 'logics'
[2024-07-16T15:00:46.343+0000] {processor.py:842} WARNING - No viable dags retrieved from /opt/airflow/dags/google_analytics_data_etl.py
[2024-07-16T15:00:46.365+0000] {processor.py:183} INFO - Processing /opt/airflow/dags/google_analytics_data_etl.py took 0.076 seconds
[2024-07-16T15:01:07.321+0000] {processor.py:161} INFO - Started process (PID=9897) to work on /opt/airflow/dags/google_analytics_data_etl.py
[2024-07-16T15:01:07.323+0000] {processor.py:830} INFO - Processing file /opt/airflow/dags/google_analytics_data_etl.py for tasks to queue
[2024-07-16T15:01:07.324+0000] {logging_mixin.py:188} INFO - [2024-07-16T15:01:07.324+0000] {dagbag.py:538} INFO - Filling up the DagBag from /opt/airflow/dags/google_analytics_data_etl.py
[2024-07-16T15:01:07.364+0000] {logging_mixin.py:188} INFO - [2024-07-16T15:01:07.359+0000] {dagbag.py:348} ERROR - Failed to import: /opt/airflow/dags/google_analytics_data_etl.py
Traceback (most recent call last):
  File "/home/airflow/.local/lib/python3.8/site-packages/airflow/models/dagbag.py", line 344, in parse
    loader.exec_module(new_module)
  File "<frozen importlib._bootstrap_external>", line 843, in exec_module
  File "<frozen importlib._bootstrap>", line 219, in _call_with_frames_removed
  File "/opt/airflow/dags/google_analytics_data_etl.py", line 4, in <module>
    from logics import extract
ModuleNotFoundError: No module named 'logics'
[2024-07-16T15:01:07.366+0000] {processor.py:842} WARNING - No viable dags retrieved from /opt/airflow/dags/google_analytics_data_etl.py
[2024-07-16T15:01:07.394+0000] {processor.py:183} INFO - Processing /opt/airflow/dags/google_analytics_data_etl.py took 0.078 seconds
[2024-07-16T15:02:10.008+0000] {processor.py:161} INFO - Started process (PID=28) to work on /opt/airflow/dags/google_analytics_data_etl.py
[2024-07-16T15:02:10.019+0000] {processor.py:830} INFO - Processing file /opt/airflow/dags/google_analytics_data_etl.py for tasks to queue
[2024-07-16T15:02:10.022+0000] {logging_mixin.py:188} INFO - [2024-07-16T15:02:10.022+0000] {dagbag.py:538} INFO - Filling up the DagBag from /opt/airflow/dags/google_analytics_data_etl.py
[2024-07-16T15:02:10.102+0000] {logging_mixin.py:188} INFO - [2024-07-16T15:02:10.082+0000] {dagbag.py:348} ERROR - Failed to import: /opt/airflow/dags/google_analytics_data_etl.py
Traceback (most recent call last):
  File "/home/airflow/.local/lib/python3.8/site-packages/airflow/models/dagbag.py", line 344, in parse
    loader.exec_module(new_module)
  File "<frozen importlib._bootstrap_external>", line 843, in exec_module
  File "<frozen importlib._bootstrap>", line 219, in _call_with_frames_removed
  File "/opt/airflow/dags/google_analytics_data_etl.py", line 4, in <module>
    from logics import extract
ModuleNotFoundError: No module named 'logics'
[2024-07-16T15:02:10.105+0000] {processor.py:842} WARNING - No viable dags retrieved from /opt/airflow/dags/google_analytics_data_etl.py
[2024-07-16T15:02:10.171+0000] {processor.py:183} INFO - Processing /opt/airflow/dags/google_analytics_data_etl.py took 0.165 seconds
[2024-07-16T15:02:40.506+0000] {processor.py:161} INFO - Started process (PID=85) to work on /opt/airflow/dags/google_analytics_data_etl.py
[2024-07-16T15:02:40.526+0000] {processor.py:830} INFO - Processing file /opt/airflow/dags/google_analytics_data_etl.py for tasks to queue
[2024-07-16T15:02:40.539+0000] {logging_mixin.py:188} INFO - [2024-07-16T15:02:40.538+0000] {dagbag.py:538} INFO - Filling up the DagBag from /opt/airflow/dags/google_analytics_data_etl.py
[2024-07-16T15:02:40.635+0000] {logging_mixin.py:188} INFO - [2024-07-16T15:02:40.629+0000] {dagbag.py:348} ERROR - Failed to import: /opt/airflow/dags/google_analytics_data_etl.py
Traceback (most recent call last):
  File "/home/airflow/.local/lib/python3.8/site-packages/airflow/models/dagbag.py", line 344, in parse
    loader.exec_module(new_module)
  File "<frozen importlib._bootstrap_external>", line 843, in exec_module
  File "<frozen importlib._bootstrap>", line 219, in _call_with_frames_removed
  File "/opt/airflow/dags/google_analytics_data_etl.py", line 4, in <module>
    from logics import extract
ModuleNotFoundError: No module named 'logics'
[2024-07-16T15:02:40.637+0000] {processor.py:842} WARNING - No viable dags retrieved from /opt/airflow/dags/google_analytics_data_etl.py
[2024-07-16T15:02:40.659+0000] {processor.py:183} INFO - Processing /opt/airflow/dags/google_analytics_data_etl.py took 0.159 seconds
[2024-07-16T15:03:11.329+0000] {processor.py:161} INFO - Started process (PID=141) to work on /opt/airflow/dags/google_analytics_data_etl.py
[2024-07-16T15:03:11.331+0000] {processor.py:830} INFO - Processing file /opt/airflow/dags/google_analytics_data_etl.py for tasks to queue
[2024-07-16T15:03:11.333+0000] {logging_mixin.py:188} INFO - [2024-07-16T15:03:11.333+0000] {dagbag.py:538} INFO - Filling up the DagBag from /opt/airflow/dags/google_analytics_data_etl.py
[2024-07-16T15:03:11.416+0000] {logging_mixin.py:188} INFO - [2024-07-16T15:03:11.384+0000] {dagbag.py:348} ERROR - Failed to import: /opt/airflow/dags/google_analytics_data_etl.py
Traceback (most recent call last):
  File "/home/airflow/.local/lib/python3.8/site-packages/airflow/models/dagbag.py", line 344, in parse
    loader.exec_module(new_module)
  File "<frozen importlib._bootstrap_external>", line 843, in exec_module
  File "<frozen importlib._bootstrap>", line 219, in _call_with_frames_removed
  File "/opt/airflow/dags/google_analytics_data_etl.py", line 4, in <module>
    from logics import extract
ModuleNotFoundError: No module named 'logics'
[2024-07-16T15:03:11.422+0000] {processor.py:842} WARNING - No viable dags retrieved from /opt/airflow/dags/google_analytics_data_etl.py
[2024-07-16T15:03:11.481+0000] {processor.py:183} INFO - Processing /opt/airflow/dags/google_analytics_data_etl.py took 0.156 seconds
[2024-07-16T15:03:42.000+0000] {processor.py:161} INFO - Started process (PID=196) to work on /opt/airflow/dags/google_analytics_data_etl.py
[2024-07-16T15:03:42.001+0000] {processor.py:830} INFO - Processing file /opt/airflow/dags/google_analytics_data_etl.py for tasks to queue
[2024-07-16T15:03:42.004+0000] {logging_mixin.py:188} INFO - [2024-07-16T15:03:42.004+0000] {dagbag.py:538} INFO - Filling up the DagBag from /opt/airflow/dags/google_analytics_data_etl.py
[2024-07-16T15:03:42.062+0000] {logging_mixin.py:188} INFO - [2024-07-16T15:03:42.038+0000] {dagbag.py:348} ERROR - Failed to import: /opt/airflow/dags/google_analytics_data_etl.py
Traceback (most recent call last):
  File "/home/airflow/.local/lib/python3.8/site-packages/airflow/models/dagbag.py", line 344, in parse
    loader.exec_module(new_module)
  File "<frozen importlib._bootstrap_external>", line 843, in exec_module
  File "<frozen importlib._bootstrap>", line 219, in _call_with_frames_removed
  File "/opt/airflow/dags/google_analytics_data_etl.py", line 4, in <module>
    from logics import extract
ModuleNotFoundError: No module named 'logics'
[2024-07-16T15:03:42.071+0000] {processor.py:842} WARNING - No viable dags retrieved from /opt/airflow/dags/google_analytics_data_etl.py
[2024-07-16T15:03:42.111+0000] {processor.py:183} INFO - Processing /opt/airflow/dags/google_analytics_data_etl.py took 0.115 seconds
[2024-07-16T15:04:12.688+0000] {processor.py:161} INFO - Started process (PID=253) to work on /opt/airflow/dags/google_analytics_data_etl.py
[2024-07-16T15:04:12.691+0000] {processor.py:830} INFO - Processing file /opt/airflow/dags/google_analytics_data_etl.py for tasks to queue
[2024-07-16T15:04:12.696+0000] {logging_mixin.py:188} INFO - [2024-07-16T15:04:12.695+0000] {dagbag.py:538} INFO - Filling up the DagBag from /opt/airflow/dags/google_analytics_data_etl.py
[2024-07-16T15:04:12.778+0000] {logging_mixin.py:188} INFO - [2024-07-16T15:04:12.760+0000] {dagbag.py:348} ERROR - Failed to import: /opt/airflow/dags/google_analytics_data_etl.py
Traceback (most recent call last):
  File "/home/airflow/.local/lib/python3.8/site-packages/airflow/models/dagbag.py", line 344, in parse
    loader.exec_module(new_module)
  File "<frozen importlib._bootstrap_external>", line 843, in exec_module
  File "<frozen importlib._bootstrap>", line 219, in _call_with_frames_removed
  File "/opt/airflow/dags/google_analytics_data_etl.py", line 4, in <module>
    from logics import extract
ModuleNotFoundError: No module named 'logics'
[2024-07-16T15:04:12.782+0000] {processor.py:842} WARNING - No viable dags retrieved from /opt/airflow/dags/google_analytics_data_etl.py
[2024-07-16T15:04:12.826+0000] {processor.py:183} INFO - Processing /opt/airflow/dags/google_analytics_data_etl.py took 0.144 seconds
[2024-07-16T15:04:43.424+0000] {processor.py:161} INFO - Started process (PID=309) to work on /opt/airflow/dags/google_analytics_data_etl.py
[2024-07-16T15:04:43.427+0000] {processor.py:830} INFO - Processing file /opt/airflow/dags/google_analytics_data_etl.py for tasks to queue
[2024-07-16T15:04:43.431+0000] {logging_mixin.py:188} INFO - [2024-07-16T15:04:43.431+0000] {dagbag.py:538} INFO - Filling up the DagBag from /opt/airflow/dags/google_analytics_data_etl.py
[2024-07-16T15:04:43.553+0000] {logging_mixin.py:188} INFO - [2024-07-16T15:04:43.538+0000] {dagbag.py:348} ERROR - Failed to import: /opt/airflow/dags/google_analytics_data_etl.py
Traceback (most recent call last):
  File "/home/airflow/.local/lib/python3.8/site-packages/airflow/models/dagbag.py", line 344, in parse
    loader.exec_module(new_module)
  File "<frozen importlib._bootstrap_external>", line 843, in exec_module
  File "<frozen importlib._bootstrap>", line 219, in _call_with_frames_removed
  File "/opt/airflow/dags/google_analytics_data_etl.py", line 4, in <module>
    from logics import extract
ModuleNotFoundError: No module named 'logics'
[2024-07-16T15:04:43.558+0000] {processor.py:842} WARNING - No viable dags retrieved from /opt/airflow/dags/google_analytics_data_etl.py
[2024-07-16T15:04:43.589+0000] {processor.py:183} INFO - Processing /opt/airflow/dags/google_analytics_data_etl.py took 0.174 seconds
[2024-07-16T15:05:11.478+0000] {processor.py:161} INFO - Started process (PID=365) to work on /opt/airflow/dags/google_analytics_data_etl.py
[2024-07-16T15:05:11.480+0000] {processor.py:830} INFO - Processing file /opt/airflow/dags/google_analytics_data_etl.py for tasks to queue
[2024-07-16T15:05:11.482+0000] {logging_mixin.py:188} INFO - [2024-07-16T15:05:11.482+0000] {dagbag.py:538} INFO - Filling up the DagBag from /opt/airflow/dags/google_analytics_data_etl.py
[2024-07-16T15:05:11.521+0000] {logging_mixin.py:188} INFO - [2024-07-16T15:05:11.512+0000] {dagbag.py:348} ERROR - Failed to import: /opt/airflow/dags/google_analytics_data_etl.py
Traceback (most recent call last):
  File "/home/airflow/.local/lib/python3.8/site-packages/airflow/models/dagbag.py", line 344, in parse
    loader.exec_module(new_module)
  File "<frozen importlib._bootstrap_external>", line 843, in exec_module
  File "<frozen importlib._bootstrap>", line 219, in _call_with_frames_removed
  File "/opt/airflow/dags/google_analytics_data_etl.py", line 4, in <module>
    from logics import extract, transform
ModuleNotFoundError: No module named 'logics'
[2024-07-16T15:05:11.523+0000] {processor.py:842} WARNING - No viable dags retrieved from /opt/airflow/dags/google_analytics_data_etl.py
[2024-07-16T15:05:11.547+0000] {processor.py:183} INFO - Processing /opt/airflow/dags/google_analytics_data_etl.py took 0.071 seconds
[2024-07-16T15:06:08.129+0000] {processor.py:161} INFO - Started process (PID=28) to work on /opt/airflow/dags/google_analytics_data_etl.py
[2024-07-16T15:06:08.134+0000] {processor.py:830} INFO - Processing file /opt/airflow/dags/google_analytics_data_etl.py for tasks to queue
[2024-07-16T15:06:08.138+0000] {logging_mixin.py:188} INFO - [2024-07-16T15:06:08.137+0000] {dagbag.py:538} INFO - Filling up the DagBag from /opt/airflow/dags/google_analytics_data_etl.py
[2024-07-16T15:06:08.239+0000] {logging_mixin.py:188} INFO - [2024-07-16T15:06:08.208+0000] {dagbag.py:348} ERROR - Failed to import: /opt/airflow/dags/google_analytics_data_etl.py
Traceback (most recent call last):
  File "/home/airflow/.local/lib/python3.8/site-packages/airflow/models/dagbag.py", line 344, in parse
    loader.exec_module(new_module)
  File "<frozen importlib._bootstrap_external>", line 843, in exec_module
  File "<frozen importlib._bootstrap>", line 219, in _call_with_frames_removed
  File "/opt/airflow/dags/google_analytics_data_etl.py", line 4, in <module>
    from logics import extract, transform
ModuleNotFoundError: No module named 'logics'
[2024-07-16T15:06:08.245+0000] {processor.py:842} WARNING - No viable dags retrieved from /opt/airflow/dags/google_analytics_data_etl.py
[2024-07-16T15:06:08.289+0000] {processor.py:183} INFO - Processing /opt/airflow/dags/google_analytics_data_etl.py took 0.163 seconds
[2024-07-16T15:06:39.113+0000] {processor.py:161} INFO - Started process (PID=83) to work on /opt/airflow/dags/google_analytics_data_etl.py
[2024-07-16T15:06:39.116+0000] {processor.py:830} INFO - Processing file /opt/airflow/dags/google_analytics_data_etl.py for tasks to queue
[2024-07-16T15:06:39.118+0000] {logging_mixin.py:188} INFO - [2024-07-16T15:06:39.118+0000] {dagbag.py:538} INFO - Filling up the DagBag from /opt/airflow/dags/google_analytics_data_etl.py
[2024-07-16T15:06:39.140+0000] {logging_mixin.py:188} INFO - [2024-07-16T15:06:39.136+0000] {dagbag.py:348} ERROR - Failed to import: /opt/airflow/dags/google_analytics_data_etl.py
Traceback (most recent call last):
  File "/home/airflow/.local/lib/python3.8/site-packages/airflow/models/dagbag.py", line 344, in parse
    loader.exec_module(new_module)
  File "<frozen importlib._bootstrap_external>", line 843, in exec_module
  File "<frozen importlib._bootstrap>", line 219, in _call_with_frames_removed
  File "/opt/airflow/dags/google_analytics_data_etl.py", line 4, in <module>
    from logics import extract, transform
ModuleNotFoundError: No module named 'logics'
[2024-07-16T15:06:39.142+0000] {processor.py:842} WARNING - No viable dags retrieved from /opt/airflow/dags/google_analytics_data_etl.py
[2024-07-16T15:06:39.161+0000] {processor.py:183} INFO - Processing /opt/airflow/dags/google_analytics_data_etl.py took 0.051 seconds
[2024-07-16T15:07:09.408+0000] {processor.py:161} INFO - Started process (PID=139) to work on /opt/airflow/dags/google_analytics_data_etl.py
[2024-07-16T15:07:09.409+0000] {processor.py:830} INFO - Processing file /opt/airflow/dags/google_analytics_data_etl.py for tasks to queue
[2024-07-16T15:07:09.412+0000] {logging_mixin.py:188} INFO - [2024-07-16T15:07:09.412+0000] {dagbag.py:538} INFO - Filling up the DagBag from /opt/airflow/dags/google_analytics_data_etl.py
[2024-07-16T15:07:09.523+0000] {logging_mixin.py:188} INFO - [2024-07-16T15:07:09.516+0000] {dagbag.py:348} ERROR - Failed to import: /opt/airflow/dags/google_analytics_data_etl.py
Traceback (most recent call last):
  File "/home/airflow/.local/lib/python3.8/site-packages/airflow/models/dagbag.py", line 344, in parse
    loader.exec_module(new_module)
  File "<frozen importlib._bootstrap_external>", line 843, in exec_module
  File "<frozen importlib._bootstrap>", line 219, in _call_with_frames_removed
  File "/opt/airflow/dags/google_analytics_data_etl.py", line 4, in <module>
    from logics import extract, transform
ModuleNotFoundError: No module named 'logics'
[2024-07-16T15:07:09.525+0000] {processor.py:842} WARNING - No viable dags retrieved from /opt/airflow/dags/google_analytics_data_etl.py
[2024-07-16T15:07:09.544+0000] {processor.py:183} INFO - Processing /opt/airflow/dags/google_analytics_data_etl.py took 0.139 seconds
[2024-07-16T15:07:39.912+0000] {processor.py:161} INFO - Started process (PID=196) to work on /opt/airflow/dags/google_analytics_data_etl.py
[2024-07-16T15:07:39.914+0000] {processor.py:830} INFO - Processing file /opt/airflow/dags/google_analytics_data_etl.py for tasks to queue
[2024-07-16T15:07:39.916+0000] {logging_mixin.py:188} INFO - [2024-07-16T15:07:39.916+0000] {dagbag.py:538} INFO - Filling up the DagBag from /opt/airflow/dags/google_analytics_data_etl.py
[2024-07-16T15:07:39.936+0000] {logging_mixin.py:188} INFO - [2024-07-16T15:07:39.933+0000] {dagbag.py:348} ERROR - Failed to import: /opt/airflow/dags/google_analytics_data_etl.py
Traceback (most recent call last):
  File "/home/airflow/.local/lib/python3.8/site-packages/airflow/models/dagbag.py", line 344, in parse
    loader.exec_module(new_module)
  File "<frozen importlib._bootstrap_external>", line 843, in exec_module
  File "<frozen importlib._bootstrap>", line 219, in _call_with_frames_removed
  File "/opt/airflow/dags/google_analytics_data_etl.py", line 4, in <module>
    from logics import extract, transform
ModuleNotFoundError: No module named 'logics'
[2024-07-16T15:07:39.937+0000] {processor.py:842} WARNING - No viable dags retrieved from /opt/airflow/dags/google_analytics_data_etl.py
[2024-07-16T15:07:39.968+0000] {processor.py:183} INFO - Processing /opt/airflow/dags/google_analytics_data_etl.py took 0.059 seconds
[2024-07-16T15:08:10.501+0000] {processor.py:161} INFO - Started process (PID=251) to work on /opt/airflow/dags/google_analytics_data_etl.py
[2024-07-16T15:08:10.503+0000] {processor.py:830} INFO - Processing file /opt/airflow/dags/google_analytics_data_etl.py for tasks to queue
[2024-07-16T15:08:10.506+0000] {logging_mixin.py:188} INFO - [2024-07-16T15:08:10.506+0000] {dagbag.py:538} INFO - Filling up the DagBag from /opt/airflow/dags/google_analytics_data_etl.py
[2024-07-16T15:08:10.606+0000] {logging_mixin.py:188} INFO - [2024-07-16T15:08:10.583+0000] {dagbag.py:348} ERROR - Failed to import: /opt/airflow/dags/google_analytics_data_etl.py
Traceback (most recent call last):
  File "/home/airflow/.local/lib/python3.8/site-packages/airflow/models/dagbag.py", line 344, in parse
    loader.exec_module(new_module)
  File "<frozen importlib._bootstrap_external>", line 843, in exec_module
  File "<frozen importlib._bootstrap>", line 219, in _call_with_frames_removed
  File "/opt/airflow/dags/google_analytics_data_etl.py", line 4, in <module>
    from logics import extract, transform
ModuleNotFoundError: No module named 'logics'
[2024-07-16T15:08:10.610+0000] {processor.py:842} WARNING - No viable dags retrieved from /opt/airflow/dags/google_analytics_data_etl.py
[2024-07-16T15:08:10.640+0000] {processor.py:183} INFO - Processing /opt/airflow/dags/google_analytics_data_etl.py took 0.144 seconds
[2024-07-16T15:08:40.970+0000] {processor.py:161} INFO - Started process (PID=308) to work on /opt/airflow/dags/google_analytics_data_etl.py
[2024-07-16T15:08:40.972+0000] {processor.py:830} INFO - Processing file /opt/airflow/dags/google_analytics_data_etl.py for tasks to queue
[2024-07-16T15:08:40.974+0000] {logging_mixin.py:188} INFO - [2024-07-16T15:08:40.974+0000] {dagbag.py:538} INFO - Filling up the DagBag from /opt/airflow/dags/google_analytics_data_etl.py
[2024-07-16T15:08:40.997+0000] {logging_mixin.py:188} INFO - [2024-07-16T15:08:40.993+0000] {dagbag.py:348} ERROR - Failed to import: /opt/airflow/dags/google_analytics_data_etl.py
Traceback (most recent call last):
  File "/home/airflow/.local/lib/python3.8/site-packages/airflow/models/dagbag.py", line 344, in parse
    loader.exec_module(new_module)
  File "<frozen importlib._bootstrap_external>", line 843, in exec_module
  File "<frozen importlib._bootstrap>", line 219, in _call_with_frames_removed
  File "/opt/airflow/dags/google_analytics_data_etl.py", line 4, in <module>
    from logics import extract, transform
ModuleNotFoundError: No module named 'logics'
[2024-07-16T15:08:41.000+0000] {processor.py:842} WARNING - No viable dags retrieved from /opt/airflow/dags/google_analytics_data_etl.py
[2024-07-16T15:08:41.025+0000] {processor.py:183} INFO - Processing /opt/airflow/dags/google_analytics_data_etl.py took 0.061 seconds
[2024-07-16T15:09:11.453+0000] {processor.py:161} INFO - Started process (PID=364) to work on /opt/airflow/dags/google_analytics_data_etl.py
[2024-07-16T15:09:11.456+0000] {processor.py:830} INFO - Processing file /opt/airflow/dags/google_analytics_data_etl.py for tasks to queue
[2024-07-16T15:09:11.468+0000] {logging_mixin.py:188} INFO - [2024-07-16T15:09:11.467+0000] {dagbag.py:538} INFO - Filling up the DagBag from /opt/airflow/dags/google_analytics_data_etl.py
[2024-07-16T15:09:11.598+0000] {logging_mixin.py:188} INFO - [2024-07-16T15:09:11.559+0000] {dagbag.py:348} ERROR - Failed to import: /opt/airflow/dags/google_analytics_data_etl.py
Traceback (most recent call last):
  File "/home/airflow/.local/lib/python3.8/site-packages/airflow/models/dagbag.py", line 344, in parse
    loader.exec_module(new_module)
  File "<frozen importlib._bootstrap_external>", line 843, in exec_module
  File "<frozen importlib._bootstrap>", line 219, in _call_with_frames_removed
  File "/opt/airflow/dags/google_analytics_data_etl.py", line 4, in <module>
    from logics import extract, transform
ModuleNotFoundError: No module named 'logics'
[2024-07-16T15:09:11.607+0000] {processor.py:842} WARNING - No viable dags retrieved from /opt/airflow/dags/google_analytics_data_etl.py
[2024-07-16T15:09:11.706+0000] {processor.py:183} INFO - Processing /opt/airflow/dags/google_analytics_data_etl.py took 0.259 seconds
[2024-07-16T15:09:42.336+0000] {processor.py:161} INFO - Started process (PID=420) to work on /opt/airflow/dags/google_analytics_data_etl.py
[2024-07-16T15:09:42.337+0000] {processor.py:830} INFO - Processing file /opt/airflow/dags/google_analytics_data_etl.py for tasks to queue
[2024-07-16T15:09:42.343+0000] {logging_mixin.py:188} INFO - [2024-07-16T15:09:42.343+0000] {dagbag.py:538} INFO - Filling up the DagBag from /opt/airflow/dags/google_analytics_data_etl.py
[2024-07-16T15:09:42.376+0000] {logging_mixin.py:188} INFO - [2024-07-16T15:09:42.372+0000] {dagbag.py:348} ERROR - Failed to import: /opt/airflow/dags/google_analytics_data_etl.py
Traceback (most recent call last):
  File "/home/airflow/.local/lib/python3.8/site-packages/airflow/models/dagbag.py", line 344, in parse
    loader.exec_module(new_module)
  File "<frozen importlib._bootstrap_external>", line 843, in exec_module
  File "<frozen importlib._bootstrap>", line 219, in _call_with_frames_removed
  File "/opt/airflow/dags/google_analytics_data_etl.py", line 4, in <module>
    from logics import extract, transform
ModuleNotFoundError: No module named 'logics'
[2024-07-16T15:09:42.392+0000] {processor.py:842} WARNING - No viable dags retrieved from /opt/airflow/dags/google_analytics_data_etl.py
[2024-07-16T15:09:42.434+0000] {processor.py:183} INFO - Processing /opt/airflow/dags/google_analytics_data_etl.py took 0.101 seconds
[2024-07-16T15:09:43.532+0000] {processor.py:161} INFO - Started process (PID=423) to work on /opt/airflow/dags/google_analytics_data_etl.py
[2024-07-16T15:09:43.534+0000] {processor.py:830} INFO - Processing file /opt/airflow/dags/google_analytics_data_etl.py for tasks to queue
[2024-07-16T15:09:43.536+0000] {logging_mixin.py:188} INFO - [2024-07-16T15:09:43.536+0000] {dagbag.py:538} INFO - Filling up the DagBag from /opt/airflow/dags/google_analytics_data_etl.py
[2024-07-16T15:09:43.587+0000] {logging_mixin.py:188} INFO - [2024-07-16T15:09:43.581+0000] {dagbag.py:348} ERROR - Failed to import: /opt/airflow/dags/google_analytics_data_etl.py
Traceback (most recent call last):
  File "/home/airflow/.local/lib/python3.8/site-packages/airflow/models/dagbag.py", line 344, in parse
    loader.exec_module(new_module)
  File "<frozen importlib._bootstrap_external>", line 843, in exec_module
  File "<frozen importlib._bootstrap>", line 219, in _call_with_frames_removed
  File "/opt/airflow/dags/google_analytics_data_etl.py", line 4, in <module>
    from logics import extract, transform
ModuleNotFoundError: No module named 'logics'
[2024-07-16T15:09:43.590+0000] {processor.py:842} WARNING - No viable dags retrieved from /opt/airflow/dags/google_analytics_data_etl.py
[2024-07-16T15:09:43.614+0000] {processor.py:183} INFO - Processing /opt/airflow/dags/google_analytics_data_etl.py took 0.084 seconds
[2024-07-16T15:10:14.264+0000] {processor.py:161} INFO - Started process (PID=479) to work on /opt/airflow/dags/google_analytics_data_etl.py
[2024-07-16T15:10:14.269+0000] {processor.py:830} INFO - Processing file /opt/airflow/dags/google_analytics_data_etl.py for tasks to queue
[2024-07-16T15:10:14.280+0000] {logging_mixin.py:188} INFO - [2024-07-16T15:10:14.280+0000] {dagbag.py:538} INFO - Filling up the DagBag from /opt/airflow/dags/google_analytics_data_etl.py
[2024-07-16T15:10:14.478+0000] {logging_mixin.py:188} INFO - [2024-07-16T15:10:14.450+0000] {dagbag.py:348} ERROR - Failed to import: /opt/airflow/dags/google_analytics_data_etl.py
Traceback (most recent call last):
  File "/home/airflow/.local/lib/python3.8/site-packages/airflow/models/dagbag.py", line 344, in parse
    loader.exec_module(new_module)
  File "<frozen importlib._bootstrap_external>", line 843, in exec_module
  File "<frozen importlib._bootstrap>", line 219, in _call_with_frames_removed
  File "/opt/airflow/dags/google_analytics_data_etl.py", line 4, in <module>
    from logics import extract, transform
ModuleNotFoundError: No module named 'logics'
[2024-07-16T15:10:14.489+0000] {processor.py:842} WARNING - No viable dags retrieved from /opt/airflow/dags/google_analytics_data_etl.py
[2024-07-16T15:10:14.518+0000] {processor.py:183} INFO - Processing /opt/airflow/dags/google_analytics_data_etl.py took 0.267 seconds
[2024-07-16T15:10:44.581+0000] {processor.py:161} INFO - Started process (PID=535) to work on /opt/airflow/dags/google_analytics_data_etl.py
[2024-07-16T15:10:44.582+0000] {processor.py:830} INFO - Processing file /opt/airflow/dags/google_analytics_data_etl.py for tasks to queue
[2024-07-16T15:10:44.585+0000] {logging_mixin.py:188} INFO - [2024-07-16T15:10:44.584+0000] {dagbag.py:538} INFO - Filling up the DagBag from /opt/airflow/dags/google_analytics_data_etl.py
[2024-07-16T15:10:44.643+0000] {logging_mixin.py:188} INFO - [2024-07-16T15:10:44.631+0000] {dagbag.py:348} ERROR - Failed to import: /opt/airflow/dags/google_analytics_data_etl.py
Traceback (most recent call last):
  File "/home/airflow/.local/lib/python3.8/site-packages/airflow/models/dagbag.py", line 344, in parse
    loader.exec_module(new_module)
  File "<frozen importlib._bootstrap_external>", line 843, in exec_module
  File "<frozen importlib._bootstrap>", line 219, in _call_with_frames_removed
  File "/opt/airflow/dags/google_analytics_data_etl.py", line 4, in <module>
    from logics import extract, transform
ModuleNotFoundError: No module named 'logics'
[2024-07-16T15:10:44.650+0000] {processor.py:842} WARNING - No viable dags retrieved from /opt/airflow/dags/google_analytics_data_etl.py
[2024-07-16T15:10:44.673+0000] {processor.py:183} INFO - Processing /opt/airflow/dags/google_analytics_data_etl.py took 0.095 seconds
[2024-07-16T15:11:14.880+0000] {processor.py:161} INFO - Started process (PID=591) to work on /opt/airflow/dags/google_analytics_data_etl.py
[2024-07-16T15:11:14.883+0000] {processor.py:830} INFO - Processing file /opt/airflow/dags/google_analytics_data_etl.py for tasks to queue
[2024-07-16T15:11:14.889+0000] {logging_mixin.py:188} INFO - [2024-07-16T15:11:14.889+0000] {dagbag.py:538} INFO - Filling up the DagBag from /opt/airflow/dags/google_analytics_data_etl.py
[2024-07-16T15:11:15.181+0000] {logging_mixin.py:188} INFO - [2024-07-16T15:11:15.107+0000] {dagbag.py:348} ERROR - Failed to import: /opt/airflow/dags/google_analytics_data_etl.py
Traceback (most recent call last):
  File "/home/airflow/.local/lib/python3.8/site-packages/airflow/models/dagbag.py", line 344, in parse
    loader.exec_module(new_module)
  File "<frozen importlib._bootstrap_external>", line 843, in exec_module
  File "<frozen importlib._bootstrap>", line 219, in _call_with_frames_removed
  File "/opt/airflow/dags/google_analytics_data_etl.py", line 4, in <module>
    from logics import extract, transform
ModuleNotFoundError: No module named 'logics'
[2024-07-16T15:11:15.218+0000] {processor.py:842} WARNING - No viable dags retrieved from /opt/airflow/dags/google_analytics_data_etl.py
[2024-07-16T15:11:15.256+0000] {processor.py:183} INFO - Processing /opt/airflow/dags/google_analytics_data_etl.py took 0.389 seconds
[2024-07-16T15:11:46.062+0000] {processor.py:161} INFO - Started process (PID=646) to work on /opt/airflow/dags/google_analytics_data_etl.py
[2024-07-16T15:11:46.066+0000] {processor.py:830} INFO - Processing file /opt/airflow/dags/google_analytics_data_etl.py for tasks to queue
[2024-07-16T15:11:46.071+0000] {logging_mixin.py:188} INFO - [2024-07-16T15:11:46.070+0000] {dagbag.py:538} INFO - Filling up the DagBag from /opt/airflow/dags/google_analytics_data_etl.py
[2024-07-16T15:11:46.111+0000] {logging_mixin.py:188} INFO - [2024-07-16T15:11:46.105+0000] {dagbag.py:348} ERROR - Failed to import: /opt/airflow/dags/google_analytics_data_etl.py
Traceback (most recent call last):
  File "/home/airflow/.local/lib/python3.8/site-packages/airflow/models/dagbag.py", line 344, in parse
    loader.exec_module(new_module)
  File "<frozen importlib._bootstrap_external>", line 843, in exec_module
  File "<frozen importlib._bootstrap>", line 219, in _call_with_frames_removed
  File "/opt/airflow/dags/google_analytics_data_etl.py", line 4, in <module>
    from logics import extract, transform
ModuleNotFoundError: No module named 'logics'
[2024-07-16T15:11:46.114+0000] {processor.py:842} WARNING - No viable dags retrieved from /opt/airflow/dags/google_analytics_data_etl.py
[2024-07-16T15:11:46.133+0000] {processor.py:183} INFO - Processing /opt/airflow/dags/google_analytics_data_etl.py took 0.081 seconds
[2024-07-16T15:12:16.869+0000] {processor.py:161} INFO - Started process (PID=702) to work on /opt/airflow/dags/google_analytics_data_etl.py
[2024-07-16T15:12:16.872+0000] {processor.py:830} INFO - Processing file /opt/airflow/dags/google_analytics_data_etl.py for tasks to queue
[2024-07-16T15:12:16.874+0000] {logging_mixin.py:188} INFO - [2024-07-16T15:12:16.874+0000] {dagbag.py:538} INFO - Filling up the DagBag from /opt/airflow/dags/google_analytics_data_etl.py
[2024-07-16T15:12:16.975+0000] {logging_mixin.py:188} INFO - [2024-07-16T15:12:16.944+0000] {dagbag.py:348} ERROR - Failed to import: /opt/airflow/dags/google_analytics_data_etl.py
Traceback (most recent call last):
  File "/home/airflow/.local/lib/python3.8/site-packages/airflow/models/dagbag.py", line 344, in parse
    loader.exec_module(new_module)
  File "<frozen importlib._bootstrap_external>", line 843, in exec_module
  File "<frozen importlib._bootstrap>", line 219, in _call_with_frames_removed
  File "/opt/airflow/dags/google_analytics_data_etl.py", line 4, in <module>
    from logics import extract, transform
ModuleNotFoundError: No module named 'logics'
[2024-07-16T15:12:16.977+0000] {processor.py:842} WARNING - No viable dags retrieved from /opt/airflow/dags/google_analytics_data_etl.py
[2024-07-16T15:12:16.994+0000] {processor.py:183} INFO - Processing /opt/airflow/dags/google_analytics_data_etl.py took 0.135 seconds
[2024-07-16T15:12:47.201+0000] {processor.py:161} INFO - Started process (PID=758) to work on /opt/airflow/dags/google_analytics_data_etl.py
[2024-07-16T15:12:47.203+0000] {processor.py:830} INFO - Processing file /opt/airflow/dags/google_analytics_data_etl.py for tasks to queue
[2024-07-16T15:12:47.209+0000] {logging_mixin.py:188} INFO - [2024-07-16T15:12:47.209+0000] {dagbag.py:538} INFO - Filling up the DagBag from /opt/airflow/dags/google_analytics_data_etl.py
[2024-07-16T15:12:47.242+0000] {logging_mixin.py:188} INFO - [2024-07-16T15:12:47.237+0000] {dagbag.py:348} ERROR - Failed to import: /opt/airflow/dags/google_analytics_data_etl.py
Traceback (most recent call last):
  File "/home/airflow/.local/lib/python3.8/site-packages/airflow/models/dagbag.py", line 344, in parse
    loader.exec_module(new_module)
  File "<frozen importlib._bootstrap_external>", line 843, in exec_module
  File "<frozen importlib._bootstrap>", line 219, in _call_with_frames_removed
  File "/opt/airflow/dags/google_analytics_data_etl.py", line 4, in <module>
    from logics import extract, transform
ModuleNotFoundError: No module named 'logics'
[2024-07-16T15:12:47.243+0000] {processor.py:842} WARNING - No viable dags retrieved from /opt/airflow/dags/google_analytics_data_etl.py
[2024-07-16T15:12:47.263+0000] {processor.py:183} INFO - Processing /opt/airflow/dags/google_analytics_data_etl.py took 0.067 seconds
[2024-07-16T15:13:17.766+0000] {processor.py:161} INFO - Started process (PID=814) to work on /opt/airflow/dags/google_analytics_data_etl.py
[2024-07-16T15:13:17.771+0000] {processor.py:830} INFO - Processing file /opt/airflow/dags/google_analytics_data_etl.py for tasks to queue
[2024-07-16T15:13:17.781+0000] {logging_mixin.py:188} INFO - [2024-07-16T15:13:17.779+0000] {dagbag.py:538} INFO - Filling up the DagBag from /opt/airflow/dags/google_analytics_data_etl.py
[2024-07-16T15:13:17.817+0000] {logging_mixin.py:188} INFO - [2024-07-16T15:13:17.811+0000] {dagbag.py:348} ERROR - Failed to import: /opt/airflow/dags/google_analytics_data_etl.py
Traceback (most recent call last):
  File "/home/airflow/.local/lib/python3.8/site-packages/airflow/models/dagbag.py", line 344, in parse
    loader.exec_module(new_module)
  File "<frozen importlib._bootstrap_external>", line 843, in exec_module
  File "<frozen importlib._bootstrap>", line 219, in _call_with_frames_removed
  File "/opt/airflow/dags/google_analytics_data_etl.py", line 4, in <module>
    from logics import extract, transform
ModuleNotFoundError: No module named 'logics'
[2024-07-16T15:13:17.819+0000] {processor.py:842} WARNING - No viable dags retrieved from /opt/airflow/dags/google_analytics_data_etl.py
[2024-07-16T15:13:17.840+0000] {processor.py:183} INFO - Processing /opt/airflow/dags/google_analytics_data_etl.py took 0.091 seconds
[2024-07-16T15:13:48.125+0000] {processor.py:161} INFO - Started process (PID=869) to work on /opt/airflow/dags/google_analytics_data_etl.py
[2024-07-16T15:13:48.129+0000] {processor.py:830} INFO - Processing file /opt/airflow/dags/google_analytics_data_etl.py for tasks to queue
[2024-07-16T15:13:48.135+0000] {logging_mixin.py:188} INFO - [2024-07-16T15:13:48.134+0000] {dagbag.py:538} INFO - Filling up the DagBag from /opt/airflow/dags/google_analytics_data_etl.py
[2024-07-16T15:13:48.194+0000] {logging_mixin.py:188} INFO - [2024-07-16T15:13:48.167+0000] {dagbag.py:348} ERROR - Failed to import: /opt/airflow/dags/google_analytics_data_etl.py
Traceback (most recent call last):
  File "/home/airflow/.local/lib/python3.8/site-packages/airflow/models/dagbag.py", line 344, in parse
    loader.exec_module(new_module)
  File "<frozen importlib._bootstrap_external>", line 843, in exec_module
  File "<frozen importlib._bootstrap>", line 219, in _call_with_frames_removed
  File "/opt/airflow/dags/google_analytics_data_etl.py", line 4, in <module>
    from logics import extract, transform
ModuleNotFoundError: No module named 'logics'
[2024-07-16T15:13:48.199+0000] {processor.py:842} WARNING - No viable dags retrieved from /opt/airflow/dags/google_analytics_data_etl.py
[2024-07-16T15:13:48.215+0000] {processor.py:183} INFO - Processing /opt/airflow/dags/google_analytics_data_etl.py took 0.102 seconds
[2024-07-16T15:13:49.271+0000] {processor.py:161} INFO - Started process (PID=871) to work on /opt/airflow/dags/google_analytics_data_etl.py
[2024-07-16T15:13:49.272+0000] {processor.py:830} INFO - Processing file /opt/airflow/dags/google_analytics_data_etl.py for tasks to queue
[2024-07-16T15:13:49.274+0000] {logging_mixin.py:188} INFO - [2024-07-16T15:13:49.273+0000] {dagbag.py:538} INFO - Filling up the DagBag from /opt/airflow/dags/google_analytics_data_etl.py
[2024-07-16T15:13:49.321+0000] {processor.py:840} INFO - DAG(s) 'google_analytics_data_etl' retrieved from /opt/airflow/dags/google_analytics_data_etl.py
[2024-07-16T15:13:49.467+0000] {logging_mixin.py:188} INFO - [2024-07-16T15:13:49.467+0000] {dag.py:3033} INFO - Sync 1 DAGs
[2024-07-16T15:13:49.478+0000] {logging_mixin.py:188} INFO - [2024-07-16T15:13:49.478+0000] {dag.py:3820} INFO - Setting next_dagrun for google_analytics_data_etl to None, run_after=None
[2024-07-16T15:13:49.528+0000] {processor.py:183} INFO - Processing /opt/airflow/dags/google_analytics_data_etl.py took 0.259 seconds
[2024-07-16T15:14:19.925+0000] {processor.py:161} INFO - Started process (PID=926) to work on /opt/airflow/dags/google_analytics_data_etl.py
[2024-07-16T15:14:19.927+0000] {processor.py:830} INFO - Processing file /opt/airflow/dags/google_analytics_data_etl.py for tasks to queue
[2024-07-16T15:14:19.932+0000] {logging_mixin.py:188} INFO - [2024-07-16T15:14:19.931+0000] {dagbag.py:538} INFO - Filling up the DagBag from /opt/airflow/dags/google_analytics_data_etl.py
[2024-07-16T15:14:19.957+0000] {processor.py:840} INFO - DAG(s) 'google_analytics_data_etl' retrieved from /opt/airflow/dags/google_analytics_data_etl.py
[2024-07-16T15:14:19.972+0000] {logging_mixin.py:188} INFO - [2024-07-16T15:14:19.972+0000] {dag.py:3033} INFO - Sync 1 DAGs
[2024-07-16T15:14:19.982+0000] {logging_mixin.py:188} INFO - [2024-07-16T15:14:19.982+0000] {dag.py:3820} INFO - Setting next_dagrun for google_analytics_data_etl to None, run_after=None
[2024-07-16T15:14:20.003+0000] {processor.py:183} INFO - Processing /opt/airflow/dags/google_analytics_data_etl.py took 0.089 seconds
